<?xml version="1.0" ?>
<!-- Generated using onshape-to-robot -->
<!-- Onshape https://cad.onshape.com/documents/e305b26a84339af20c593973/w/6750d451f9cbcfe7ac139539/e/251023ea04190ab16854eb80 -->
<robot name="robot">
  <!-- Link turning_bowl -->
  <link name="turning_bowl">
    <inertial>
      <origin xyz="-0.0011015 3.36586e-09 0.00982937" rpy="0 0 0"/>
      <mass value="0.0856525"/>
      <inertia ixx="0.000103778" ixy="1.62688e-11" ixz="5.11021e-07" iyy="9.91009e-05" iyz="2.46124e-13" izz="0.000188612"/>
    </inertial>
    <!-- Part turning_bowl -->
    <visual>
      <origin xyz="-0.00198261 3.46945e-18 0.2445" rpy="1.57772e-30 -3.15544e-30 1.5708"/>
      <geometry>
        <mesh filename="package://assets/turning_bowl.stl"/>
      </geometry>
      <material name="turning_bowl_material">
        <color rgba="0.34902 0.376471 0.4 1.0"/>
      </material>
    </visual>
    <collision>
      <origin xyz="-0.00198261 3.46945e-18 0.2445" rpy="1.57772e-30 -3.15544e-30 1.5708"/>
      <geometry>
        <mesh filename="package://assets/turning_bowl.stl"/>
      </geometry>
    </collision>
  </link>
  <!-- Link main_plate -->
  <link name="main_plate">
    <inertial>
      <origin xyz="6.84881e-05 0.00157052 -0.0411006" rpy="0 0 0"/>
      <mass value="0.42461"/>
      <inertia ixx="0.00174771" ixy="-3.57066e-07" ixz="-1.95668e-07" iyy="0.00169917" iyz="5.33713e-05" izz="0.00193868"/>
    </inertial>
    <!-- Part dc15_a01_case_m_dummy -->
    <visual>
      <origin xyz="0.108746 0.039063 -0.014785" rpy="-3.14159 1.79711e-16 2.0944"/>
      <geometry>
        <mesh filename="package://assets/dc15_a01_case_m_dummy.stl"/>
      </geometry>
      <material name="dc15_a01_case_m_dummy_material">
        <color rgba="0.262745 0.282353 0.301961 1.0"/>
      </material>
    </visual>
    <collision>
      <origin xyz="0.108746 0.039063 -0.014785" rpy="-3.14159 1.79711e-16 2.0944"/>
      <geometry>
        <mesh filename="package://assets/dc15_a01_case_m_dummy.stl"/>
      </geometry>
    </collision>
    <!-- Part main_plate -->
    <visual>
      <origin xyz="4.33013e-05 -2.5e-05 -0.014785" rpy="3.14159 1.54571e-15 1.0472"/>
      <geometry>
        <mesh filename="package://assets/main_plate.stl"/>
      </geometry>
      <material name="main_plate_material">
        <color rgba="0.196078 0.196078 0.196078 1.0"/>
      </material>
    </visual>
    <collision>
      <origin xyz="4.33013e-05 -2.5e-05 -0.014785" rpy="3.14159 1.54571e-15 1.0472"/>
      <geometry>
        <mesh filename="package://assets/main_plate.stl"/>
      </geometry>
    </collision>
    <!-- Part dc15_a01_case_f_dummy -->
    <visual>
      <origin xyz="0.000476314 -0.000275 -0.014785" rpy="3.14159 1.59993e-16 1.0472"/>
      <geometry>
        <mesh filename="package://assets/dc15_a01_case_f_dummy.stl"/>
      </geometry>
      <material name="dc15_a01_case_f_dummy_material">
        <color rgba="0.262745 0.282353 0.301961 1.0"/>
      </material>
    </visual>
    <collision>
      <origin xyz="0.000476314 -0.000275 -0.014785" rpy="3.14159 1.59993e-16 1.0472"/>
      <geometry>
        <mesh filename="package://assets/dc15_a01_case_f_dummy.stl"/>
      </geometry>
    </collision>
    <!-- Part dc15_a01_horn_dummy -->
    <visual>
      <origin xyz="-0.0106397 0.0174785 -0.014785" rpy="-3.14159 -5.68849e-17 -1.0472"/>
      <geometry>
        <mesh filename="package://assets/dc15_a01_horn_dummy.stl"/>
      </geometry>
      <material name="dc15_a01_horn_dummy_material">
        <color rgba="0.262745 0.282353 0.301961 1.0"/>
      </material>
    </visual>
    <collision>
      <origin xyz="-0.0106397 0.0174785 -0.014785" rpy="-3.14159 -5.68849e-17 -1.0472"/>
      <geometry>
        <mesh filename="package://assets/dc15_a01_horn_dummy.stl"/>
      </geometry>
    </collision>
    <!-- Part dc15_a01_horn_dummy_2 -->
    <visual>
      <origin xyz="0.000476314 -0.000275 -0.014785" rpy="3.14159 1.59993e-16 1.0472"/>
      <geometry>
        <mesh filename="package://assets/dc15_a01_horn_dummy.stl"/>
      </geometry>
      <material name="dc15_a01_horn_dummy_2_material">
        <color rgba="0.262745 0.282353 0.301961 1.0"/>
      </material>
    </visual>
    <collision>
      <origin xyz="0.000476314 -0.000275 -0.014785" rpy="3.14159 1.59993e-16 1.0472"/>
      <geometry>
        <mesh filename="package://assets/dc15_a01_horn_dummy.stl"/>
      </geometry>
    </collision>
    <!-- Part dc15_a01_horn_dummy_3 -->
    <visual>
      <origin xyz="-0.00977369 -0.0180285 -0.014785" rpy="3.14159 1.59993e-16 1.0472"/>
      <geometry>
        <mesh filename="package://assets/dc15_a01_horn_dummy.stl"/>
      </geometry>
      <material name="dc15_a01_horn_dummy_3_material">
        <color rgba="0.262745 0.282353 0.301961 1.0"/>
      </material>
    </visual>
    <collision>
      <origin xyz="-0.00977369 -0.0180285 -0.014785" rpy="3.14159 1.59993e-16 1.0472"/>
      <geometry>
        <mesh filename="package://assets/dc15_a01_horn_dummy.stl"/>
      </geometry>
    </collision>
    <!-- Part dc15_a01_case_b_dummy -->
    <visual>
      <origin xyz="0.108746 0.039063 -0.014785" rpy="-3.14159 1.79711e-16 2.0944"/>
      <geometry>
        <mesh filename="package://assets/dc15_a01_case_b_dummy.stl"/>
      </geometry>
      <material name="dc15_a01_case_b_dummy_material">
        <color rgba="0.262745 0.282353 0.301961 1.0"/>
      </material>
    </visual>
    <collision>
      <origin xyz="0.108746 0.039063 -0.014785" rpy="-3.14159 1.79711e-16 2.0944"/>
      <geometry>
        <mesh filename="package://assets/dc15_a01_case_b_dummy.stl"/>
      </geometry>
    </collision>
    <!-- Part dc15_a01_case_b_dummy_2 -->
    <visual>
      <origin xyz="-0.00977369 -0.0180285 -0.014785" rpy="3.14159 1.59993e-16 1.0472"/>
      <geometry>
        <mesh filename="package://assets/dc15_a01_case_b_dummy.stl"/>
      </geometry>
      <material name="dc15_a01_case_b_dummy_2_material">
        <color rgba="0.262745 0.282353 0.301961 1.0"/>
      </material>
    </visual>
    <collision>
      <origin xyz="-0.00977369 -0.0180285 -0.014785" rpy="3.14159 1.59993e-16 1.0472"/>
      <geometry>
        <mesh filename="package://assets/dc15_a01_case_b_dummy.stl"/>
      </geometry>
    </collision>
    <!-- Part foot -->
    <visual>
      <origin xyz="4.33013e-05 -2.5e-05 -0.014785" rpy="3.14159 -1.79711e-16 -1.0472"/>
      <geometry>
        <mesh filename="package://assets/foot.stl"/>
      </geometry>
      <material name="foot_material">
        <color rgba="0.196078 0.196078 0.196078 1.0"/>
      </material>
    </visual>
    <collision>
      <origin xyz="4.33013e-05 -2.5e-05 -0.014785" rpy="3.14159 -1.79711e-16 -1.0472"/>
      <geometry>
        <mesh filename="package://assets/foot.stl"/>
      </geometry>
    </collision>
    <!-- Part dc15_a01_case_f_dummy_2 -->
    <visual>
      <origin xyz="0.108746 0.039063 -0.014785" rpy="-3.14159 1.79711e-16 2.0944"/>
      <geometry>
        <mesh filename="package://assets/dc15_a01_case_f_dummy.stl"/>
      </geometry>
      <material name="dc15_a01_case_f_dummy_2_material">
        <color rgba="0.262745 0.282353 0.301961 1.0"/>
      </material>
    </visual>
    <collision>
      <origin xyz="0.108746 0.039063 -0.014785" rpy="-3.14159 1.79711e-16 2.0944"/>
      <geometry>
        <mesh filename="package://assets/dc15_a01_case_f_dummy.stl"/>
      </geometry>
    </collision>
    <!-- Part dc15_a01_horn_dummy_4 -->
    <visual>
      <origin xyz="-0.000389711 -0.000275 -0.014785" rpy="3.14159 -1.79711e-16 -1.0472"/>
      <geometry>
        <mesh filename="package://assets/dc15_a01_horn_dummy.stl"/>
      </geometry>
      <material name="dc15_a01_horn_dummy_4_material">
        <color rgba="0.262745 0.282353 0.301961 1.0"/>
      </material>
    </visual>
    <collision>
      <origin xyz="-0.000389711 -0.000275 -0.014785" rpy="3.14159 -1.79711e-16 -1.0472"/>
      <geometry>
        <mesh filename="package://assets/dc15_a01_horn_dummy.stl"/>
      </geometry>
    </collision>
    <!-- Part drive_palonier__configuration_simple_axe -->
    <visual>
      <origin xyz="-0.0220836 0.01275 -0.017185" rpy="1.5708 3.45422e-16 2.61799"/>
      <geometry>
        <mesh filename="package://assets/drive_palonier__configuration_simple_axe.stl"/>
      </geometry>
      <material name="drive_palonier__configuration_simple_axe_material">
        <color rgba="0.623529 0.666667 0.701961 1.0"/>
      </material>
    </visual>
    <collision>
      <origin xyz="-0.0220836 0.01275 -0.017185" rpy="1.5708 3.45422e-16 2.61799"/>
      <geometry>
        <mesh filename="package://assets/drive_palonier__configuration_simple_axe.stl"/>
      </geometry>
    </collision>
    <!-- Part wj_wk00_0124bottomcase_45__configuration_simple_axe -->
    <visual>
      <origin xyz="-0.0220256 0.012753 -0.017185" rpy="1.5708 4.6369e-16 2.61799"/>
      <geometry>
        <mesh filename="package://assets/wj_wk00_0124bottomcase_45__configuration_simple_axe.stl"/>
      </geometry>
      <material name="wj_wk00_0124bottomcase_45__configuration_simple_axe_material">
        <color rgba="0.247059 0.243137 0.243137 1.0"/>
      </material>
    </visual>
    <collision>
      <origin xyz="-0.0220256 0.012753 -0.017185" rpy="1.5708 4.6369e-16 2.61799"/>
      <geometry>
        <mesh filename="package://assets/wj_wk00_0124bottomcase_45__configuration_simple_axe.stl"/>
      </geometry>
    </collision>
    <!-- Part dc15_a01_case_f_dummy_3 -->
    <visual>
      <origin xyz="-0.0106397 0.0174785 -0.014785" rpy="3.14159 -1.79711e-16 -1.0472"/>
      <geometry>
        <mesh filename="package://assets/dc15_a01_case_f_dummy.stl"/>
      </geometry>
      <material name="dc15_a01_case_f_dummy_3_material">
        <color rgba="0.262745 0.282353 0.301961 1.0"/>
      </material>
    </visual>
    <collision>
      <origin xyz="-0.0106397 0.0174785 -0.014785" rpy="3.14159 -1.79711e-16 -1.0472"/>
      <geometry>
        <mesh filename="package://assets/dc15_a01_case_f_dummy.stl"/>
      </geometry>
    </collision>
    <!-- Part wj_wk00_0123middlecase_56__configuration_simple_axe -->
    <visual>
      <origin xyz="-0.0220371 0.0127896 -0.017185" rpy="1.5708 -8.00364e-16 2.61799"/>
      <geometry>
        <mesh filename="package://assets/wj_wk00_0123middlecase_56__configuration_simple_axe.stl"/>
      </geometry>
      <material name="wj_wk00_0123middlecase_56__configuration_simple_axe_material">
        <color rgba="0.247059 0.243137 0.243137 1.0"/>
      </material>
    </visual>
    <collision>
      <origin xyz="-0.0220371 0.0127896 -0.017185" rpy="1.5708 -8.00364e-16 2.61799"/>
      <geometry>
        <mesh filename="package://assets/wj_wk00_0123middlecase_56__configuration_simple_axe.stl"/>
      </geometry>
    </collision>
    <!-- Part dc15_a01_horn_dummy_5 -->
    <visual>
      <origin xyz="0.0205433 0.000475 -0.014785" rpy="3.14159 1.42533e-16 3.14159"/>
      <geometry>
        <mesh filename="package://assets/dc15_a01_horn_dummy.stl"/>
      </geometry>
      <material name="dc15_a01_horn_dummy_5_material">
        <color rgba="0.262745 0.282353 0.301961 1.0"/>
      </material>
    </visual>
    <collision>
      <origin xyz="0.0205433 0.000475 -0.014785" rpy="3.14159 1.42533e-16 3.14159"/>
      <geometry>
        <mesh filename="package://assets/dc15_a01_horn_dummy.stl"/>
      </geometry>
    </collision>
    <!-- Part dc15_a01_case_b_dummy_3 -->
    <visual>
      <origin xyz="4.33013e-05 0.000475 -0.014785" rpy="-3.14159 1.97181e-17 3.14159"/>
      <geometry>
        <mesh filename="package://assets/dc15_a01_case_b_dummy.stl"/>
      </geometry>
      <material name="dc15_a01_case_b_dummy_3_material">
        <color rgba="0.262745 0.282353 0.301961 1.0"/>
      </material>
    </visual>
    <collision>
      <origin xyz="4.33013e-05 0.000475 -0.014785" rpy="-3.14159 1.97181e-17 3.14159"/>
      <geometry>
        <mesh filename="package://assets/dc15_a01_case_b_dummy.stl"/>
      </geometry>
    </collision>
    <!-- Part dc15_a01_case_f_dummy_4 -->
    <visual>
      <origin xyz="0.0205433 0.000475 -0.014785" rpy="-3.14159 1.97181e-17 3.14159"/>
      <geometry>
        <mesh filename="package://assets/dc15_a01_case_f_dummy.stl"/>
      </geometry>
      <material name="dc15_a01_case_f_dummy_4_material">
        <color rgba="0.262745 0.282353 0.301961 1.0"/>
      </material>
    </visual>
    <collision>
      <origin xyz="0.0205433 0.000475 -0.014785" rpy="-3.14159 1.97181e-17 3.14159"/>
      <geometry>
        <mesh filename="package://assets/dc15_a01_case_f_dummy.stl"/>
      </geometry>
    </collision>
    <!-- Part side_plate -->
    <visual>
      <origin xyz="4.33013e-05 -2.5e-05 -0.014785" rpy="3.14159 -1.79711e-16 -1.0472"/>
      <geometry>
        <mesh filename="package://assets/side_plate.stl"/>
      </geometry>
      <material name="side_plate_material">
        <color rgba="0.196078 0.196078 0.196078 1.0"/>
      </material>
    </visual>
    <collision>
      <origin xyz="4.33013e-05 -2.5e-05 -0.014785" rpy="3.14159 -1.79711e-16 -1.0472"/>
      <geometry>
        <mesh filename="package://assets/side_plate.stl"/>
      </geometry>
    </collision>
    <!-- Part dc15_a01_case_m_dummy_2 -->
    <visual>
      <origin xyz="-0.00977369 -0.0180285 -0.014785" rpy="3.14159 1.59993e-16 1.0472"/>
      <geometry>
        <mesh filename="package://assets/dc15_a01_case_m_dummy.stl"/>
      </geometry>
      <material name="dc15_a01_case_m_dummy_2_material">
        <color rgba="0.262745 0.282353 0.301961 1.0"/>
      </material>
    </visual>
    <collision>
      <origin xyz="-0.00977369 -0.0180285 -0.014785" rpy="3.14159 1.59993e-16 1.0472"/>
      <geometry>
        <mesh filename="package://assets/dc15_a01_case_m_dummy.stl"/>
      </geometry>
    </collision>
    <!-- Part dc15_a01_case_m_dummy_3 -->
    <visual>
      <origin xyz="4.33013e-05 0.000475 -0.014785" rpy="-3.14159 1.97181e-17 3.14159"/>
      <geometry>
        <mesh filename="package://assets/dc15_a01_case_m_dummy.stl"/>
      </geometry>
      <material name="dc15_a01_case_m_dummy_3_material">
        <color rgba="0.262745 0.282353 0.301961 1.0"/>
      </material>
    </visual>
    <collision>
      <origin xyz="4.33013e-05 0.000475 -0.014785" rpy="-3.14159 1.97181e-17 3.14159"/>
      <geometry>
        <mesh filename="package://assets/dc15_a01_case_m_dummy.stl"/>
      </geometry>
    </collision>
    <!-- Part side_plate_2 -->
    <visual>
      <origin xyz="4.33013e-05 -2.5e-05 -0.014785" rpy="-3.14159 1.97181e-17 3.14159"/>
      <geometry>
        <mesh filename="package://assets/side_plate.stl"/>
      </geometry>
      <material name="side_plate_2_material">
        <color rgba="0.196078 0.196078 0.196078 1.0"/>
      </material>
    </visual>
    <collision>
      <origin xyz="4.33013e-05 -2.5e-05 -0.014785" rpy="-3.14159 1.97181e-17 3.14159"/>
      <geometry>
        <mesh filename="package://assets/side_plate.stl"/>
      </geometry>
    </collision>
    <!-- Part dc15_a01_case_m_dummy_4 -->
    <visual>
      <origin xyz="0.0205433 0.000475 -0.014785" rpy="-3.14159 1.97181e-17 3.14159"/>
      <geometry>
        <mesh filename="package://assets/dc15_a01_case_m_dummy.stl"/>
      </geometry>
      <material name="dc15_a01_case_m_dummy_4_material">
        <color rgba="0.262745 0.282353 0.301961 1.0"/>
      </material>
    </visual>
    <collision>
      <origin xyz="0.0205433 0.000475 -0.014785" rpy="-3.14159 1.97181e-17 3.14159"/>
      <geometry>
        <mesh filename="package://assets/dc15_a01_case_m_dummy.stl"/>
      </geometry>
    </collision>
    <!-- Part dc15_a01_horn_dummy_6 -->
    <visual>
      <origin xyz="4.33013e-05 0.000475 -0.014785" rpy="-3.14159 1.97181e-17 3.14159"/>
      <geometry>
        <mesh filename="package://assets/dc15_a01_horn_dummy.stl"/>
      </geometry>
      <material name="dc15_a01_horn_dummy_6_material">
        <color rgba="0.262745 0.282353 0.301961 1.0"/>
      </material>
    </visual>
    <collision>
      <origin xyz="4.33013e-05 0.000475 -0.014785" rpy="-3.14159 1.97181e-17 3.14159"/>
      <geometry>
        <mesh filename="package://assets/dc15_a01_horn_dummy.stl"/>
      </geometry>
    </collision>
    <!-- Part side_plate_3 -->
    <visual>
      <origin xyz="4.33013e-05 -2.5e-05 -0.014785" rpy="3.14159 1.59993e-16 1.0472"/>
      <geometry>
        <mesh filename="package://assets/side_plate.stl"/>
      </geometry>
      <material name="side_plate_3_material">
        <color rgba="0.196078 0.196078 0.196078 1.0"/>
      </material>
    </visual>
    <collision>
      <origin xyz="4.33013e-05 -2.5e-05 -0.014785" rpy="3.14159 1.59993e-16 1.0472"/>
      <geometry>
        <mesh filename="package://assets/side_plate.stl"/>
      </geometry>
    </collision>
    <!-- Part top_body -->
    <visual>
      <origin xyz="2.23926e-06 1.6062e-05 -0.212785" rpy="-3.14159 -1.97181e-17 2.22045e-16"/>
      <geometry>
        <mesh filename="package://assets/top_body.stl"/>
      </geometry>
      <material name="top_body_material">
        <color rgba="1 1 1 1.0"/>
      </material>
    </visual>
    <collision>
      <origin xyz="2.23926e-06 1.6062e-05 -0.212785" rpy="-3.14159 -1.97181e-17 2.22045e-16"/>
      <geometry>
        <mesh filename="package://assets/top_body.stl"/>
      </geometry>
    </collision>
    <!-- Part wj_wk00_0122topcabinetcase_95__configuration_simple_axe -->
    <visual>
      <origin xyz="-0.0220836 0.01275 -0.017185" rpy="1.5708 -4.3975e-17 2.61799"/>
      <geometry>
        <mesh filename="package://assets/wj_wk00_0122topcabinetcase_95__configuration_simple_axe.stl"/>
      </geometry>
      <material name="wj_wk00_0122topcabinetcase_95__configuration_simple_axe_material">
        <color rgba="0.247059 0.243137 0.243137 1.0"/>
      </material>
    </visual>
    <collision>
      <origin xyz="-0.0220836 0.01275 -0.017185" rpy="1.5708 -4.3975e-17 2.61799"/>
      <geometry>
        <mesh filename="package://assets/wj_wk00_0122topcabinetcase_95__configuration_simple_axe.stl"/>
      </geometry>
    </collision>
    <!-- Part dc15_a01_case_m_dummy_5 -->
    <visual>
      <origin xyz="-0.0106397 0.0174785 -0.014785" rpy="3.14159 -1.79711e-16 -1.0472"/>
      <geometry>
        <mesh filename="package://assets/dc15_a01_case_m_dummy.stl"/>
      </geometry>
      <material name="dc15_a01_case_m_dummy_5_material">
        <color rgba="0.262745 0.282353 0.301961 1.0"/>
      </material>
    </visual>
    <collision>
      <origin xyz="-0.0106397 0.0174785 -0.014785" rpy="3.14159 -1.79711e-16 -1.0472"/>
      <geometry>
        <mesh filename="package://assets/dc15_a01_case_m_dummy.stl"/>
      </geometry>
    </collision>
    <!-- Part bottom_body -->
    <visual>
      <origin xyz="4.33013e-05 -2.5e-05 -0.213285" rpy="-3.14159 1.97181e-17 -3.14159"/>
      <geometry>
        <mesh filename="package://assets/bottom_body.stl"/>
      </geometry>
      <material name="bottom_body_material">
        <color rgba="1 1 1 1.0"/>
      </material>
    </visual>
    <collision>
      <origin xyz="4.33013e-05 -2.5e-05 -0.213285" rpy="-3.14159 1.97181e-17 -3.14159"/>
      <geometry>
        <mesh filename="package://assets/bottom_body.stl"/>
      </geometry>
    </collision>
    <!-- Part foot_2 -->
    <visual>
      <origin xyz="4.33013e-05 -2.5e-05 -0.014785" rpy="-3.14159 1.97181e-17 3.14159"/>
      <geometry>
        <mesh filename="package://assets/foot.stl"/>
      </geometry>
      <material name="foot_2_material">
        <color rgba="0.196078 0.196078 0.196078 1.0"/>
      </material>
    </visual>
    <collision>
      <origin xyz="4.33013e-05 -2.5e-05 -0.014785" rpy="-3.14159 1.97181e-17 3.14159"/>
      <geometry>
        <mesh filename="package://assets/foot.stl"/>
      </geometry>
    </collision>
    <!-- Part dc15_a01_case_f_dummy_5 -->
    <visual>
      <origin xyz="-0.00977369 -0.0180285 -0.014785" rpy="3.14159 1.59993e-16 1.0472"/>
      <geometry>
        <mesh filename="package://assets/dc15_a01_case_f_dummy.stl"/>
      </geometry>
      <material name="dc15_a01_case_f_dummy_5_material">
        <color rgba="0.262745 0.282353 0.301961 1.0"/>
      </material>
    </visual>
    <collision>
      <origin xyz="-0.00977369 -0.0180285 -0.014785" rpy="3.14159 1.59993e-16 1.0472"/>
      <geometry>
        <mesh filename="package://assets/dc15_a01_case_f_dummy.stl"/>
      </geometry>
    </collision>
    <!-- Part dc15_a01_case_b_dummy_4 -->
    <visual>
      <origin xyz="0.0205433 0.000475 -0.014785" rpy="-3.14159 1.97181e-17 3.14159"/>
      <geometry>
        <mesh filename="package://assets/dc15_a01_case_b_dummy.stl"/>
      </geometry>
      <material name="dc15_a01_case_b_dummy_4_material">
        <color rgba="0.262745 0.282353 0.301961 1.0"/>
      </material>
    </visual>
    <collision>
      <origin xyz="0.0205433 0.000475 -0.014785" rpy="-3.14159 1.97181e-17 3.14159"/>
      <geometry>
        <mesh filename="package://assets/dc15_a01_case_b_dummy.stl"/>
      </geometry>
    </collision>
    <!-- Part foot_3 -->
    <visual>
      <origin xyz="4.33013e-05 -2.5e-05 -0.014785" rpy="3.14159 1.59993e-16 1.0472"/>
      <geometry>
        <mesh filename="package://assets/foot.stl"/>
      </geometry>
      <material name="foot_3_material">
        <color rgba="0.196078 0.196078 0.196078 1.0"/>
      </material>
    </visual>
    <collision>
      <origin xyz="4.33013e-05 -2.5e-05 -0.014785" rpy="3.14159 1.59993e-16 1.0472"/>
      <geometry>
        <mesh filename="package://assets/foot.stl"/>
      </geometry>
    </collision>
    <!-- Part dc15_a01_case_b_dummy_5 -->
    <visual>
      <origin xyz="-0.0106397 0.0174785 -0.014785" rpy="3.14159 -1.79711e-16 -1.0472"/>
      <geometry>
        <mesh filename="package://assets/dc15_a01_case_b_dummy.stl"/>
      </geometry>
      <material name="dc15_a01_case_b_dummy_5_material">
        <color rgba="0.262745 0.282353 0.301961 1.0"/>
      </material>
    </visual>
    <collision>
      <origin xyz="-0.0106397 0.0174785 -0.014785" rpy="3.14159 -1.79711e-16 -1.0472"/>
      <geometry>
        <mesh filename="package://assets/dc15_a01_case_b_dummy.stl"/>
      </geometry>
    </collision>
    <!-- Part dc15_a01_case_b_dummy_6 -->
    <visual>
      <origin xyz="0.000476314 -0.000275 -0.014785" rpy="3.14159 1.59993e-16 1.0472"/>
      <geometry>
        <mesh filename="package://assets/dc15_a01_case_b_dummy.stl"/>
      </geometry>
      <material name="dc15_a01_case_b_dummy_6_material">
        <color rgba="0.262745 0.282353 0.301961 1.0"/>
      </material>
    </visual>
    <collision>
      <origin xyz="0.000476314 -0.000275 -0.014785" rpy="3.14159 1.59993e-16 1.0472"/>
      <geometry>
        <mesh filename="package://assets/dc15_a01_case_b_dummy.stl"/>
      </geometry>
    </collision>
    <!-- Part dc15_a01_case_m_dummy_6 -->
    <visual>
      <origin xyz="0.000476314 -0.000275 -0.014785" rpy="3.14159 1.59993e-16 1.0472"/>
      <geometry>
        <mesh filename="package://assets/dc15_a01_case_m_dummy.stl"/>
      </geometry>
      <material name="dc15_a01_case_m_dummy_6_material">
        <color rgba="0.262745 0.282353 0.301961 1.0"/>
      </material>
    </visual>
    <collision>
      <origin xyz="0.000476314 -0.000275 -0.014785" rpy="3.14159 1.59993e-16 1.0472"/>
      <geometry>
        <mesh filename="package://assets/dc15_a01_case_m_dummy.stl"/>
      </geometry>
    </collision>
    <!-- Part mid_plate -->
    <visual>
      <origin xyz="4.33013e-05 -2.5e-05 -0.014785" rpy="3.14159 1.59993e-16 1.0472"/>
      <geometry>
        <mesh filename="package://assets/mid_plate.stl"/>
      </geometry>
      <material name="mid_plate_material">
        <color rgba="0.196078 0.196078 0.196078 1.0"/>
      </material>
    </visual>
    <collision>
      <origin xyz="4.33013e-05 -2.5e-05 -0.014785" rpy="3.14159 1.59993e-16 1.0472"/>
      <geometry>
        <mesh filename="package://assets/mid_plate.stl"/>
      </geometry>
    </collision>
    <!-- Part dc15_a01_case_f_dummy_6 -->
    <visual>
      <origin xyz="4.33013e-05 0.000475 -0.014785" rpy="-3.14159 1.97181e-17 3.14159"/>
      <geometry>
        <mesh filename="package://assets/dc15_a01_case_f_dummy.stl"/>
      </geometry>
      <material name="dc15_a01_case_f_dummy_6_material">
        <color rgba="0.262745 0.282353 0.301961 1.0"/>
      </material>
    </visual>
    <collision>
      <origin xyz="4.33013e-05 0.000475 -0.014785" rpy="-3.14159 1.97181e-17 3.14159"/>
      <geometry>
        <mesh filename="package://assets/dc15_a01_case_f_dummy.stl"/>
      </geometry>
    </collision>
  </link>
  <!-- Link arm -->
  <link name="arm">
    <inertial>
      <origin xyz="0 0 0" rpy="0 0 0"/>
      <mass value="1e-09"/>
      <inertia ixx="1e-09" ixy="0" ixz="0" iyy="1e-09" iyz="0" izz="1e-09"/>
    </inertial>
    <!-- Part ball -->
    <visual>
      <origin xyz="0.038 -1.38778e-17 -0.00768" rpy="2.10544e-15 3.08206e-16 1.5708"/>
      <geometry>
        <mesh filename="package://assets/ball.stl"/>
      </geometry>
      <material name="ball_material">
        <color rgba="0.901961 0.901961 0.901961 1.0"/>
      </material>
    </visual>
    <collision>
      <origin xyz="0.038 -1.38778e-17 -0.00768" rpy="2.10544e-15 3.08206e-16 1.5708"/>
      <geometry>
        <mesh filename="package://assets/ball.stl"/>
      </geometry>
    </collision>
    <!-- Part arm -->
    <visual>
      <origin xyz="-0.01025 -0.03 -0.0425915" rpy="-1.5708 2.19947e-16 5.18987e-33"/>
      <geometry>
        <mesh filename="package://assets/arm.stl"/>
      </geometry>
      <material name="arm_material">
        <color rgba="0.196078 0.196078 0.196078 1.0"/>
      </material>
    </visual>
    <collision>
      <origin xyz="-0.01025 -0.03 -0.0425915" rpy="-1.5708 2.19947e-16 5.18987e-33"/>
      <geometry>
        <mesh filename="package://assets/arm.stl"/>
      </geometry>
    </collision>
  </link>
  <!-- Link passive_1_link_x -->
  <link name="passive_1_link_x">
    <inertial>
      <origin xyz="0 0 0" rpy="0 0 0"/>
      <mass value="1e-09"/>
      <inertia ixx="1e-09" ixy="0" ixz="0" iyy="1e-09" iyz="0" izz="1e-09"/>
    </inertial>
  </link>
  <!-- Link passive_1_link_y -->
  <link name="passive_1_link_y">
    <inertial>
      <origin xyz="0 0 0" rpy="0 0 0"/>
      <mass value="1e-09"/>
      <inertia ixx="1e-09" ixy="0" ixz="0" iyy="1e-09" iyz="0" izz="1e-09"/>
    </inertial>
  </link>
  <!-- Link rod -->
  <link name="rod">
    <inertial>
      <origin xyz="0 0 0" rpy="0 0 0"/>
      <mass value="1e-09"/>
      <inertia ixx="1e-09" ixy="0" ixz="0" iyy="1e-09" iyz="0" izz="1e-09"/>
    </inertial>
    <!-- Part rod -->
    <visual>
      <origin xyz="0.00371031 0.0370326 -0.0564076" rpy="0.01484 -1.08842 -4.16182e-16"/>
      <geometry>
        <mesh filename="package://assets/rod.stl"/>
      </geometry>
      <material name="rod_material">
        <color rgba="0.8 0.8 0.8 1.0"/>
      </material>
    </visual>
    <collision>
      <origin xyz="0.00371031 0.0370326 -0.0564076" rpy="0.01484 -1.08842 -4.16182e-16"/>
      <geometry>
        <mesh filename="package://assets/rod.stl"/>
      </geometry>
    </collision>
    <!-- Part shape -->
    <visual>
      <origin xyz="0 1.38778e-17 -6.93889e-18" rpy="-3.1327e-17 -1.84285e-18 4.57538e-18"/>
      <geometry>
        <mesh filename="package://assets/shape.stl"/>
      </geometry>
      <material name="shape_material">
        <color rgba="0.901961 0.901961 0.901961 1.0"/>
      </material>
    </visual>
    <collision>
      <origin xyz="0 1.38778e-17 -6.93889e-18" rpy="-3.1327e-17 -1.84285e-18 4.57538e-18"/>
      <geometry>
        <mesh filename="package://assets/shape.stl"/>
      </geometry>
    </collision>
    <!-- Part shape_2 -->
    <visual>
      <origin xyz="-0.0900003 -2.77556e-17 -3.1572e-16" rpy="-4.33066e-15 2.30363e-14 -3.14159"/>
      <geometry>
        <mesh filename="package://assets/shape.stl"/>
      </geometry>
      <material name="shape_2_material">
        <color rgba="0.901961 0.901961 0.901961 1.0"/>
      </material>
    </visual>
    <collision>
      <origin xyz="-0.0900003 -2.77556e-17 -3.1572e-16" rpy="-4.33066e-15 2.30363e-14 -3.14159"/>
      <geometry>
        <mesh filename="package://assets/shape.stl"/>
      </geometry>
    </collision>
  </link>
  <!-- Frame closing_1_1 (dummy link + fixed joint) -->
  <link name="closing_1_1">
    <origin xyz="0 0 0" rpy="0 -0 0"/>
    <inertial>
      <origin xyz="0 0 0" rpy="0 0 0"/>
      <mass value="1e-9"/>
      <inertia ixx="0" ixy="0" ixz="0" iyy="0" iyz="0" izz="0"/>
    </inertial>
  </link>
  <joint name="closing_1_1_frame" type="fixed">
    <origin xyz="-0.0900003 -2.77556e-17 -3.1572e-16" rpy="-4.33066e-15 2.30363e-14 -3.14159"/>
    <parent link="rod"/>
    <child link="closing_1_1"/>
    <axis xyz="0 0 0"/>
  </joint>
  <!-- Joint from passive_1_link_y to rod -->
  <joint name="passive_1_z" type="revolute">
    <origin xyz="0 1.38778e-17 -6.93889e-18" rpy="-3.1327e-17 -1.84285e-18 4.57538e-18"/>
    <parent link="passive_1_link_y"/>
    <child link="rod"/>
    <axis xyz="0 0 1"/>
    <limit effort="10" velocity="10" lower="-3.141592653589793" upper="3.141592653589793"/>
  </joint>
  <!-- Joint from passive_1_link_x to passive_1_link_y -->
  <joint name="passive_1_y" type="revolute">
    <origin xyz="0 1.38778e-17 -6.93889e-18" rpy="-3.1327e-17 -1.84285e-18 4.57538e-18"/>
    <parent link="passive_1_link_x"/>
    <child link="passive_1_link_y"/>
    <axis xyz="0 1 0"/>
    <limit effort="10" velocity="10" lower="-3.141592653589793" upper="3.141592653589793"/>
  </joint>
  <!-- Joint from arm to passive_1_link_x -->
  <joint name="passive_1_x" type="revolute">
    <origin xyz="0.038 -3.19189e-16 -0.00768" rpy="-0.173384 -0.0202587 1.08831"/>
    <parent link="arm"/>
    <child link="passive_1_link_x"/>
    <axis xyz="1 0 0"/>
    <limit effort="10" velocity="10" lower="-3.141592653589793" upper="3.141592653589793"/>
  </joint>
  <!-- Joint from main_plate to arm -->
  <joint name="1" type="revolute">
    <origin xyz="0.0313706 0.0298975 -0.044785" rpy="1.5708 -1.04478e-14 2.0944"/>
    <parent link="main_plate"/>
    <child link="arm"/>
    <axis xyz="0 0 1"/>
    <limit effort="10" velocity="10" lower="-1.39626" upper="1.39626"/>
  </joint>
  <!-- Link arm_2 -->
  <link name="arm_2">
    <inertial>
      <origin xyz="0 0 0" rpy="0 0 0"/>
      <mass value="1e-09"/>
      <inertia ixx="1e-09" ixy="0" ixz="0" iyy="1e-09" iyz="0" izz="1e-09"/>
    </inertial>
    <!-- Part ball_2 -->
    <visual>
      <origin xyz="0.038 0 -0.00768" rpy="-1.74899e-15 9.23518e-15 -1.5708"/>
      <geometry>
        <mesh filename="package://assets/ball.stl"/>
      </geometry>
      <material name="ball_2_material">
        <color rgba="0.901961 0.901961 0.901961 1.0"/>
      </material>
    </visual>
    <collision>
      <origin xyz="0.038 0 -0.00768" rpy="-1.74899e-15 9.23518e-15 -1.5708"/>
      <geometry>
        <mesh filename="package://assets/ball.stl"/>
      </geometry>
    </collision>
    <!-- Part arm_2 -->
    <visual>
      <origin xyz="-0.01025 -0.03 -0.0425915" rpy="-1.5708 2.58696e-16 0"/>
      <geometry>
        <mesh filename="package://assets/arm.stl"/>
      </geometry>
      <material name="arm_2_material">
        <color rgba="0.196078 0.196078 0.196078 1.0"/>
      </material>
    </visual>
    <collision>
      <origin xyz="-0.01025 -0.03 -0.0425915" rpy="-1.5708 2.58696e-16 0"/>
      <geometry>
        <mesh filename="package://assets/arm.stl"/>
      </geometry>
    </collision>
  </link>
  <!-- Link passive_2_link_x -->
  <link name="passive_2_link_x">
    <inertial>
      <origin xyz="0 0 0" rpy="0 0 0"/>
      <mass value="1e-09"/>
      <inertia ixx="1e-09" ixy="0" ixz="0" iyy="1e-09" iyz="0" izz="1e-09"/>
    </inertial>
  </link>
  <!-- Link passive_2_link_y -->
  <link name="passive_2_link_y">
    <inertial>
      <origin xyz="0 0 0" rpy="0 0 0"/>
      <mass value="1e-09"/>
      <inertia ixx="1e-09" ixy="0" ixz="0" iyy="1e-09" iyz="0" izz="1e-09"/>
    </inertial>
  </link>
  <!-- Link shape -->
  <link name="shape">
    <inertial>
      <origin xyz="0 0 0" rpy="0 0 0"/>
      <mass value="1e-09"/>
      <inertia ixx="1e-09" ixy="0" ixz="0" iyy="1e-09" iyz="0" izz="1e-09"/>
    </inertial>
    <!-- Part shape_3 -->
    <visual>
      <origin xyz="-0.0900003 1.38778e-16 -3.46945e-17" rpy="-5.45526e-18 1.49021e-17 3.14159"/>
      <geometry>
        <mesh filename="package://assets/shape.stl"/>
      </geometry>
      <material name="shape_3_material">
        <color rgba="0.901961 0.901961 0.901961 1.0"/>
      </material>
    </visual>
    <collision>
      <origin xyz="-0.0900003 1.38778e-16 -3.46945e-17" rpy="-5.45526e-18 1.49021e-17 3.14159"/>
      <geometry>
        <mesh filename="package://assets/shape.stl"/>
      </geometry>
    </collision>
    <!-- Part shape_4 -->
    <visual>
      <origin xyz="-6.93889e-18 0 0" rpy="-4.71327e-17 -1.08554e-17 -5.04809e-17"/>
      <geometry>
        <mesh filename="package://assets/shape.stl"/>
      </geometry>
      <material name="shape_4_material">
        <color rgba="0.901961 0.901961 0.901961 1.0"/>
      </material>
    </visual>
    <collision>
      <origin xyz="-6.93889e-18 0 0" rpy="-4.71327e-17 -1.08554e-17 -5.04809e-17"/>
      <geometry>
        <mesh filename="package://assets/shape.stl"/>
      </geometry>
    </collision>
    <!-- Part rod_2 -->
    <visual>
      <origin xyz="0.00371031 0.0370326 -0.0564076" rpy="0.01484 -1.08842 7.37504e-14"/>
      <geometry>
        <mesh filename="package://assets/rod.stl"/>
      </geometry>
      <material name="rod_2_material">
        <color rgba="0.8 0.8 0.8 1.0"/>
      </material>
    </visual>
    <collision>
      <origin xyz="0.00371031 0.0370326 -0.0564076" rpy="0.01484 -1.08842 7.37504e-14"/>
      <geometry>
        <mesh filename="package://assets/rod.stl"/>
      </geometry>
    </collision>
  </link>
  <!-- Frame closing_2_1 (dummy link + fixed joint) -->
  <link name="closing_2_1">
    <origin xyz="0 0 0" rpy="0 -0 0"/>
    <inertial>
      <origin xyz="0 0 0" rpy="0 0 0"/>
      <mass value="1e-9"/>
      <inertia ixx="0" ixy="0" ixz="0" iyy="0" iyz="0" izz="0"/>
    </inertial>
  </link>
  <joint name="closing_2_1_frame" type="fixed">
    <origin xyz="-0.0900003 1.38778e-16 -3.46945e-17" rpy="-5.45526e-18 1.49021e-17 3.14159"/>
    <parent link="shape"/>
    <child link="closing_2_1"/>
    <axis xyz="0 0 0"/>
  </joint>
  <!-- Joint from passive_2_link_y to shape -->
  <joint name="passive_2_z" type="revolute">
    <origin xyz="-6.93889e-18 0 0" rpy="-4.71327e-17 -1.08554e-17 -5.04809e-17"/>
    <parent link="passive_2_link_y"/>
    <child link="shape"/>
    <axis xyz="0 0 1"/>
    <limit effort="10" velocity="10" lower="-3.141592653589793" upper="3.141592653589793"/>
  </joint>
  <!-- Joint from passive_2_link_x to passive_2_link_y -->
  <joint name="passive_2_y" type="revolute">
    <origin xyz="-6.93889e-18 0 0" rpy="-4.71327e-17 -1.08554e-17 -5.04809e-17"/>
    <parent link="passive_2_link_x"/>
    <child link="passive_2_link_y"/>
    <axis xyz="0 1 0"/>
    <limit effort="10" velocity="10" lower="-3.141592653589793" upper="3.141592653589793"/>
  </joint>
  <!-- Joint from arm_2 to passive_2_link_x -->
  <joint name="passive_2_x" type="revolute">
    <origin xyz="0.038 8.32667e-17 -0.00768" rpy="-0.186454 -0.0202587 -1.08831"/>
    <parent link="arm_2"/>
    <child link="passive_2_link_x"/>
    <axis xyz="1 0 0"/>
    <limit effort="10" velocity="10" lower="-3.141592653589793" upper="3.141592653589793"/>
  </joint>
  <!-- Joint from main_plate to arm_2 -->
  <joint name="2" type="revolute">
    <origin xyz="0.0416206 0.012144 -0.044785" rpy="-1.5708 1.45885e-14 -1.0472"/>
    <parent link="main_plate"/>
    <child link="arm_2"/>
    <axis xyz="0 0 1"/>
    <limit effort="10" velocity="10" lower="-1.39626" upper="1.39626"/>
  </joint>
  <!-- Link arm_3 -->
  <link name="arm_3">
    <inertial>
      <origin xyz="0 0 0" rpy="0 0 0"/>
      <mass value="1e-09"/>
      <inertia ixx="1e-09" ixy="0" ixz="0" iyy="1e-09" iyz="0" izz="1e-09"/>
    </inertial>
    <!-- Part arm_3 -->
    <visual>
      <origin xyz="-0.01025 -0.03 -0.0425915" rpy="-1.5708 2.89121e-16 6.16298e-33"/>
      <geometry>
        <mesh filename="package://assets/arm.stl"/>
      </geometry>
      <material name="arm_3_material">
        <color rgba="0.196078 0.196078 0.196078 1.0"/>
      </material>
    </visual>
    <collision>
      <origin xyz="-0.01025 -0.03 -0.0425915" rpy="-1.5708 2.89121e-16 6.16298e-33"/>
      <geometry>
        <mesh filename="package://assets/arm.stl"/>
      </geometry>
    </collision>
    <!-- Part ball_3 -->
    <visual>
      <origin xyz="0.038 2.77556e-17 -0.00768" rpy="1.15188e-16 -2.03523e-16 1.5708"/>
      <geometry>
        <mesh filename="package://assets/ball.stl"/>
      </geometry>
      <material name="ball_3_material">
        <color rgba="0.901961 0.901961 0.901961 1.0"/>
      </material>
    </visual>
    <collision>
      <origin xyz="0.038 2.77556e-17 -0.00768" rpy="1.15188e-16 -2.03523e-16 1.5708"/>
      <geometry>
        <mesh filename="package://assets/ball.stl"/>
      </geometry>
    </collision>
  </link>
  <!-- Link passive_3_link_x -->
  <link name="passive_3_link_x">
    <inertial>
      <origin xyz="0 0 0" rpy="0 0 0"/>
      <mass value="1e-09"/>
      <inertia ixx="1e-09" ixy="0" ixz="0" iyy="1e-09" iyz="0" izz="1e-09"/>
    </inertial>
  </link>
  <!-- Link passive_3_link_y -->
  <link name="passive_3_link_y">
    <inertial>
      <origin xyz="0 0 0" rpy="0 0 0"/>
      <mass value="1e-09"/>
      <inertia ixx="1e-09" ixy="0" ixz="0" iyy="1e-09" iyz="0" izz="1e-09"/>
    </inertial>
  </link>
  <!-- Link shape_2 -->
  <link name="shape_2">
    <inertial>
      <origin xyz="0 0 0" rpy="0 0 0"/>
      <mass value="1e-09"/>
      <inertia ixx="1e-09" ixy="0" ixz="0" iyy="1e-09" iyz="0" izz="1e-09"/>
    </inertial>
    <!-- Part rod_3 -->
    <visual>
      <origin xyz="0.00371031 0.0370326 -0.0564076" rpy="0.01484 -1.08842 1.20162e-17"/>
      <geometry>
        <mesh filename="package://assets/rod.stl"/>
      </geometry>
      <material name="rod_3_material">
        <color rgba="0.8 0.8 0.8 1.0"/>
      </material>
    </visual>
    <collision>
      <origin xyz="0.00371031 0.0370326 -0.0564076" rpy="0.01484 -1.08842 1.20162e-17"/>
      <geometry>
        <mesh filename="package://assets/rod.stl"/>
      </geometry>
    </collision>
    <!-- Part shape_5 -->
    <visual>
      <origin xyz="6.93889e-18 0 -3.46945e-18" rpy="1.84422e-17 -4.71284e-18 1.5244e-17"/>
      <geometry>
        <mesh filename="package://assets/shape.stl"/>
      </geometry>
      <material name="shape_5_material">
        <color rgba="0.901961 0.901961 0.901961 1.0"/>
      </material>
    </visual>
    <collision>
      <origin xyz="6.93889e-18 0 -3.46945e-18" rpy="1.84422e-17 -4.71284e-18 1.5244e-17"/>
      <geometry>
        <mesh filename="package://assets/shape.stl"/>
      </geometry>
    </collision>
    <!-- Part shape_6 -->
    <visual>
      <origin xyz="-0.0900003 -1.38778e-17 -9.71445e-17" rpy="-1.09454e-16 6.55503e-17 3.14159"/>
      <geometry>
        <mesh filename="package://assets/shape.stl"/>
      </geometry>
      <material name="shape_6_material">
        <color rgba="0.901961 0.901961 0.901961 1.0"/>
      </material>
    </visual>
    <collision>
      <origin xyz="-0.0900003 -1.38778e-17 -9.71445e-17" rpy="-1.09454e-16 6.55503e-17 3.14159"/>
      <geometry>
        <mesh filename="package://assets/shape.stl"/>
      </geometry>
    </collision>
  </link>
  <!-- Frame closing_3_1 (dummy link + fixed joint) -->
  <link name="closing_3_1">
    <origin xyz="0 0 0" rpy="0 -0 0"/>
    <inertial>
      <origin xyz="0 0 0" rpy="0 0 0"/>
      <mass value="1e-9"/>
      <inertia ixx="0" ixy="0" ixz="0" iyy="0" iyz="0" izz="0"/>
    </inertial>
  </link>
  <joint name="closing_3_1_frame" type="fixed">
    <origin xyz="-0.0900003 -1.38778e-17 -9.71445e-17" rpy="-1.09454e-16 6.55503e-17 3.14159"/>
    <parent link="shape_2"/>
    <child link="closing_3_1"/>
    <axis xyz="0 0 0"/>
  </joint>
  <!-- Joint from passive_3_link_y to shape_2 -->
  <joint name="passive_3_z" type="revolute">
    <origin xyz="6.93889e-18 0 -3.46945e-18" rpy="1.84422e-17 -4.71284e-18 1.5244e-17"/>
    <parent link="passive_3_link_y"/>
    <child link="shape_2"/>
    <axis xyz="0 0 1"/>
    <limit effort="10" velocity="10" lower="-3.141592653589793" upper="3.141592653589793"/>
  </joint>
  <!-- Joint from passive_3_link_x to passive_3_link_y -->
  <joint name="passive_3_y" type="revolute">
    <origin xyz="6.93889e-18 0 -3.46945e-18" rpy="1.84422e-17 -4.71284e-18 1.5244e-17"/>
    <parent link="passive_3_link_x"/>
    <child link="passive_3_link_y"/>
    <axis xyz="0 1 0"/>
    <limit effort="10" velocity="10" lower="-3.141592653589793" upper="3.141592653589793"/>
  </joint>
  <!-- Joint from arm_3 to passive_3_link_x -->
  <joint name="passive_3_x" type="revolute">
    <origin xyz="0.038 -1.38778e-17 -0.00768" rpy="2.99943 -0.0202587 1.08831"/>
    <parent link="arm_3"/>
    <child link="passive_3_link_x"/>
    <axis xyz="1 0 0"/>
    <limit effort="10" velocity="10" lower="-3.141592653589793" upper="3.141592653589793"/>
  </joint>
  <!-- Joint from main_plate to arm_3 -->
  <joint name="3" type="revolute">
    <origin xyz="0.0102933 -0.0421165 -0.044785" rpy="1.5708 -5.55112e-17 1.58503e-16"/>
    <parent link="main_plate"/>
    <child link="arm_3"/>
    <axis xyz="0 0 1"/>
    <limit effort="10" velocity="10" lower="-1.39626" upper="1.39626"/>
  </joint>
  <!-- Link ball -->
  <link name="ball">
    <inertial>
      <origin xyz="0 0 0" rpy="0 0 0"/>
      <mass value="1e-09"/>
      <inertia ixx="1e-09" ixy="0" ixz="0" iyy="1e-09" iyz="0" izz="1e-09"/>
    </inertial>
    <!-- Part ball_4 -->
    <visual>
      <origin xyz="0.038 0 -0.00768" rpy="-1.73323e-16 -4.55048e-16 -1.5708"/>
      <geometry>
        <mesh filename="package://assets/ball.stl"/>
      </geometry>
      <material name="ball_4_material">
        <color rgba="0.901961 0.901961 0.901961 1.0"/>
      </material>
    </visual>
    <collision>
      <origin xyz="0.038 0 -0.00768" rpy="-1.73323e-16 -4.55048e-16 -1.5708"/>
      <geometry>
        <mesh filename="package://assets/ball.stl"/>
      </geometry>
    </collision>
    <!-- Part arm_4 -->
    <visual>
      <origin xyz="-0.01025 -0.03 -0.0425915" rpy="-1.5708 2.89121e-16 -7.88861e-31"/>
      <geometry>
        <mesh filename="package://assets/arm.stl"/>
      </geometry>
      <material name="arm_4_material">
        <color rgba="0.196078 0.196078 0.196078 1.0"/>
      </material>
    </visual>
    <collision>
      <origin xyz="-0.01025 -0.03 -0.0425915" rpy="-1.5708 2.89121e-16 -7.88861e-31"/>
      <geometry>
        <mesh filename="package://assets/arm.stl"/>
      </geometry>
    </collision>
  </link>
  <!-- Link passive_4_link_x -->
  <link name="passive_4_link_x">
    <inertial>
      <origin xyz="0 0 0" rpy="0 0 0"/>
      <mass value="1e-09"/>
      <inertia ixx="1e-09" ixy="0" ixz="0" iyy="1e-09" iyz="0" izz="1e-09"/>
    </inertial>
  </link>
  <!-- Link passive_4_link_y -->
  <link name="passive_4_link_y">
    <inertial>
      <origin xyz="0 0 0" rpy="0 0 0"/>
      <mass value="1e-09"/>
      <inertia ixx="1e-09" ixy="0" ixz="0" iyy="1e-09" iyz="0" izz="1e-09"/>
    </inertial>
  </link>
  <!-- Link shape_3 -->
  <link name="shape_3">
    <inertial>
      <origin xyz="0 0 0" rpy="0 0 0"/>
      <mass value="1e-09"/>
      <inertia ixx="1e-09" ixy="0" ixz="0" iyy="1e-09" iyz="0" izz="1e-09"/>
    </inertial>
    <!-- Part shape_7 -->
    <visual>
      <origin xyz="-0.0900003 1.38778e-17 3.01842e-16" rpy="5.86424e-15 -4.14539e-15 3.14159"/>
      <geometry>
        <mesh filename="package://assets/shape.stl"/>
      </geometry>
      <material name="shape_7_material">
        <color rgba="0.901961 0.901961 0.901961 1.0"/>
      </material>
    </visual>
    <collision>
      <origin xyz="-0.0900003 1.38778e-17 3.01842e-16" rpy="5.86424e-15 -4.14539e-15 3.14159"/>
      <geometry>
        <mesh filename="package://assets/shape.stl"/>
      </geometry>
    </collision>
    <!-- Part rod_4 -->
    <visual>
      <origin xyz="0.00371031 0.0370326 -0.0564076" rpy="0.01484 -1.08842 1.25848e-17"/>
      <geometry>
        <mesh filename="package://assets/rod.stl"/>
      </geometry>
      <material name="rod_4_material">
        <color rgba="0.8 0.8 0.8 1.0"/>
      </material>
    </visual>
    <collision>
      <origin xyz="0.00371031 0.0370326 -0.0564076" rpy="0.01484 -1.08842 1.25848e-17"/>
      <geometry>
        <mesh filename="package://assets/rod.stl"/>
      </geometry>
    </collision>
    <!-- Part shape_8 -->
    <visual>
      <origin xyz="-1.38778e-17 0 -4.33681e-18" rpy="2.96221e-17 -6.36981e-17 -1.30539e-16"/>
      <geometry>
        <mesh filename="package://assets/shape.stl"/>
      </geometry>
      <material name="shape_8_material">
        <color rgba="0.901961 0.901961 0.901961 1.0"/>
      </material>
    </visual>
    <collision>
      <origin xyz="-1.38778e-17 0 -4.33681e-18" rpy="2.96221e-17 -6.36981e-17 -1.30539e-16"/>
      <geometry>
        <mesh filename="package://assets/shape.stl"/>
      </geometry>
    </collision>
  </link>
  <!-- Frame closing_4_1 (dummy link + fixed joint) -->
  <link name="closing_4_1">
    <origin xyz="0 0 0" rpy="0 -0 0"/>
    <inertial>
      <origin xyz="0 0 0" rpy="0 0 0"/>
      <mass value="1e-9"/>
      <inertia ixx="0" ixy="0" ixz="0" iyy="0" iyz="0" izz="0"/>
    </inertial>
  </link>
  <joint name="closing_4_1_frame" type="fixed">
    <origin xyz="-0.0900003 1.38778e-17 3.01842e-16" rpy="5.86424e-15 -4.14539e-15 3.14159"/>
    <parent link="shape_3"/>
    <child link="closing_4_1"/>
    <axis xyz="0 0 0"/>
  </joint>
  <!-- Joint from passive_4_link_y to shape_3 -->
  <joint name="passive_4_z" type="revolute">
    <origin xyz="-1.38778e-17 0 -4.33681e-18" rpy="2.96221e-17 -6.36981e-17 -1.30539e-16"/>
    <parent link="passive_4_link_y"/>
    <child link="shape_3"/>
    <axis xyz="0 0 1"/>
    <limit effort="10" velocity="10" lower="-3.141592653589793" upper="3.141592653589793"/>
  </joint>
  <!-- Joint from passive_4_link_x to passive_4_link_y -->
  <joint name="passive_4_y" type="revolute">
    <origin xyz="-1.38778e-17 0 -4.33681e-18" rpy="2.96221e-17 -6.36981e-17 -1.30539e-16"/>
    <parent link="passive_4_link_x"/>
    <child link="passive_4_link_y"/>
    <axis xyz="0 1 0"/>
    <limit effort="10" velocity="10" lower="-3.141592653589793" upper="3.141592653589793"/>
  </joint>
  <!-- Joint from ball to passive_4_link_x -->
  <joint name="passive_4_x" type="revolute">
    <origin xyz="0.038 -1.38778e-16 -0.00768" rpy="-2.75098 -0.0202587 -1.08831"/>
    <parent link="ball"/>
    <child link="passive_4_link_x"/>
    <axis xyz="1 0 0"/>
    <limit effort="10" velocity="10" lower="-3.141592653589793" upper="3.141592653589793"/>
  </joint>
  <!-- Joint from main_plate to ball -->
  <joint name="4" type="revolute">
    <origin xyz="-0.0102067 -0.0421165 -0.044785" rpy="-1.5708 4.43797e-15 -3.14159"/>
    <parent link="main_plate"/>
    <child link="ball"/>
    <axis xyz="0 0 1"/>
    <limit effort="10" velocity="10" lower="-1.39626" upper="1.39626"/>
  </joint>
  <!-- Link arm_4 -->
  <link name="arm_4">
    <inertial>
      <origin xyz="0 0 0" rpy="0 0 0"/>
      <mass value="1e-09"/>
      <inertia ixx="1e-09" ixy="0" ixz="0" iyy="1e-09" iyz="0" izz="1e-09"/>
    </inertial>
    <!-- Part ball_5 -->
    <visual>
      <origin xyz="0.038 1.38778e-17 -0.00768" rpy="-3.14159 -1.24738e-15 1.5708"/>
      <geometry>
        <mesh filename="package://assets/ball.stl"/>
      </geometry>
      <material name="ball_5_material">
        <color rgba="0.901961 0.901961 0.901961 1.0"/>
      </material>
    </visual>
    <collision>
      <origin xyz="0.038 1.38778e-17 -0.00768" rpy="-3.14159 -1.24738e-15 1.5708"/>
      <geometry>
        <mesh filename="package://assets/ball.stl"/>
      </geometry>
    </collision>
    <!-- Part arm_5 -->
    <visual>
      <origin xyz="-0.01025 -0.03 -0.0425915" rpy="-1.5708 2.2603e-16 -4.74694e-32"/>
      <geometry>
        <mesh filename="package://assets/arm.stl"/>
      </geometry>
      <material name="arm_5_material">
        <color rgba="0.196078 0.196078 0.196078 1.0"/>
      </material>
    </visual>
    <collision>
      <origin xyz="-0.01025 -0.03 -0.0425915" rpy="-1.5708 2.2603e-16 -4.74694e-32"/>
      <geometry>
        <mesh filename="package://assets/arm.stl"/>
      </geometry>
    </collision>
  </link>
  <!-- Link passive_5_link_x -->
  <link name="passive_5_link_x">
    <inertial>
      <origin xyz="0 0 0" rpy="0 0 0"/>
      <mass value="1e-09"/>
      <inertia ixx="1e-09" ixy="0" ixz="0" iyy="1e-09" iyz="0" izz="1e-09"/>
    </inertial>
  </link>
  <!-- Link passive_5_link_y -->
  <link name="passive_5_link_y">
    <inertial>
      <origin xyz="0 0 0" rpy="0 0 0"/>
      <mass value="1e-09"/>
      <inertia ixx="1e-09" ixy="0" ixz="0" iyy="1e-09" iyz="0" izz="1e-09"/>
    </inertial>
  </link>
  <!-- Link shape_4 -->
  <link name="shape_4">
    <inertial>
      <origin xyz="0 0 0" rpy="0 0 0"/>
      <mass value="1e-09"/>
      <inertia ixx="1e-09" ixy="0" ixz="0" iyy="1e-09" iyz="0" izz="1e-09"/>
    </inertial>
    <!-- Part shape_9 -->
    <visual>
      <origin xyz="-0.0900003 6.93889e-18 1.72085e-15" rpy="-3.97467e-14 -2.23603e-14 -3.14159"/>
      <geometry>
        <mesh filename="package://assets/shape.stl"/>
      </geometry>
      <material name="shape_9_material">
        <color rgba="0.901961 0.901961 0.901961 1.0"/>
      </material>
    </visual>
    <collision>
      <origin xyz="-0.0900003 6.93889e-18 1.72085e-15" rpy="-3.97467e-14 -2.23603e-14 -3.14159"/>
      <geometry>
        <mesh filename="package://assets/shape.stl"/>
      </geometry>
    </collision>
    <!-- Part rod_5 -->
    <visual>
      <origin xyz="0.00371031 0.0370326 -0.0564076" rpy="0.01484 -1.08842 -4.36661e-17"/>
      <geometry>
        <mesh filename="package://assets/rod.stl"/>
      </geometry>
      <material name="rod_5_material">
        <color rgba="0.8 0.8 0.8 1.0"/>
      </material>
    </visual>
    <collision>
      <origin xyz="0.00371031 0.0370326 -0.0564076" rpy="0.01484 -1.08842 -4.36661e-17"/>
      <geometry>
        <mesh filename="package://assets/rod.stl"/>
      </geometry>
    </collision>
    <!-- Part shape_10 -->
    <visual>
      <origin xyz="0 1.38778e-17 0" rpy="-3.59448e-17 -1.53626e-17 -3.22246e-17"/>
      <geometry>
        <mesh filename="package://assets/shape.stl"/>
      </geometry>
      <material name="shape_10_material">
        <color rgba="0.901961 0.901961 0.901961 1.0"/>
      </material>
    </visual>
    <collision>
      <origin xyz="0 1.38778e-17 0" rpy="-3.59448e-17 -1.53626e-17 -3.22246e-17"/>
      <geometry>
        <mesh filename="package://assets/shape.stl"/>
      </geometry>
    </collision>
  </link>
  <!-- Frame closing_5_1 (dummy link + fixed joint) -->
  <link name="closing_5_1">
    <origin xyz="0 0 0" rpy="0 -0 0"/>
    <inertial>
      <origin xyz="0 0 0" rpy="0 0 0"/>
      <mass value="1e-9"/>
      <inertia ixx="0" ixy="0" ixz="0" iyy="0" iyz="0" izz="0"/>
    </inertial>
  </link>
  <joint name="closing_5_1_frame" type="fixed">
    <origin xyz="-0.0900003 6.93889e-18 1.72085e-15" rpy="-3.97467e-14 -2.23603e-14 -3.14159"/>
    <parent link="shape_4"/>
    <child link="closing_5_1"/>
    <axis xyz="0 0 0"/>
  </joint>
  <!-- Joint from passive_5_link_y to shape_4 -->
  <joint name="passive_5_z" type="revolute">
    <origin xyz="0 1.38778e-17 0" rpy="-3.59448e-17 -1.53626e-17 -3.22246e-17"/>
    <parent link="passive_5_link_y"/>
    <child link="shape_4"/>
    <axis xyz="0 0 1"/>
    <limit effort="10" velocity="10" lower="-3.141592653589793" upper="3.141592653589793"/>
  </joint>
  <!-- Joint from passive_5_link_x to passive_5_link_y -->
  <joint name="passive_5_y" type="revolute">
    <origin xyz="0 1.38778e-17 0" rpy="-3.59448e-17 -1.53626e-17 -3.22246e-17"/>
    <parent link="passive_5_link_x"/>
    <child link="passive_5_link_y"/>
    <axis xyz="0 1 0"/>
    <limit effort="10" velocity="10" lower="-3.141592653589793" upper="3.141592653589793"/>
  </joint>
  <!-- Joint from arm_4 to passive_5_link_x -->
  <joint name="passive_5_x" type="revolute">
    <origin xyz="0.038 1.38778e-17 -0.00768" rpy="-2.7279 -0.0202587 1.08831"/>
    <parent link="arm_4"/>
    <child link="passive_5_link_x"/>
    <axis xyz="1 0 0"/>
    <limit effort="10" velocity="10" lower="-3.141592653589793" upper="3.141592653589793"/>
  </joint>
  <!-- Joint from main_plate to arm_4 -->
  <joint name="5" type="revolute">
    <origin xyz="-0.041534 0.012144 -0.044785" rpy="1.5708 -6.46911e-15 -2.0944"/>
    <parent link="main_plate"/>
    <child link="arm_4"/>
    <axis xyz="0 0 1"/>
    <limit effort="10" velocity="10" lower="-1.39626" upper="1.39626"/>
  </joint>
  <!-- Link arm_5 -->
  <link name="arm_5">
    <inertial>
      <origin xyz="0 0 0" rpy="0 0 0"/>
      <mass value="1e-09"/>
      <inertia ixx="1e-09" ixy="0" ixz="0" iyy="1e-09" iyz="0" izz="1e-09"/>
    </inertial>
    <!-- Part ball_6 -->
    <visual>
      <origin xyz="0.038 0 -0.00768" rpy="3.14159 2.19395e-15 -1.5708"/>
      <geometry>
        <mesh filename="package://assets/ball.stl"/>
      </geometry>
      <material name="ball_6_material">
        <color rgba="0.901961 0.901961 0.901961 1.0"/>
      </material>
    </visual>
    <collision>
      <origin xyz="0.038 0 -0.00768" rpy="3.14159 2.19395e-15 -1.5708"/>
      <geometry>
        <mesh filename="package://assets/ball.stl"/>
      </geometry>
    </collision>
    <!-- Part arm_6 -->
    <visual>
      <origin xyz="-0.01025 -0.03 -0.0425915" rpy="-1.5708 2.24962e-16 0"/>
      <geometry>
        <mesh filename="package://assets/arm.stl"/>
      </geometry>
      <material name="arm_6_material">
        <color rgba="0.196078 0.196078 0.196078 1.0"/>
      </material>
    </visual>
    <collision>
      <origin xyz="-0.01025 -0.03 -0.0425915" rpy="-1.5708 2.24962e-16 0"/>
      <geometry>
        <mesh filename="package://assets/arm.stl"/>
      </geometry>
    </collision>
  </link>
  <!-- Link passive_6_link_x -->
  <link name="passive_6_link_x">
    <inertial>
      <origin xyz="0 0 0" rpy="0 0 0"/>
      <mass value="1e-09"/>
      <inertia ixx="1e-09" ixy="0" ixz="0" iyy="1e-09" iyz="0" izz="1e-09"/>
    </inertial>
  </link>
  <!-- Link passive_6_link_y -->
  <link name="passive_6_link_y">
    <inertial>
      <origin xyz="0 0 0" rpy="0 0 0"/>
      <mass value="1e-09"/>
      <inertia ixx="1e-09" ixy="0" ixz="0" iyy="1e-09" iyz="0" izz="1e-09"/>
    </inertial>
  </link>
  <!-- Link shape_5 -->
  <link name="shape_5">
    <inertial>
      <origin xyz="0 0 0" rpy="0 0 0"/>
      <mass value="1e-09"/>
      <inertia ixx="1e-09" ixy="0" ixz="0" iyy="1e-09" iyz="0" izz="1e-09"/>
    </inertial>
    <!-- Part shape_11 -->
    <visual>
      <origin xyz="-0.0900003 2.22045e-16 -1.31188e-17" rpy="-1.49802e-17 -5.73288e-17 3.14159"/>
      <geometry>
        <mesh filename="package://assets/shape.stl"/>
      </geometry>
      <material name="shape_11_material">
        <color rgba="0.901961 0.901961 0.901961 1.0"/>
      </material>
    </visual>
    <collision>
      <origin xyz="-0.0900003 2.22045e-16 -1.31188e-17" rpy="-1.49802e-17 -5.73288e-17 3.14159"/>
      <geometry>
        <mesh filename="package://assets/shape.stl"/>
      </geometry>
    </collision>
    <!-- Part rod_6 -->
    <visual>
      <origin xyz="0.00371031 0.0370326 -0.0564076" rpy="0.01484 -1.08842 2.39271e-16"/>
      <geometry>
        <mesh filename="package://assets/rod.stl"/>
      </geometry>
      <material name="rod_6_material">
        <color rgba="0.8 0.8 0.8 1.0"/>
      </material>
    </visual>
    <collision>
      <origin xyz="0.00371031 0.0370326 -0.0564076" rpy="0.01484 -1.08842 2.39271e-16"/>
      <geometry>
        <mesh filename="package://assets/rod.stl"/>
      </geometry>
    </collision>
    <!-- Part shape_12 -->
    <visual>
      <origin xyz="-1.38778e-17 1.38778e-17 2.1684e-19" rpy="-5.18698e-17 -1.9094e-18 4.12252e-17"/>
      <geometry>
        <mesh filename="package://assets/shape.stl"/>
      </geometry>
      <material name="shape_12_material">
        <color rgba="0.901961 0.901961 0.901961 1.0"/>
      </material>
    </visual>
    <collision>
      <origin xyz="-1.38778e-17 1.38778e-17 2.1684e-19" rpy="-5.18698e-17 -1.9094e-18 4.12252e-17"/>
      <geometry>
        <mesh filename="package://assets/shape.stl"/>
      </geometry>
    </collision>
  </link>
  <!-- Link passive_7_link_x -->
  <link name="passive_7_link_x">
    <inertial>
      <origin xyz="0 0 0" rpy="0 0 0"/>
      <mass value="1e-09"/>
      <inertia ixx="1e-09" ixy="0" ixz="0" iyy="1e-09" iyz="0" izz="1e-09"/>
    </inertial>
  </link>
  <!-- Link passive_7_link_y -->
  <link name="passive_7_link_y">
    <inertial>
      <origin xyz="0 0 0" rpy="0 0 0"/>
      <mass value="1e-09"/>
      <inertia ixx="1e-09" ixy="0" ixz="0" iyy="1e-09" iyz="0" izz="1e-09"/>
    </inertial>
  </link>
  <!-- Link plateform -->
  <link name="plateform">
    <inertial>
      <origin xyz="0.0548333 0.00287548 -0.0381711" rpy="0 0 0"/>
      <mass value="0.115777"/>
      <inertia ixx="0.000318707" ixy="7.14935e-06" ixz="-2.4557e-05" iyy="0.000353048" iyz="-1.13518e-05" izz="0.000217873"/>
    </inertial>
    <!-- Part head_shell_front -->
    <visual>
      <origin xyz="0.0574222 0.00200241 -0.0383511" rpy="-2.44262 1.34723 -2.88418"/>
      <geometry>
        <mesh filename="package://assets/head_shell_front.stl"/>
      </geometry>
      <material name="head_shell_front_material">
        <color rgba="1 1 1 1.0"/>
      </material>
    </visual>
    <collision>
      <origin xyz="0.0574222 0.00200241 -0.0383511" rpy="-2.44262 1.34723 -2.88418"/>
      <geometry>
        <mesh filename="package://assets/head_shell_front.stl"/>
      </geometry>
    </collision>
    <!-- Part head_head_back -->
    <visual>
      <origin xyz="0.0574222 0.00200241 -0.0383511" rpy="-2.44262 1.34723 -2.88418"/>
      <geometry>
        <mesh filename="package://assets/head_head_back.stl"/>
      </geometry>
      <material name="head_head_back_material">
        <color rgba="1 1 1 1.0"/>
      </material>
    </visual>
    <collision>
      <origin xyz="0.0574222 0.00200241 -0.0383511" rpy="-2.44262 1.34723 -2.88418"/>
      <geometry>
        <mesh filename="package://assets/head_head_back.stl"/>
      </geometry>
    </collision>
    <!-- Part big_lens -->
    <visual>
      <origin xyz="0.0382577 -0.0398757 -0.0317134" rpy="-2.44262 1.34723 -2.88418"/>
      <geometry>
        <mesh filename="package://assets/big_lens.stl"/>
      </geometry>
      <material name="big_lens_material">
        <color rgba="0.439216 0.47451 0.501961 1.0"/>
      </material>
    </visual>
    <collision>
      <origin xyz="0.0382577 -0.0398757 -0.0317134" rpy="-2.44262 1.34723 -2.88418"/>
      <geometry>
        <mesh filename="package://assets/big_lens.stl"/>
      </geometry>
    </collision>
    <!-- Part ball_7 -->
    <visual>
      <origin xyz="0.00603053 0.0104995 0.00473221" rpy="-0.378336 -0.170541 2.68759"/>
      <geometry>
        <mesh filename="package://assets/ball.stl"/>
      </geometry>
      <material name="ball_7_material">
        <color rgba="0.901961 0.901961 0.901961 1.0"/>
      </material>
    </visual>
    <collision>
      <origin xyz="0.00603053 0.0104995 0.00473221" rpy="-0.378336 -0.170541 2.68759"/>
      <geometry>
        <mesh filename="package://assets/ball.stl"/>
      </geometry>
    </collision>
    <!-- Part small_lens -->
    <visual>
      <origin xyz="0.0381978 -0.0400065 -0.0316926" rpy="-2.44262 1.34723 -2.88418"/>
      <geometry>
        <mesh filename="package://assets/small_lens.stl"/>
      </geometry>
      <material name="small_lens_material">
        <color rgba="0.439216 0.47451 0.501961 1.0"/>
      </material>
    </visual>
    <collision>
      <origin xyz="0.0381978 -0.0400065 -0.0316926" rpy="-2.44262 1.34723 -2.88418"/>
      <geometry>
        <mesh filename="package://assets/small_lens.stl"/>
      </geometry>
    </collision>
    <!-- Part uc_a37_rev_a_step -->
    <visual>
      <origin xyz="0.0349328 -0.0262995 -0.0217693" rpy="-1.42553 -0.170541 2.68759"/>
      <geometry>
        <mesh filename="package://assets/uc_a37_rev_a_step.stl"/>
      </geometry>
      <material name="uc_a37_rev_a_step_material">
        <color rgba="0.25098 0.25098 0.25098 1.0"/>
      </material>
    </visual>
    <collision>
      <origin xyz="0.0349328 -0.0262995 -0.0217693" rpy="-1.42553 -0.170541 2.68759"/>
      <geometry>
        <mesh filename="package://assets/uc_a37_rev_a_step.stl"/>
      </geometry>
    </collision>
    <!-- Part ball_8 -->
    <visual>
      <origin xyz="0.0157039 0.0472846 -0.0384653" rpy="-1.42553 -0.170541 2.68759"/>
      <geometry>
        <mesh filename="package://assets/ball.stl"/>
      </geometry>
      <material name="ball_8_material">
        <color rgba="0.901961 0.901961 0.901961 1.0"/>
      </material>
    </visual>
    <collision>
      <origin xyz="0.0157039 0.0472846 -0.0384653" rpy="-1.42553 -0.170541 2.68759"/>
      <geometry>
        <mesh filename="package://assets/ball.stl"/>
      </geometry>
    </collision>
    <!-- Part ball_9 -->
    <visual>
      <origin xyz="-0.0107081 -0.00281895 -0.0487017" rpy="-2.47273 -0.170541 2.68759"/>
      <geometry>
        <mesh filename="package://assets/ball.stl"/>
      </geometry>
      <material name="ball_9_material">
        <color rgba="0.901961 0.901961 0.901961 1.0"/>
      </material>
    </visual>
    <collision>
      <origin xyz="-0.0107081 -0.00281895 -0.0487017" rpy="-2.47273 -0.170541 2.68759"/>
      <geometry>
        <mesh filename="package://assets/ball.stl"/>
      </geometry>
    </collision>
    <!-- Part head_interface -->
    <visual>
      <origin xyz="0.0569793 0.00221851 -0.0382662" rpy="-2.44262 1.34723 -2.88418"/>
      <geometry>
        <mesh filename="package://assets/head_interface.stl"/>
      </geometry>
      <material name="head_interface_material">
        <color rgba="0.972549 0.529412 0.00392157 1.0"/>
      </material>
    </visual>
    <collision>
      <origin xyz="0.0569793 0.00221851 -0.0382662" rpy="-2.44262 1.34723 -2.88418"/>
      <geometry>
        <mesh filename="package://assets/head_interface.stl"/>
      </geometry>
    </collision>
    <!-- Part ball_10 -->
    <visual>
      <origin xyz="-0.00746482 0.00694678 -0.056646" rpy="-2.47273 -0.170541 2.68759"/>
      <geometry>
        <mesh filename="package://assets/ball.stl"/>
      </geometry>
      <material name="ball_10_material">
        <color rgba="0.901961 0.901961 0.901961 1.0"/>
      </material>
    </visual>
    <collision>
      <origin xyz="-0.00746482 0.00694678 -0.056646" rpy="-2.47273 -0.170541 2.68759"/>
      <geometry>
        <mesh filename="package://assets/ball.stl"/>
      </geometry>
    </collision>
    <!-- Part eye_support -->
    <visual>
      <origin xyz="0.0382704 -0.039848 -0.0317178" rpy="-2.44262 1.34723 -2.88418"/>
      <geometry>
        <mesh filename="package://assets/eye_support.stl"/>
      </geometry>
      <material name="eye_support_material">
        <color rgba="0.262745 0.282353 0.301961 1.0"/>
      </material>
    </visual>
    <collision>
      <origin xyz="0.0382704 -0.039848 -0.0317178" rpy="-2.44262 1.34723 -2.88418"/>
      <geometry>
        <mesh filename="package://assets/eye_support.stl"/>
      </geometry>
    </collision>
    <!-- Part plateform -->
    <visual>
      <origin xyz="-0.0935013 0.0657437 -0.00885671" rpy="1.78688 0.657446 1.25014"/>
      <geometry>
        <mesh filename="package://assets/plateform.stl"/>
      </geometry>
      <material name="plateform_material">
        <color rgba="1 1 1 1.0"/>
      </material>
    </visual>
    <collision>
      <origin xyz="-0.0935013 0.0657437 -0.00885671" rpy="1.78688 0.657446 1.25014"/>
      <geometry>
        <mesh filename="package://assets/plateform.stl"/>
      </geometry>
    </collision>
    <!-- Part ball_11 -->
    <visual>
      <origin xyz="0 -1.38778e-17 -3.03577e-18" rpy="-0.378336 -0.170541 2.68759"/>
      <geometry>
        <mesh filename="package://assets/ball.stl"/>
      </geometry>
      <material name="ball_11_material">
        <color rgba="0.901961 0.901961 0.901961 1.0"/>
      </material>
    </visual>
    <collision>
      <origin xyz="0 -1.38778e-17 -3.03577e-18" rpy="-0.378336 -0.170541 2.68759"/>
      <geometry>
        <mesh filename="package://assets/ball.stl"/>
      </geometry>
    </collision>
    <!-- Part ball_12 -->
    <visual>
      <origin xyz="0.0184911 0.0480184 -0.0257888" rpy="-1.42553 -0.170541 2.68759"/>
      <geometry>
        <mesh filename="package://assets/ball.stl"/>
      </geometry>
      <material name="ball_12_material">
        <color rgba="0.901961 0.901961 0.901961 1.0"/>
      </material>
    </visual>
    <collision>
      <origin xyz="0.0184911 0.0480184 -0.0257888" rpy="-1.42553 -0.170541 2.68759"/>
      <geometry>
        <mesh filename="package://assets/ball.stl"/>
      </geometry>
    </collision>
  </link>
  <!-- Frame closing_1_2 (dummy link + fixed joint) -->
  <link name="closing_1_2">
    <origin xyz="0 0 0" rpy="0 -0 0"/>
    <inertial>
      <origin xyz="0 0 0" rpy="0 0 0"/>
      <mass value="1e-9"/>
      <inertia ixx="0" ixy="0" ixz="0" iyy="0" iyz="0" izz="0"/>
    </inertial>
  </link>
  <joint name="closing_1_2_frame" type="fixed">
    <origin xyz="-0.0107081 -0.00281895 -0.0487017" rpy="2.47273 0.170541 -0.454"/>
    <parent link="plateform"/>
    <child link="closing_1_2"/>
    <axis xyz="0 0 0"/>
  </joint>
  <!-- Frame closing_2_2 (dummy link + fixed joint) -->
  <link name="closing_2_2">
    <origin xyz="0 0 0" rpy="0 -0 0"/>
    <inertial>
      <origin xyz="0 0 0" rpy="0 0 0"/>
      <mass value="1e-9"/>
      <inertia ixx="0" ixy="0" ixz="0" iyy="0" iyz="0" izz="0"/>
    </inertial>
  </link>
  <joint name="closing_2_2_frame" type="fixed">
    <origin xyz="-0.00746482 0.00694678 -0.056646" rpy="2.47273 0.170541 -0.454"/>
    <parent link="plateform"/>
    <child link="closing_2_2"/>
    <axis xyz="0 0 0"/>
  </joint>
  <!-- Frame closing_3_2 (dummy link + fixed joint) -->
  <link name="closing_3_2">
    <origin xyz="0 0 0" rpy="0 -0 0"/>
    <inertial>
      <origin xyz="0 0 0" rpy="0 0 0"/>
      <mass value="1e-9"/>
      <inertia ixx="0" ixy="0" ixz="0" iyy="0" iyz="0" izz="0"/>
    </inertial>
  </link>
  <joint name="closing_3_2_frame" type="fixed">
    <origin xyz="0.0157039 0.0472846 -0.0384653" rpy="0.871822 -1.34723 0.257412"/>
    <parent link="plateform"/>
    <child link="closing_3_2"/>
    <axis xyz="0 0 0"/>
  </joint>
  <!-- Frame closing_4_2 (dummy link + fixed joint) -->
  <link name="closing_4_2">
    <origin xyz="0 0 0" rpy="0 -0 0"/>
    <inertial>
      <origin xyz="0 0 0" rpy="0 0 0"/>
      <mass value="1e-9"/>
      <inertia ixx="0" ixy="0" ixz="0" iyy="0" iyz="0" izz="0"/>
    </inertial>
  </link>
  <joint name="closing_4_2_frame" type="fixed">
    <origin xyz="0.0184911 0.0480184 -0.0257888" rpy="-0.871822 1.34723 -2.88418"/>
    <parent link="plateform"/>
    <child link="closing_4_2"/>
    <axis xyz="0 0 0"/>
  </joint>
  <!-- Frame closing_5_2 (dummy link + fixed joint) -->
  <link name="closing_5_2">
    <origin xyz="0 0 0" rpy="0 -0 0"/>
    <inertial>
      <origin xyz="0 0 0" rpy="0 0 0"/>
      <mass value="1e-9"/>
      <inertia ixx="0" ixy="0" ixz="0" iyy="0" iyz="0" izz="0"/>
    </inertial>
  </link>
  <joint name="closing_5_2_frame" type="fixed">
    <origin xyz="0.00603053 0.0104995 0.00473221" rpy="2.95835 0.372577 -2.09215"/>
    <parent link="plateform"/>
    <child link="closing_5_2"/>
    <axis xyz="0 0 0"/>
  </joint>
  <!-- Frame head (dummy link + fixed joint) -->
  <link name="head">
    <origin xyz="0 0 0" rpy="0 -0 0"/>
    <inertial>
      <origin xyz="0 0 0" rpy="0 0 0"/>
      <mass value="1e-9"/>
      <inertia ixx="0" ixy="0" ixz="0" iyy="0" iyz="0" izz="0"/>
    </inertial>
  </link>
  <joint name="head_frame" type="fixed">
    <origin xyz="0.00367542 0.0183217 -0.0274783" rpy="-1.74312 -0.143141 -1.99997"/>
    <parent link="plateform"/>
    <child link="head"/>
    <axis xyz="0 0 0"/>
  </joint>
  <!-- Link test_antenna_body -->
  <link name="test_antenna_body">
    <inertial>
      <origin xyz="0.00144486 0.0287138 -0.00297745" rpy="0 0 0"/>
      <mass value="0.00463834"/>
      <inertia ixx="1.36882e-05" ixy="-6.79045e-07" ixz="-4.92291e-08" iyy="2.27725e-07" iyz="-9.78329e-07" izz="1.36937e-05"/>
    </inertial>
    <!-- Part test_antenna -->
    <visual>
      <origin xyz="0.0285297 -0.0184653 0.0570171" rpy="-1.67148 -0.521403 2.81648e-17"/>
      <geometry>
        <mesh filename="package://assets/test_antenna.stl"/>
      </geometry>
      <material name="test_antenna_material">
        <color rgba="0.262745 0.282353 0.301961 1.0"/>
      </material>
    </visual>
    <collision>
      <origin xyz="0.0285297 -0.0184653 0.0570171" rpy="-1.67148 -0.521403 2.81648e-17"/>
      <geometry>
        <mesh filename="package://assets/test_antenna.stl"/>
      </geometry>
    </collision>
    <!-- Part test_antenna_body -->
    <visual>
      <origin xyz="0.0285297 -0.0184653 0.0570171" rpy="-1.67148 -0.521403 1.19983e-17"/>
      <geometry>
        <mesh filename="package://assets/test_antenna_body.stl"/>
      </geometry>
      <material name="test_antenna_body_material">
        <color rgba="1 1 1 1.0"/>
      </material>
    </visual>
    <collision>
      <origin xyz="0.0285297 -0.0184653 0.0570171" rpy="-1.67148 -0.521403 1.19983e-17"/>
      <geometry>
        <mesh filename="package://assets/test_antenna_body.stl"/>
      </geometry>
    </collision>
  </link>
  <!-- Joint from plateform to test_antenna_body -->
  <joint name="left_antenna" type="revolute">
    <origin xyz="0.0786202 0.0183429 -0.0976865" rpy="-0.242906 0.87314 -2.31329"/>
    <parent link="plateform"/>
    <child link="test_antenna_body"/>
    <axis xyz="0 0 1"/>
    <limit effort="10" velocity="10" lower="-3.141592653589793" upper="3.141592653589793"/>
  </joint>
  <!-- Link test_antenna -->
  <link name="test_antenna">
    <inertial>
      <origin xyz="0.00144486 0.0287138 -0.00297745" rpy="0 0 0"/>
      <mass value="0.00463834"/>
      <inertia ixx="1.36882e-05" ixy="-6.79045e-07" ixz="-4.92291e-08" iyy="2.27725e-07" iyz="-9.78329e-07" izz="1.36937e-05"/>
    </inertial>
    <!-- Part test_antenna_body_2 -->
    <visual>
      <origin xyz="0.0285297 -0.0184653 0.0570171" rpy="-1.67148 -0.521403 4.73403e-18"/>
      <geometry>
        <mesh filename="package://assets/test_antenna_body.stl"/>
      </geometry>
      <material name="test_antenna_body_2_material">
        <color rgba="1 1 1 1.0"/>
      </material>
    </visual>
    <collision>
      <origin xyz="0.0285297 -0.0184653 0.0570171" rpy="-1.67148 -0.521403 4.73403e-18"/>
      <geometry>
        <mesh filename="package://assets/test_antenna_body.stl"/>
      </geometry>
    </collision>
    <!-- Part test_antenna_2 -->
    <visual>
      <origin xyz="0.0285297 -0.0184653 0.0570171" rpy="-1.67148 -0.521403 2.29986e-16"/>
      <geometry>
        <mesh filename="package://assets/test_antenna.stl"/>
      </geometry>
      <material name="test_antenna_2_material">
        <color rgba="0.262745 0.282353 0.301961 1.0"/>
      </material>
    </visual>
    <collision>
      <origin xyz="0.0285297 -0.0184653 0.0570171" rpy="-1.67148 -0.521403 2.29986e-16"/>
      <geometry>
        <mesh filename="package://assets/test_antenna.stl"/>
      </geometry>
    </collision>
  </link>
  <!-- Joint from plateform to test_antenna -->
  <joint name="right_antenna" type="revolute">
    <origin xyz="0.101086 0.024257 0.00448913" rpy="-3.0252 1.213 1.08209"/>
    <parent link="plateform"/>
    <child link="test_antenna"/>
    <axis xyz="0 0 1"/>
    <limit effort="10" velocity="10" lower="-3.141592653589793" upper="3.141592653589793"/>
  </joint>
  <!-- Joint from passive_7_link_y to plateform -->
  <joint name="passive_7_z" type="revolute">
    <origin xyz="0 -1.38778e-17 -3.03577e-18" rpy="4.31179e-18 4.6347e-17 -7.78613e-17"/>
    <parent link="passive_7_link_y"/>
    <child link="plateform"/>
    <axis xyz="0 0 1"/>
    <limit effort="10" velocity="10" lower="-3.141592653589793" upper="3.141592653589793"/>
  </joint>
  <!-- Joint from passive_7_link_x to passive_7_link_y -->
  <joint name="passive_7_y" type="revolute">
    <origin xyz="0 -1.38778e-17 -3.03577e-18" rpy="4.31179e-18 4.6347e-17 -7.78613e-17"/>
    <parent link="passive_7_link_x"/>
    <child link="passive_7_link_y"/>
    <axis xyz="0 1 0"/>
    <limit effort="10" velocity="10" lower="-3.141592653589793" upper="3.141592653589793"/>
  </joint>
  <!-- Joint from shape_5 to passive_7_link_x -->
  <joint name="passive_7_x" type="revolute">
    <origin xyz="-0.0900003 2.22045e-16 -1.31188e-17" rpy="3.14159 -5.73288e-17 3.14159"/>
    <parent link="shape_5"/>
    <child link="passive_7_link_x"/>
    <axis xyz="1 0 0"/>
    <limit effort="10" velocity="10" lower="-3.141592653589793" upper="3.141592653589793"/>
  </joint>
  <!-- Joint from passive_6_link_y to shape_5 -->
  <joint name="passive_6_z" type="revolute">
    <origin xyz="-1.38778e-17 1.38778e-17 1.95156e-18" rpy="-5.18698e-17 -1.9094e-18 4.12252e-17"/>
    <parent link="passive_6_link_y"/>
    <child link="shape_5"/>
    <axis xyz="0 0 1"/>
    <limit effort="10" velocity="10" lower="-3.141592653589793" upper="3.141592653589793"/>
  </joint>
  <!-- Joint from passive_6_link_x to passive_6_link_y -->
  <joint name="passive_6_y" type="revolute">
    <origin xyz="-1.38778e-17 1.38778e-17 1.95156e-18" rpy="-5.18698e-17 -1.9094e-18 4.12252e-17"/>
    <parent link="passive_6_link_x"/>
    <child link="passive_6_link_y"/>
    <axis xyz="0 1 0"/>
    <limit effort="10" velocity="10" lower="-3.141592653589793" upper="3.141592653589793"/>
  </joint>
  <!-- Joint from arm_5 to passive_6_link_x -->
  <joint name="passive_6_x" type="revolute">
    <origin xyz="0.038 2.77556e-17 -0.00768" rpy="-2.72876 -0.0202587 -1.08831"/>
    <parent link="arm_5"/>
    <child link="passive_6_link_x"/>
    <axis xyz="1 0 0"/>
    <limit effort="10" velocity="10" lower="-3.141592653589793" upper="3.141592653589793"/>
  </joint>
  <!-- Joint from main_plate to arm_5 -->
  <joint name="6" type="revolute">
    <origin xyz="-0.031284 0.0298975 -0.044785" rpy="-1.5708 -1.65104e-14 1.0472"/>
    <parent link="main_plate"/>
    <child link="arm_5"/>
    <axis xyz="0 0 1"/>
    <limit effort="10" velocity="10" lower="-1.39626" upper="1.39626"/>
  </joint>
  <!-- Joint from turning_bowl to main_plate -->
  <joint name="all_yaw" type="revolute">
    <origin xyz="-0.00198261 3.46945e-18 0.0316" rpy="-3.14159 -3.15544e-30 1.5708"/>
    <parent link="turning_bowl"/>
    <child link="main_plate"/>
    <axis xyz="0 0 1"/>
    <limit effort="10" velocity="10" lower="-2.96706" upper="2.96706"/>
  </joint>
</robot>
