<?xml version="1.0" ?>
<!-- Generated using onshape-to-robot -->
<!-- Onshape https://cad.onshape.com/documents/e305b26a84339af20c593973/w/ec7765eccdaa9a5960507125/e/251023ea04190ab16854eb80 -->
<mujoco model="reachy_mini">
  <compiler angle="radian" meshdir="assets" autolimits="true"/>
  <default>
    <default class="reachy_mini">
      <joint frictionloss="0.1" armature="0.005"/>
      <position kp="50" dampratio="1"/>
      <default class="visual">
        <geom type="mesh" contype="0" conaffinity="0" group="2"/>
      </default>
      <default class="collision">
        <geom group="3"/>
      </default>
    </default>
  </default>
  <!-- Additional joints_properties.xml -->
  <default>
    <default class="perfect_actuator">
      <geom contype="0" conaffinity="0"/>
      <joint damping="0.095" frictionloss="0.001" armature="0.001"/>
      <position kp="10.0" kv="0.0" forcerange="-10.0 10.0"/>
      <default class="chosen_actuator"/>
    </default>
    <default class="xc330m288t">
      <!-- probably wrong, would need to re-identify -->
      <geom contype="0" conaffinity="0"/>
      <joint damping="0.095" frictionloss="0.058" armature="0.0018"/>
      <position kp="2.54" kv="0.0" forcerange="-0.8 0.8"/>
    </default>
    <default class="sts3215_345">
      <!-- Standard sts3215 with 1/345 gear ratio -->
      <!-- Confident that this is realistic (mini duck walks with these values) -->
      <geom contype="0" conaffinity="0"/>
      <joint damping="0.56" frictionloss="0.068" armature="0.027"/>
      <position kp="17.11" kv="0.0" forcerange="-3.23 3.23"/>
    </default>
    <default class="sts3215_147">
      <!-- sts3215 with 1/147 gear ratio -->
      <!-- (Estimation based on the gear ratio difference) -->
      <geom contype="0" conaffinity="0"/>
      <joint damping="0.1" frictionloss="0.028" armature="0.011"/>
      <position kp="17.11" kv="0.0" forcerange="-1.35 1.35"/>
    </default>
  </default>
  <!-- Additional additional.xml -->
  <contact>
    <!-- <exclude name="exclude0" body1="torso" body2="sts32155"/> -->
  </contact>
  <default>
    <equality solref="0.002 1" solimp="0.99 0.999 0.0005 0.5 2"/>
  </default>
  <worldbody>
    <!-- Link pp01071_turning_bowl -->
    <body name="pp01071_turning_bowl" pos="0 0 0" quat="1 0 0 0" childclass="reachy_mini">
      <inertial pos="0.000667521 1.7878e-09 0.0118411" mass="0.0947234" fullinertia="0.000111359 0.000106563 0.000196298 1.02485e-11 8.96229e-07 4.95917e-13"/>
      <!-- Part pp01071_turning_bowl -->
      <geom type="mesh" class="visual" pos="-1.38778e-17 0 0.2345" quat="0.707107 0 -6.16298e-32 0.707107" mesh="pp01071_turning_bowl" material="pp01071_turning_bowl_material"/>
      <!-- Part pp01072_turning_end -->
      <geom type="mesh" class="visual" pos="3.46945e-17 -4.51028e-17 0.2345" quat="0.707107 7.85046e-17 -2.22045e-16 0.707107" mesh="pp01072_turning_end" material="pp01072_turning_end_material"/>
      <!-- Link dc15_a01_case_b_dummy -->
      <body name="dc15_a01_case_b_dummy" pos="4.85723e-17 -5.60663e-19 0.0339" quat="7.85046e-17 -0.707107 -0.707107 -7.85046e-17">
        <!-- Joint from pp01071_turning_bowl to dc15_a01_case_b_dummy -->
        <joint axis="0 0 1" name="all_yaw" type="hinge" class="chosen_actuator"/>
        <inertial pos="-1.60377e-06 0.00140187 -0.0329593" mass="0.443795" fullinertia="0.00159333 0.0015483 0.00187065 2.80397e-07 1.98452e-07 4.26838e-05"/>
        <!-- Part pp01065_stewart_side_plate -->
        <geom type="mesh" class="visual" pos="-3.43031e-17 -4.85723e-17 -0.00705" quat="1.07797e-16 0.866025 0.5 3.39116e-18" mesh="pp01065_stewart_side_plate" material="pp01065_stewart_side_plate_material"/>
        <!-- Part pp01067_bottom_body -->
        <geom type="mesh" class="visual" pos="1.38767e-16 1.83881e-16 -0.20055" quat="9.16593e-17 1 -3.29597e-17 5.68353e-17" mesh="pp01067_bottom_body" material="pp01067_bottom_body_material"/>
        <!-- Part dc15_a01_case_m_dummy -->
        <geom type="mesh" class="visual" pos="-1.4706e-16 -8.67362e-17 -0.00705" quat="5.09617e-17 0.866025 -0.5 9.50505e-17" mesh="dc15_a01_case_m_dummy" material="dc15_a01_case_m_dummy_material"/>
        <!-- Part dc15_a01_case_f_dummy -->
        <geom type="mesh" class="visual" pos="0.0205 6.93889e-18 -0.00705" quat="3.33067e-16 3.64292e-17 1 -4.44089e-16" mesh="dc15_a01_case_f_dummy" material="dc15_a01_case_f_dummy_material"/>
        <!-- Part dc15_a01_horn_dummy -->
        <geom type="mesh" class="visual" pos="0.0205 1.73472e-17 -0.00705" quat="3.33067e-16 3.64292e-17 1 -4.44089e-16" mesh="dc15_a01_horn_dummy" material="dc15_a01_horn_dummy_material"/>
        <!-- Part dc15_a01_horn_dummy_2 -->
        <geom type="mesh" class="visual" pos="-0.01025 0.0177535 -0.00705" quat="5.09617e-17 0.866025 -0.5 9.50505e-17" mesh="dc15_a01_horn_dummy" material="dc15_a01_horn_dummy_material"/>
        <!-- Part wj_wk00_0122topcabinetcase_95__configuration_default -->
        <geom type="mesh" class="visual" pos="6.12843e-18 -0.0255 -0.00945" quat="0.5 0.5 -0.5 -0.5" mesh="wj_wk00_0122topcabinetcase_95__configuration_default" material="wj_wk00_0122topcabinetcase_95__configuration_default_material"/>
        <!-- Part dc15_a01_case_m_dummy_2 -->
        <geom type="mesh" class="visual" pos="-2.56295e-17 3.1225e-17 -0.00705" quat="1.11022e-16 2.60209e-17 1 -2.22045e-16" mesh="dc15_a01_case_m_dummy" material="dc15_a01_case_m_dummy_material"/>
        <!-- Part dc15_a01_case_b_dummy -->
        <geom type="mesh" class="visual" pos="-0.01025 -0.0177535 -0.00705" quat="1.07797e-16 0.866025 0.5 3.39116e-18" mesh="dc15_a01_case_b_dummy" material="dc15_a01_case_b_dummy_material"/>
        <!-- Part dc15_a01_case_b_dummy_2 -->
        <geom type="mesh" class="visual" pos="0.0205 3.46945e-18 -0.00705" quat="3.33067e-16 3.64292e-17 1 -4.44089e-16" mesh="dc15_a01_case_b_dummy" material="dc15_a01_case_b_dummy_material"/>
        <!-- Part pp01068_top_body -->
        <geom type="mesh" class="visual" pos="-8.55341e-16 -3.12493e-14 -0.20005" quat="9.19752e-14 1 -3.64292e-17 -2.66929e-15" mesh="pp01068_top_body" material="pp01068_top_body_material"/>
        <!-- Part dc15_a01_case_f_dummy_2 -->
        <geom type="mesh" class="visual" pos="-3.43031e-17 -3.46945e-18 -0.00705" quat="3.33067e-16 3.64292e-17 1 -4.44089e-16" mesh="dc15_a01_case_f_dummy" material="dc15_a01_case_f_dummy_material"/>
        <!-- Part drive_palonier__configuration_default -->
        <geom type="mesh" class="visual" pos="4.39371e-18 -0.0255 -0.00945" quat="0.5 0.5 -0.5 -0.5" mesh="drive_palonier__configuration_default" material="drive_palonier__configuration_default_material"/>
        <!-- Part dc15_a01_case_f_dummy_3 -->
        <geom type="mesh" class="visual" pos="-0.01025 0.0177535 -0.00705" quat="5.09617e-17 0.866025 -0.5 9.50505e-17" mesh="dc15_a01_case_f_dummy" material="dc15_a01_case_f_dummy_material"/>
        <!-- Part dc15_a01_case_m_dummy_3 -->
        <geom type="mesh" class="visual" pos="-3.43031e-17 -6.245e-17 -0.00705" quat="1.07797e-16 0.866025 0.5 3.39116e-18" mesh="dc15_a01_case_m_dummy" material="dc15_a01_case_m_dummy_material"/>
        <!-- Part dc15_a01_case_b_dummy_3 -->
        <geom type="mesh" class="visual" pos="-9.1549e-17 -6.245e-17 -0.00705" quat="5.09617e-17 0.866025 -0.5 9.50505e-17" mesh="dc15_a01_case_b_dummy" material="dc15_a01_case_b_dummy_material"/>
        <!-- Part wj_wk00_0123middlecase_56__configuration_default -->
        <geom type="mesh" class="visual" pos="-1.75347e-05 -0.0254895 -0.00945" quat="0.5 0.5 -0.5 -0.5" mesh="wj_wk00_0123middlecase_56__configuration_default" material="wj_wk00_0123middlecase_56__configuration_default_material"/>
        <!-- Part dc15_a01_case_b_dummy_4 -->
        <geom type="mesh" class="visual" pos="-3.60378e-17 -1.04083e-17 -0.00705" quat="3.33067e-16 3.64292e-17 1 -4.44089e-16" mesh="dc15_a01_case_b_dummy" material="dc15_a01_case_b_dummy_material"/>
        <!-- Part dc15_a01_case_f_dummy_4 -->
        <geom type="mesh" class="visual" pos="-2.26857e-16 -1.00614e-16 -0.00705" quat="5.09617e-17 0.866025 -0.5 9.50505e-17" mesh="dc15_a01_case_f_dummy" material="dc15_a01_case_f_dummy_material"/>
        <!-- Part dc15_a01_case_b_dummy_5 -->
        <geom type="mesh" class="visual" pos="-0.01025 0.0177535 -0.00705" quat="5.09617e-17 0.866025 -0.5 9.50505e-17" mesh="dc15_a01_case_b_dummy" material="dc15_a01_case_b_dummy_material"/>
        <!-- Part dc15_a01_horn_dummy_3 -->
        <geom type="mesh" class="visual" pos="-1.15835e-16 -6.93889e-17 -0.00705" quat="5.09617e-17 0.866025 -0.5 9.50505e-17" mesh="dc15_a01_horn_dummy" material="dc15_a01_horn_dummy_material"/>
        <!-- Part dc15_a01_horn_dummy_4 -->
        <geom type="mesh" class="visual" pos="-0.01025 -0.0177535 -0.00705" quat="1.07797e-16 0.866025 0.5 3.39116e-18" mesh="dc15_a01_horn_dummy" material="dc15_a01_horn_dummy_material"/>
        <!-- Part dc15_a01_case_m_dummy_4 -->
        <geom type="mesh" class="visual" pos="-0.01025 0.0177535 -0.00705" quat="5.09617e-17 0.866025 -0.5 9.50505e-17" mesh="dc15_a01_case_m_dummy" material="dc15_a01_case_m_dummy_material"/>
        <!-- Part pp01065_stewart_side_plate_2 -->
        <geom type="mesh" class="visual" pos="-1.34864e-17 6.59195e-17 -0.00705" quat="0 3.64292e-17 1 0" mesh="pp01065_stewart_side_plate" material="pp01065_stewart_side_plate_material"/>
        <!-- Part dc15_a01_case_b_dummy_6 -->
        <geom type="mesh" class="visual" pos="-6.37934e-17 -3.46945e-17 -0.00705" quat="1.07797e-16 0.866025 0.5 3.39116e-18" mesh="dc15_a01_case_b_dummy" material="dc15_a01_case_b_dummy_material"/>
        <!-- Part pp01066_stewart_mid_plate -->
        <geom type="mesh" class="visual" pos="-8.28754e-17 -1.04083e-17 -0.00705" quat="1.07797e-16 0.866025 0.5 3.39116e-18" mesh="pp01066_stewart_mid_plate" material="pp01066_stewart_mid_plate_material"/>
        <!-- Part dc15_a01_case_f_dummy_5 -->
        <geom type="mesh" class="visual" pos="-3.77726e-17 -4.85723e-17 -0.00705" quat="1.07797e-16 0.866025 0.5 3.39116e-18" mesh="dc15_a01_case_f_dummy" material="dc15_a01_case_f_dummy_material"/>
        <!-- Part dc15_a01_horn_dummy_5 -->
        <geom type="mesh" class="visual" pos="-5.51198e-17 -4.85723e-17 -0.00705" quat="1.07797e-16 0.866025 0.5 3.39116e-18" mesh="dc15_a01_horn_dummy" material="dc15_a01_horn_dummy_material"/>
        <!-- Part dc15_a01_case_m_dummy_5 -->
        <geom type="mesh" class="visual" pos="0.0205 3.81639e-17 -0.00705" quat="1.11022e-16 2.60209e-17 1 -2.22045e-16" mesh="dc15_a01_case_m_dummy" material="dc15_a01_case_m_dummy_material"/>
        <!-- Part wj_wk00_0124bottomcase_45__configuration_default -->
        <geom type="mesh" class="visual" pos="-1.04636e-05 -0.0254966 -0.00945" quat="0.5 0.5 -0.5 -0.5" mesh="wj_wk00_0124bottomcase_45__configuration_default" material="wj_wk00_0124bottomcase_45__configuration_default_material"/>
        <!-- Part dc15_a01_horn_dummy_6 -->
        <geom type="mesh" class="visual" pos="-3.25684e-17 1.04083e-17 -0.00705" quat="3.33067e-16 3.64292e-17 1 -4.44089e-16" mesh="dc15_a01_horn_dummy" material="dc15_a01_horn_dummy_material"/>
        <!-- Part dc15_a01_case_m_dummy_6 -->
        <geom type="mesh" class="visual" pos="-0.01025 -0.0177535 -0.00705" quat="1.07797e-16 0.866025 0.5 3.39116e-18" mesh="dc15_a01_case_m_dummy" material="dc15_a01_case_m_dummy_material"/>
        <!-- Part pp01064_stewart_main_plate -->
        <geom type="mesh" class="visual" pos="-2.73642e-17 -1.38778e-17 -0.00705" quat="1.11022e-16 -8.67362e-18 -1 -1.11022e-16" mesh="pp01064_stewart_main_plate" material="pp01064_stewart_main_plate_material"/>
        <!-- Part dc15_a01_case_f_dummy_6 -->
        <geom type="mesh" class="visual" pos="-0.01025 -0.0177535 -0.00705" quat="1.07797e-16 0.866025 0.5 3.39116e-18" mesh="dc15_a01_case_f_dummy" material="dc15_a01_case_f_dummy_material"/>
        <!-- Part pp01065_stewart_side_plate_3 -->
        <geom type="mesh" class="visual" pos="-6.20587e-17 -1.04083e-17 -0.00705" quat="5.09617e-17 0.866025 -0.5 9.50505e-17" mesh="pp01065_stewart_side_plate" material="pp01065_stewart_side_plate_material"/>
        <!-- Link pp01062_stewart_arm -->
        <body name="pp01062_stewart_arm" pos="0.0317603 0.0301725 -0.03705" quat="0.353553 -0.353553 -0.612372 0.612372">
          <!-- Joint from dc15_a01_case_b_dummy to pp01062_stewart_arm -->
          <joint axis="0 0 1" name="1" type="hinge" range="-1.3962634015954645 1.3962634015954627" class="chosen_actuator"/>
          <inertial pos="0.0181787 2.77556e-17 0.00350559" mass="0.00272417" fullinertia="4.89963e-08 6.75761e-07 6.91798e-07 -2.63422e-25 -7.04811e-08 2.66043e-25"/>
          <!-- Part ball -->
          <geom type="mesh" class="visual" pos="0.038 2.77556e-17 0.00768" quat="0 1 0 0" mesh="ball" material="ball_material"/>
          <!-- Part pp01062_stewart_arm -->
          <geom type="mesh" class="visual" pos="-0.01025 0.03 0.0425915" quat="0.707107 0.707107 -1.11022e-16 8.49837e-17" mesh="pp01062_stewart_arm" material="pp01062_stewart_arm_material"/>
          <!-- Link shape -->
          <body name="shape" pos="0.038 2.77556e-17 0.00768" quat="0.0274567 -0.855096 0.517739 -0.00153082">
            <!-- Joint from pp01062_stewart_arm to shape -->
            <joint axis="0 0 1" name="passive_1" type="ball" class="chosen_actuator"/>
            <inertial pos="-0.0450002 -2.17877e-17 -4.85069e-17" mass="0.00355525" fullinertia="1.7732e-08 3.06049e-06 3.0658e-06 3.75919e-22 -8.93073e-21 -1.00288e-21"/>
            <!-- Part shape -->
            <geom type="mesh" class="visual" pos="6.93889e-18 -1.38778e-17 0" quat="1 1.53003e-17 -1.11022e-16 -1.249e-16" mesh="shape" material="shape_material"/>
            <!-- Part pp00xxx_stewart_rod -->
            <geom type="mesh" class="visual" pos="0.00371031 0.0370326 -0.0564076" quat="0.855513 0.00634803 -0.517727 0.00384161" mesh="pp00xxx_stewart_rod" material="pp00xxx_stewart_rod_material"/>
            <!-- Part shape_2 -->
            <geom type="mesh" class="visual" pos="-0.0900003 -2.77556e-17 -8.32667e-17" quat="1.66533e-16 1.57422e-17 -1 1.11022e-16" mesh="shape" material="shape_material"/>
            <!-- Frame closing_1_1 -->
            <site group="3" name="closing_1_1" pos="-0.0900003 -2.77556e-17 -8.32667e-17" quat="1.66533e-16 1.57422e-17 -1 1.11022e-16"/>
          </body>
        </body>
        <!-- Link pp01062_stewart_arm_2 -->
        <body name="pp01062_stewart_arm_2" pos="0.0420103 0.012419 -0.03705" quat="0.612372 0.612372 -0.353553 -0.353553">
          <!-- Joint from dc15_a01_case_b_dummy to pp01062_stewart_arm_2 -->
          <joint axis="0 0 1" name="2" type="hinge" range="-1.3962634015954662 1.396263401595461" class="chosen_actuator"/>
          <inertial pos="0.0181787 2.34834e-18 0.00350559" mass="0.00272417" fullinertia="4.89963e-08 6.75761e-07 6.91798e-07 2.48336e-22 -7.04811e-08 5.24015e-23"/>
          <!-- Part ball_2 -->
          <geom type="mesh" class="visual" pos="0.038 -1.38778e-17 0.00768" quat="1.66533e-16 -2.4037e-17 -1 -1.11022e-16" mesh="ball" material="ball_material"/>
          <!-- Part pp01062_stewart_arm_2 -->
          <geom type="mesh" class="visual" pos="-0.01025 0.03 0.0425915" quat="0.707107 0.707107 -1.11022e-16 8.24487e-17" mesh="pp01062_stewart_arm" material="pp01062_stewart_arm_material"/>
          <!-- Link shape_2 -->
          <body name="shape_2" pos="0.038 -8.32667e-17 0.00768" quat="0.0131699 -0.855436 -0.517228 0.0230506">
            <!-- Joint from pp01062_stewart_arm_2 to shape_2 -->
            <joint axis="0 0 1" name="passive_2" type="ball" class="chosen_actuator"/>
            <inertial pos="-0.0450002 -1.00413e-17 -8.56034e-18" mass="0.00355525" fullinertia="1.7732e-08 3.06049e-06 3.0658e-06 9.05427e-21 -9.31125e-21 -1.13245e-20"/>
            <!-- Part shape_3 -->
            <geom type="mesh" class="visual" pos="-0.0900003 -2.77556e-17 2.08167e-17" quat="2.22045e-16 2.94872e-15 1 3.85803e-15" mesh="shape" material="shape_material"/>
            <!-- Part shape_4 -->
            <geom type="mesh" class="visual" pos="6.93889e-18 0 6.93889e-18" quat="1 -0 -0 -4.85723e-17" mesh="shape" material="shape_material"/>
            <!-- Part pp00xxx_stewart_rod_2 -->
            <geom type="mesh" class="visual" pos="0.00371031 0.0370326 -0.0564076" quat="0.855513 0.00634803 -0.517727 0.00384161" mesh="pp00xxx_stewart_rod" material="pp00xxx_stewart_rod_material"/>
            <!-- Frame closing_2_2 -->
            <site group="3" name="closing_2_2" pos="-0.0900003 -2.77556e-17 2.08167e-17" quat="2.78561e-15 -0.707107 0.707107 2.55257e-15"/>
          </body>
        </body>
        <!-- Link pp01062_stewart_arm_3 -->
        <body name="pp01062_stewart_arm_3" pos="0.01025 -0.0425915 -0.03705" quat="0.707107 -0.707107 -1.11022e-16 1.84877e-17">
          <!-- Joint from dc15_a01_case_b_dummy to pp01062_stewart_arm_3 -->
          <joint axis="0 0 1" name="3" type="hinge" range="-1.3962634015954645 1.3962634015954627" class="chosen_actuator"/>
          <inertial pos="0.0181787 -1.87132e-19 0.00350559" mass="0.00272417" fullinertia="4.89963e-08 6.75761e-07 6.91798e-07 9.85709e-24 -7.04811e-08 -1.47314e-24"/>
          <!-- Part pp01062_stewart_arm_3 -->
          <geom type="mesh" class="visual" pos="-0.01025 0.03 0.0425915" quat="0.707107 0.707107 -1.11022e-16 1.0222e-16" mesh="pp01062_stewart_arm" material="pp01062_stewart_arm_material"/>
          <!-- Part ball_3 -->
          <geom type="mesh" class="visual" pos="0.038 0 0.00768" quat="1.45894e-16 -0.707107 0.707107 5.21114e-18" mesh="ball" material="ball_material"/>
          <!-- Link shape_3 -->
          <body name="shape_3" pos="0.038 4.16334e-17 0.00768" quat="0.85509 -0.027647 0.0318018 -0.516764">
            <!-- Joint from pp01062_stewart_arm_3 to shape_3 -->
            <joint axis="0 0 1" name="passive_3" type="ball" class="chosen_actuator"/>
            <inertial pos="-0.0450002 -4.79199e-18 4.11785e-17" mass="0.00355525" fullinertia="1.7732e-08 3.06049e-06 3.0658e-06 9.80819e-22 -7.34923e-21 1.45141e-21"/>
            <!-- Part shape_5 -->
            <geom type="mesh" class="visual" pos="-0.0900003 0 1.31839e-16" quat="4.16334e-16 4.4964e-17 1 -2.22045e-16" mesh="shape" material="shape_material"/>
            <!-- Part shape_6 -->
            <geom type="mesh" class="visual" pos="1.38778e-17 0 0" quat="1 -0 -0 2.56739e-16" mesh="shape" material="shape_material"/>
            <!-- Part pp00xxx_stewart_rod_3 -->
            <geom type="mesh" class="visual" pos="0.00371031 0.0370326 -0.0564076" quat="0.855513 0.00634803 -0.517727 0.00384161" mesh="pp00xxx_stewart_rod" material="pp00xxx_stewart_rod_material"/>
            <!-- Frame closing_3_2 -->
            <site group="3" name="closing_3_2" pos="-0.0900003 0 1.31839e-16" quat="0 4.06771e-16 -3.33067e-16 -1"/>
          </body>
        </body>
        <!-- Link pp01062_stewart_arm_4 -->
        <body name="pp01062_stewart_arm_4" pos="-0.01025 -0.0425915 -0.03705" quat="4.44089e-16 -1.5721e-15 -0.707107 -0.707107">
          <!-- Joint from dc15_a01_case_b_dummy to pp01062_stewart_arm_4 -->
          <joint axis="0 0 1" name="4" type="hinge" range="-1.3962634015954831 1.396263401595444" class="chosen_actuator"/>
          <inertial pos="0.0181787 -5.24899e-19 0.00350559" mass="0.00272417" fullinertia="4.89963e-08 6.75761e-07 6.91798e-07 4.36416e-22 -7.04811e-08 3.66848e-23"/>
          <!-- Part ball_4 -->
          <geom type="mesh" class="visual" pos="0.038 -2.77556e-17 0.00768" quat="4.51946e-15 -0.707107 -0.707107 -1.08859e-15" mesh="ball" material="ball_material"/>
          <!-- Part pp01062_stewart_arm_4 -->
          <geom type="mesh" class="visual" pos="-0.01025 0.03 0.0425915" quat="0.707107 0.707107 -1.11022e-16 1.0222e-16" mesh="pp01062_stewart_arm" material="pp01062_stewart_arm_material"/>
          <!-- Link shape_4 -->
          <body name="shape_4" pos="0.038 -2.77556e-17 0.00768" quat="0.854409 0.0439152 0.0416306 0.516065">
            <!-- Joint from pp01062_stewart_arm_4 to shape_4 -->
            <joint axis="0 0 1" name="passive_4" type="ball" class="chosen_actuator"/>
            <inertial pos="-0.0450002 1.04447e-16 -1.1361e-17" mass="0.00355525" fullinertia="1.7732e-08 3.06049e-06 3.0658e-06 6.31755e-21 -5.94417e-21 1.35905e-20"/>
            <!-- Part shape_7 -->
            <geom type="mesh" class="visual" pos="-0.0900003 2.08167e-16 3.46945e-18" quat="3.33067e-16 0 -1 1.66533e-16" mesh="shape" material="shape_material"/>
            <!-- Part pp00xxx_stewart_rod_4 -->
            <geom type="mesh" class="visual" pos="0.00371031 0.0370326 -0.0564076" quat="0.855513 0.00634803 -0.517727 0.00384161" mesh="pp00xxx_stewart_rod" material="pp00xxx_stewart_rod_material"/>
            <!-- Part shape_8 -->
            <geom type="mesh" class="visual" pos="6.93889e-18 0 3.46945e-18" quat="1 0 3.33067e-16 1.31839e-16" mesh="shape" material="shape_material"/>
            <!-- Frame closing_4_1 -->
            <site group="3" name="closing_4_1" pos="-0.0900003 2.08167e-16 3.46945e-18" quat="3.33067e-16 0 -1 1.66533e-16"/>
          </body>
        </body>
        <!-- Link pp01062_stewart_arm_5 -->
        <body name="pp01062_stewart_arm_5" pos="-0.0420103 0.012419 -0.03705" quat="0.353553 -0.353553 0.612372 -0.612372">
          <!-- Joint from dc15_a01_case_b_dummy to pp01062_stewart_arm_5 -->
          <joint axis="0 0 1" name="5" type="hinge" range="-1.3962634015954662 1.396263401595461" class="chosen_actuator"/>
          <inertial pos="0.0181787 3.11301e-35 0.00350559" mass="0.00272417" fullinertia="4.89963e-08 6.75761e-07 6.91798e-07 -4.49492e-25 -7.04811e-08 -1.26741e-25"/>
          <!-- Part pp01062_stewart_arm_5 -->
          <geom type="mesh" class="visual" pos="-0.01025 0.03 0.0425915" quat="0.707107 0.707107 -1.11022e-16 9.55014e-17" mesh="pp01062_stewart_arm" material="pp01062_stewart_arm_material"/>
          <!-- Part ball_5 -->
          <geom type="mesh" class="visual" pos="0.038 0 0.00768" quat="1.38778e-17 5.55459e-17 1 3.33067e-16" mesh="ball" material="ball_material"/>
          <!-- Link pp00xxx_stewart_rod -->
          <body name="pp00xxx_stewart_rod" pos="0.038 1.38778e-17 0.00768" quat="0.0908372 -0.850701 0.516198 -0.0399478">
            <!-- Joint from pp01062_stewart_arm_5 to pp00xxx_stewart_rod -->
            <joint axis="0 0 1" name="passive_5" type="ball" class="chosen_actuator"/>
            <inertial pos="-0.0450002 7.44667e-17 -1.14016e-17" mass="0.00355525" fullinertia="1.7732e-08 3.06049e-06 3.0658e-06 4.55471e-21 -4.43821e-21 1.23083e-21"/>
            <!-- Part shape_9 -->
            <geom type="mesh" class="visual" pos="0 0 0" quat="1 0 -2.22045e-16 0" mesh="shape" material="shape_material"/>
            <!-- Part pp00xxx_stewart_rod_5 -->
            <geom type="mesh" class="visual" pos="0.00371031 0.0370326 -0.0564076" quat="0.855513 0.00634803 -0.517727 0.00384161" mesh="pp00xxx_stewart_rod" material="pp00xxx_stewart_rod_material"/>
            <!-- Part shape_10 -->
            <geom type="mesh" class="visual" pos="-0.0900003 1.38778e-16 6.93889e-18" quat="9.99201e-16 -4.04899e-16 1 1.9984e-15" mesh="shape" material="shape_material"/>
            <!-- Frame closing_5_1 -->
            <site group="3" name="closing_5_1" pos="-0.0900003 1.38778e-16 6.93889e-18" quat="9.99201e-16 -4.04899e-16 1 1.9984e-15"/>
          </body>
        </body>
        <!-- Link pp01062_stewart_arm_6 -->
        <body name="pp01062_stewart_arm_6" pos="-0.0317603 0.0301725 -0.03705" quat="0.612372 0.612372 0.353553 0.353553">
          <!-- Joint from dc15_a01_case_b_dummy to pp01062_stewart_arm_6 -->
          <joint axis="0 0 1" name="6" type="hinge" range="-1.3962634015954636 1.3962634015954636" class="chosen_actuator"/>
          <inertial pos="0.0181787 -1.69382e-17 0.00350559" mass="0.00272417" fullinertia="4.89963e-08 6.75761e-07 6.91798e-07 1.6528e-22 -7.04811e-08 3.48685e-23"/>
          <!-- Part pp01062_stewart_arm_6 -->
          <geom type="mesh" class="visual" pos="-0.01025 0.03 0.0425915" quat="0.707107 0.707107 -1.11022e-16 1.00194e-16" mesh="pp01062_stewart_arm" material="pp01062_stewart_arm_material"/>
          <!-- Part ball_6 -->
          <geom type="mesh" class="visual" pos="0.038 -2.77556e-17 0.00768" quat="0 1 0 0" mesh="ball" material="ball_material"/>
          <!-- Link shape_5 -->
          <body name="shape_5" pos="0.038 -2.77556e-17 0.00768" quat="0.0131438 -0.855436 -0.517229 0.0230347">
            <!-- Joint from pp01062_stewart_arm_6 to shape_5 -->
            <joint axis="0 0 1" name="passive_6" type="ball" class="chosen_actuator"/>
            <inertial pos="-0.0450002 7.95049e-16 -1.5589e-17" mass="0.00355525" fullinertia="1.7732e-08 3.06049e-06 3.0658e-06 4.84585e-20 -8.92792e-21 -1.86218e-20"/>
            <!-- Part shape_11 -->
            <geom type="mesh" class="visual" pos="-0.0900003 1.83187e-15 6.93889e-18" quat="1.77636e-15 6.61483e-15 1 6.27276e-15" mesh="shape" material="shape_material"/>
            <!-- Part shape_12 -->
            <geom type="mesh" class="visual" pos="6.93889e-18 0 0" quat="1 1.00165e-17 -8.32667e-17 0" mesh="shape" material="shape_material"/>
            <!-- Part pp00xxx_stewart_rod_6 -->
            <geom type="mesh" class="visual" pos="0.00371031 0.0370326 -0.0564076" quat="0.855513 0.00634803 -0.517727 0.00384161" mesh="pp00xxx_stewart_rod" material="pp00xxx_stewart_rod_material"/>
            <!-- Link pp01063_stewart_plateform -->
            <body name="pp01063_stewart_plateform" pos="-0.0900003 1.88738e-15 -2.08167e-17" quat="0.0131438 0.855436 0.517229 -0.0230347">
              <!-- Joint from shape_5 to pp01063_stewart_plateform -->
              <joint axis="0 0 1" name="passive_7" type="ball" class="chosen_actuator"/>
              <inertial pos="-0.00488914 -0.0469134 0.0291732" mass="0.168092" fullinertia="0.000413571 0.000428808 0.000324749 -2.28564e-06 -5.24367e-05 -9.58295e-07"/>
              <!-- Part small_lens -->
              <geom type="mesh" class="visual" pos="0.0262444 -0.0524 0.0136834" quat="0.612372 0.612372 -0.353553 0.353553" mesh="small_lens" material="small_lens_material"/>
              <!-- Part m12_lens -->
              <geom type="mesh" class="visual" pos="0.010421 -0.0524 -0.0147088" quat="0.183013 0.683013 -0.683013 -0.183013" mesh="m12_lens" material="m12_lens_material"/>
              <!-- Part pp01080_back_small_eye -->
              <geom type="mesh" class="visual" pos="0.0262444 -0.0524 0.0136834" quat="0.612372 0.612372 -0.353553 0.353553" mesh="pp01080_back_small_eye" material="pp01080_back_small_eye_material"/>
              <!-- Part m12_lens_2 -->
              <geom type="mesh" class="visual" pos="0.042581 -0.0524 0.0417792" quat="0.183013 0.683013 -0.683013 -0.183013" mesh="m12_lens" material="m12_lens_material"/>
              <!-- Part ball_7 -->
              <geom type="mesh" class="visual" pos="-0.013 5.55112e-17 -5.55112e-17" quat="1 1.3274e-15 5.77316e-15 -2.63678e-15" mesh="ball" material="ball_material"/>
              <!-- Part uc_a37_rev_a_step -->
              <geom type="mesh" class="visual" pos="0.0239513 -0.04265 0.0271316" quat="9.36644e-18 0.866025 0 0.5" mesh="uc_a37_rev_a_step" material="uc_a37_rev_a_step_material"/>
              <!-- Part ball_8 -->
              <geom type="mesh" class="visual" pos="-8.67362e-19 2.77556e-17 0" quat="1 -0 -2.04613e-16 -5.18024e-19" mesh="ball" material="ball_material"/>
              <!-- Part pp01070_head_head_back -->
              <geom type="mesh" class="visual" pos="-0.0134282 -0.0524 0.0365883" quat="0.612372 0.612372 -0.353553 0.353553" mesh="pp01070_head_head_back" material="pp01070_head_head_back_material"/>
              <!-- Part ball_9 -->
              <geom type="mesh" class="visual" pos="0.0249723 5.55112e-17 0.0432533" quat="1.36964e-17 0.866025 -1.11022e-16 -0.5" mesh="ball" material="ball_material"/>
              <!-- Part pp01079_back_big_eye -->
              <geom type="mesh" class="visual" pos="0.0265844 -0.0524 0.013487" quat="0.612372 0.612372 -0.353553 0.353553" mesh="pp01079_back_big_eye" material="pp01079_back_big_eye_material"/>
              <!-- Part ball_10 -->
              <geom type="mesh" class="visual" pos="-0.0379723 5.55112e-17 0.0432533" quat="0.353553 -0.612372 0.612372 -0.353553" mesh="ball" material="ball_material"/>
              <!-- Part pp01069_head_shell_front -->
              <geom type="mesh" class="visual" pos="-0.0142942 -0.0524 0.0370883" quat="0.612372 0.612372 -0.353553 0.353553" mesh="pp01069_head_shell_front" material="pp01069_head_shell_front_material"/>
              <!-- Part pp01078_glasses -->
              <geom type="mesh" class="visual" pos="0.025976 -0.0524 0.0138383" quat="0.612372 0.612372 -0.353553 0.353553" mesh="pp01078_glasses" material="pp01078_glasses_material"/>
              <!-- Part pp01063_stewart_plateform -->
              <geom type="mesh" class="visual" pos="-0.0065 0.109722 0.0325883" quat="0.353553 0.353553 0.612372 -0.612372" mesh="pp01063_stewart_plateform" material="pp01063_stewart_plateform_material"/>
              <!-- Part ball_11 -->
              <geom type="mesh" class="visual" pos="-0.0314723 2.77556e-17 0.0545117" quat="0.353553 -0.612372 0.612372 -0.353553" mesh="ball" material="ball_material"/>
              <!-- Part big_lens -->
              <geom type="mesh" class="visual" pos="0.0281677 -0.0524 0.0125729" quat="0.612372 0.612372 -0.353553 0.353553" mesh="big_lens" material="big_lens_material"/>
              <!-- Part ball_12 -->
              <geom type="mesh" class="visual" pos="0.0184723 5.55112e-17 0.0545117" quat="3.07775e-17 -0.866025 -0 0.5" mesh="ball" material="ball_material"/>
              <!-- Frame closing_1_2 -->
              <site group="3" name="closing_1_2" pos="0.0249723 5.55112e-17 0.0432533" quat="0.353553 0.612372 -0.612372 -0.353553"/>
              <!-- Frame closing_2_1 -->
              <site group="3" name="closing_2_1" pos="0.0184723 5.55112e-17 0.0545117" quat="3.07775e-17 -0.866025 -0 0.5"/>
              <!-- Frame closing_3_1 -->
              <site group="3" name="closing_3_1" pos="-0.0314723 2.77556e-17 0.0545117" quat="0.353553 -0.612372 0.612372 -0.353553"/>
              <!-- Frame closing_4_2 -->
              <site group="3" name="closing_4_2" pos="-0.0379723 5.55112e-17 0.0432533" quat="0.612372 0.353553 -0.353553 -0.612372"/>
              <!-- Frame closing_5_2 -->
              <site group="3" name="closing_5_2" pos="-0.013 5.55112e-17 -5.55112e-17" quat="0.707107 -3.16544e-15 5.10703e-15 -0.707107"/>
              <!-- Frame head -->
              <site group="3" name="head" pos="-0.0134282 -0.0012 0.0365883" quat="0.683013 0.683013 0.183013 -0.183013"/>
              <!-- Frame camera -->
              <site group="3" name="camera" pos="0.0244171 -0.0524 0.0147383" quat="0.683013 0.683013 0.183013 -0.183013"/>
              <!-- Frame camera_optical -->
              <site group="3" name="camera_optical" pos="0.0244171 -0.0524 0.0147383" quat="0.5 0 0.866025 -2.22045e-16"/>
              <!-- Link test_antenna_body -->
              <body name="test_antenna_body" pos="-0.0161053 -0.0744 0.100068" quat="0.964418 0.0356203 -0.25955 0.0355422">
                <!-- Joint from pp01063_stewart_plateform to test_antenna_body -->
                <joint axis="0 0 1" name="left_antenna" type="hinge" class="chosen_actuator"/>
                <inertial pos="0.00147983 -0.0294086 0.00298611" mass="0.00456766" fullinertia="1.38179e-05 2.28739e-07 1.38227e-05 6.85535e-07 5.01796e-08 -9.97217e-07"/>
                <!-- Part test_antenna -->
                <geom type="mesh" class="visual" pos="0.0285777 0.0175124 -0.0571006" quat="0.716727 0.647969 0.191203 -0.172861" mesh="test_antenna" material="test_antenna_material"/>
                <!-- Part test_antenna_body -->
                <geom type="mesh" class="visual" pos="0.0285297 0.0184653 -0.0570171" quat="0.716727 0.647969 0.191203 -0.172861" mesh="test_antenna_body" material="test_antenna_body_material"/>
              </body>
              <!-- Link test_antenna -->
              <body name="test_antenna" pos="-0.0697422 -0.0744 0.00716666" quat="0.706492 0.0909539 -0.701233 -0.0294913">
                <!-- Joint from pp01063_stewart_plateform to test_antenna -->
                <joint axis="0 0 1" name="right_antenna" type="hinge" class="chosen_actuator"/>
                <inertial pos="0.00147983 -0.0294086 0.00298611" mass="0.00456766" fullinertia="1.38179e-05 2.28739e-07 1.38227e-05 6.85535e-07 5.01796e-08 -9.97217e-07"/>
                <!-- Part test_antenna_2 -->
                <geom type="mesh" class="visual" pos="0.0285777 0.0175124 -0.0571006" quat="0.716727 0.647969 0.191203 -0.172861" mesh="test_antenna" material="test_antenna_material"/>
                <!-- Part test_antenna_body_2 -->
                <geom type="mesh" class="visual" pos="0.0285297 0.0184653 -0.0570171" quat="0.716727 0.647969 0.191203 -0.172861" mesh="test_antenna_body" material="test_antenna_body_material"/>
              </body>
            </body>
          </body>
        </body>
      </body>
    </body>
  </worldbody>
  <asset>
    <mesh file="dc15_a01_case_b_dummy.stl"/>
    <mesh file="pp01078_glasses.stl"/>
    <mesh file="big_lens.stl"/>
    <mesh file="test_antenna_body.stl"/>
    <mesh file="pp01065_stewart_side_plate.stl"/>
    <mesh file="small_lens.stl"/>
    <mesh file="pp01080_back_small_eye.stl"/>
    <mesh file="pp01064_stewart_main_plate.stl"/>
    <mesh file="shape.stl"/>
    <mesh file="pp00xxx_stewart_rod.stl"/>
    <mesh file="pp01079_back_big_eye.stl"/>
    <mesh file="ball.stl"/>
    <mesh file="wj_wk00_0123middlecase_56__configuration_default.stl"/>
    <mesh file="test_antenna.stl"/>
    <mesh file="pp01070_head_head_back.stl"/>
    <mesh file="dc15_a01_case_f_dummy.stl"/>
    <mesh file="drive_palonier__configuration_default.stl"/>
    <mesh file="dc15_a01_horn_dummy.stl"/>
    <mesh file="wj_wk00_0122topcabinetcase_95__configuration_default.stl"/>
    <mesh file="pp01071_turning_bowl.stl"/>
    <mesh file="pp01068_top_body.stl"/>
    <mesh file="wj_wk00_0124bottomcase_45__configuration_default.stl"/>
    <mesh file="uc_a37_rev_a_step.stl"/>
    <mesh file="dc15_a01_case_m_dummy.stl"/>
    <mesh file="pp01062_stewart_arm.stl"/>
    <mesh file="pp01072_turning_end.stl"/>
    <mesh file="m12_lens.stl"/>
    <mesh file="pp01069_head_shell_front.stl"/>
    <mesh file="pp01063_stewart_plateform.stl"/>
    <mesh file="pp01066_stewart_mid_plate.stl"/>
    <mesh file="pp01067_bottom_body.stl"/>
    <material name="pp01071_turning_bowl_material" rgba="0.34902 0.376471 0.4 1"/>
    <material name="pp01072_turning_end_material" rgba="0.262745 0.282353 0.301961 1"/>
    <material name="pp01065_stewart_side_plate_material" rgba="0.196078 0.196078 0.196078 1"/>
    <material name="pp01067_bottom_body_material" rgba="1 1 1 1"/>
    <material name="dc15_a01_case_m_dummy_material" rgba="0.262745 0.282353 0.301961 1"/>
    <material name="dc15_a01_case_f_dummy_material" rgba="0.262745 0.282353 0.301961 1"/>
    <material name="dc15_a01_horn_dummy_material" rgba="0.262745 0.282353 0.301961 1"/>
    <material name="wj_wk00_0122topcabinetcase_95__configuration_default_material" rgba="0.247059 0.243137 0.243137 1"/>
    <material name="dc15_a01_case_b_dummy_material" rgba="0.262745 0.282353 0.301961 1"/>
    <material name="pp01068_top_body_material" rgba="1 1 1 1"/>
    <material name="drive_palonier__configuration_default_material" rgba="0.623529 0.666667 0.701961 1"/>
    <material name="wj_wk00_0123middlecase_56__configuration_default_material" rgba="0.247059 0.243137 0.243137 1"/>
    <material name="pp01066_stewart_mid_plate_material" rgba="0.196078 0.196078 0.196078 1"/>
    <material name="wj_wk00_0124bottomcase_45__configuration_default_material" rgba="0.247059 0.243137 0.243137 1"/>
    <material name="pp01064_stewart_main_plate_material" rgba="0.196078 0.196078 0.196078 1"/>
    <material name="ball_material" rgba="0.901961 0.901961 0.901961 1"/>
    <material name="pp01062_stewart_arm_material" rgba="0.196078 0.196078 0.196078 1"/>
    <material name="shape_material" rgba="0.901961 0.901961 0.901961 1"/>
    <material name="pp00xxx_stewart_rod_material" rgba="0.8 0.8 0.8 1"/>
    <material name="small_lens_material" rgba="0.439216 0.47451 0.501961 0.298039"/>
    <material name="m12_lens_material" rgba="0.262745 0.282353 0.301961 1"/>
    <material name="pp01080_back_small_eye_material" rgba="0.168627 0.168627 0.168627 1"/>
    <material name="uc_a37_rev_a_step_material" rgba="0.25098 0.25098 0.25098 1"/>
    <material name="pp01070_head_head_back_material" rgba="1 1 1 1"/>
    <material name="pp01079_back_big_eye_material" rgba="0.168627 0.168627 0.168627 1"/>
    <material name="pp01069_head_shell_front_material" rgba="1 1 1 1"/>
    <material name="pp01078_glasses_material" rgba="0.168627 0.168627 0.168627 1"/>
    <material name="pp01063_stewart_plateform_material" rgba="1 1 1 1"/>
    <material name="big_lens_material" rgba="0.439216 0.47451 0.501961 0.298039"/>
    <material name="test_antenna_material" rgba="0.262745 0.282353 0.301961 1"/>
    <material name="test_antenna_body_material" rgba="1 1 1 1"/>
  </asset>
  <actuator>
    <position class="chosen_actuator" name="all_yaw" joint="all_yaw"/>
    <position class="chosen_actuator" name="1" joint="1" inheritrange="1"/>
    <position class="chosen_actuator" name="2" joint="2" inheritrange="1"/>
    <position class="chosen_actuator" name="3" joint="3" inheritrange="1"/>
    <position class="chosen_actuator" name="4" joint="4" inheritrange="1"/>
    <position class="chosen_actuator" name="5" joint="5" inheritrange="1"/>
    <position class="chosen_actuator" name="6" joint="6" inheritrange="1"/>
    <position class="chosen_actuator" name="left_antenna" joint="left_antenna"/>
    <position class="chosen_actuator" name="right_antenna" joint="right_antenna"/>
  </actuator>
  <equality>
    <connect site1="closing_1_1" site2="closing_1_2"/>
    <connect site1="closing_2_1" site2="closing_2_2"/>
    <connect site1="closing_3_1" site2="closing_3_2"/>
    <connect site1="closing_4_1" site2="closing_4_2"/>
    <connect site1="closing_5_1" site2="closing_5_2"/>
  </equality>
</mujoco>
