<?xml version="1.0" ?>
<!-- Generated using onshape-to-robot -->
<!-- Onshape https://cad.onshape.com/documents/e305b26a84339af20c593973/w/695ea941e5d92df9f00ffaef/e/333e72319d1d07cd9b78e76b -->
<robot name="robot">
  <!-- Link simplified_xl330 -->
  <link name="simplified_xl330">
    <inertial>
      <origin xyz="1.34605e-07 2.33142e-07 0.0267776" rpy="0 0 0"/>
      <mass value="0.180117"/>
      <inertia ixx="0.00016756" ixy="-2.21414e-09" ixz="-3.40032e-10" iyy="0.000167557" iyz="-5.88953e-10" izz="0.00025142"/>
    </inertial>
    <!-- Part base_side -->
    <visual>
      <origin xyz="2.77241e-17 6.93302e-18 0.0426353" rpy="-2.29587e-16 1.82529e-16 -0.523599"/>
      <geometry>
        <mesh filename="package://assets/base_side.stl"/>
      </geometry>
      <material name="base_side_material">
        <color rgba="1 1 1 1.0"/>
      </material>
    </visual>
    <collision>
      <origin xyz="2.77241e-17 6.93302e-18 0.0426353" rpy="-2.29587e-16 1.82529e-16 -0.523599"/>
      <geometry>
        <mesh filename="package://assets/base_side.stl"/>
      </geometry>
    </collision>
    <!-- Part base_side_2 -->
    <visual>
      <origin xyz="1.31347e-06 4.9169e-07 0.0426361" rpy="-1.39735e-10 -3.14651e-05 -2.61798"/>
      <geometry>
        <mesh filename="package://assets/base_side.stl"/>
      </geometry>
      <material name="base_side_2_material">
        <color rgba="1 1 1 1.0"/>
      </material>
    </visual>
    <collision>
      <origin xyz="1.31347e-06 4.9169e-07 0.0426361" rpy="-1.39735e-10 -3.14651e-05 -2.61798"/>
      <geometry>
        <mesh filename="package://assets/base_side.stl"/>
      </geometry>
    </collision>
    <!-- Part base_top -->
    <visual>
      <origin xyz="2.56857e-17 9.03047e-18 0.0426353" rpy="-2.2879e-16 1.82778e-16 -0.523599"/>
      <geometry>
        <mesh filename="package://assets/base_top.stl"/>
      </geometry>
      <material name="base_top_material">
        <color rgba="0.615686 0.811765 0.929412 1.0"/>
      </material>
    </visual>
    <collision>
      <origin xyz="2.56857e-17 9.03047e-18 0.0426353" rpy="-2.2879e-16 1.82778e-16 -0.523599"/>
      <geometry>
        <mesh filename="package://assets/base_top.stl"/>
      </geometry>
    </collision>
    <!-- Part base_side_3 -->
    <visual>
      <origin xyz="-2.30919e-07 1.38334e-06 0.0426361" rpy="-1.39733e-10 3.14651e-05 1.57079"/>
      <geometry>
        <mesh filename="package://assets/base_side.stl"/>
      </geometry>
      <material name="base_side_3_material">
        <color rgba="1 1 1 1.0"/>
      </material>
    </visual>
    <collision>
      <origin xyz="-2.30919e-07 1.38334e-06 0.0426361" rpy="-1.39733e-10 3.14651e-05 1.57079"/>
      <geometry>
        <mesh filename="package://assets/base_side.stl"/>
      </geometry>
    </collision>
    <!-- Part base_bot -->
    <visual>
      <origin xyz="-1.00763e-17 -1.82615e-18 0.0426353" rpy="3.40237e-16 3.2563e-16 -0.523599"/>
      <geometry>
        <mesh filename="package://assets/base_bot.stl"/>
      </geometry>
      <material name="base_bot_material">
        <color rgba="0.85098 0.756863 0.866667 1.0"/>
      </material>
    </visual>
    <collision>
      <origin xyz="-1.00763e-17 -1.82615e-18 0.0426353" rpy="3.40237e-16 3.2563e-16 -0.523599"/>
      <geometry>
        <mesh filename="package://assets/base_bot.stl"/>
      </geometry>
    </collision>
    <!-- Part simplified_xl330 -->
    <visual>
      <origin xyz="0.0239338 0.0203709 0.0296924" rpy="1.27428 -0.37714 1.68284"/>
      <geometry>
        <mesh filename="package://assets/simplified_xl330.stl"/>
      </geometry>
      <material name="simplified_xl330_material">
        <color rgba="0.301961 0.301961 0.301961 1.0"/>
      </material>
    </visual>
    <collision>
      <origin xyz="0.0239338 0.0203709 0.0296924" rpy="1.27428 -0.37714 1.68284"/>
      <geometry>
        <mesh filename="package://assets/simplified_xl330.stl"/>
      </geometry>
    </collision>
    <!-- Part simplified_xl330_2 -->
    <visual>
      <origin xyz="0.00567481 0.0309127 0.0296924" rpy="1.27428 0.37714 -2.73004"/>
      <geometry>
        <mesh filename="package://assets/simplified_xl330.stl"/>
      </geometry>
      <material name="simplified_xl330_2_material">
        <color rgba="0.301961 0.301961 0.301961 1.0"/>
      </material>
    </visual>
    <collision>
      <origin xyz="0.00567481 0.0309127 0.0296924" rpy="1.27428 0.37714 -2.73004"/>
      <geometry>
        <mesh filename="package://assets/simplified_xl330.stl"/>
      </geometry>
    </collision>
    <!-- Part simplified_xl330_3 -->
    <visual>
      <origin xyz="-0.0296071 0.0105423 0.0296936" rpy="1.27427 -0.377203 -2.50593"/>
      <geometry>
        <mesh filename="package://assets/simplified_xl330.stl"/>
      </geometry>
      <material name="simplified_xl330_3_material">
        <color rgba="0.301961 0.301961 0.301961 1.0"/>
      </material>
    </visual>
    <collision>
      <origin xyz="-0.0296071 0.0105423 0.0296936" rpy="1.27427 -0.377203 -2.50593"/>
      <geometry>
        <mesh filename="package://assets/simplified_xl330.stl"/>
      </geometry>
    </collision>
    <!-- Part simplified_xl330_4 -->
    <visual>
      <origin xyz="0.00567413 -0.0309124 0.0296922" rpy="1.27427 -0.377171 -0.411546"/>
      <geometry>
        <mesh filename="package://assets/simplified_xl330.stl"/>
      </geometry>
      <material name="simplified_xl330_4_material">
        <color rgba="0.301961 0.301961 0.301961 1.0"/>
      </material>
    </visual>
    <collision>
      <origin xyz="0.00567413 -0.0309124 0.0296922" rpy="1.27427 -0.377171 -0.411546"/>
      <geometry>
        <mesh filename="package://assets/simplified_xl330.stl"/>
      </geometry>
    </collision>
    <!-- Part simplified_xl330_5 -->
    <visual>
      <origin xyz="-0.029608 -0.0105423 0.0296922" rpy="1.27427 0.377171 -0.635652"/>
      <geometry>
        <mesh filename="package://assets/simplified_xl330.stl"/>
      </geometry>
      <material name="simplified_xl330_5_material">
        <color rgba="0.301961 0.301961 0.301961 1.0"/>
      </material>
    </visual>
    <collision>
      <origin xyz="-0.029608 -0.0105423 0.0296922" rpy="1.27427 0.377171 -0.635652"/>
      <geometry>
        <mesh filename="package://assets/simplified_xl330.stl"/>
      </geometry>
    </collision>
    <!-- Part simplified_xl330_6 -->
    <visual>
      <origin xyz="0.0239334 -0.0203694 0.0296936" rpy="1.27427 0.377203 1.45873"/>
      <geometry>
        <mesh filename="package://assets/simplified_xl330.stl"/>
      </geometry>
      <material name="simplified_xl330_6_material">
        <color rgba="0.301961 0.301961 0.301961 1.0"/>
      </material>
    </visual>
    <collision>
      <origin xyz="0.0239334 -0.0203694 0.0296936" rpy="1.27427 0.377203 1.45873"/>
      <geometry>
        <mesh filename="package://assets/simplified_xl330.stl"/>
      </geometry>
    </collision>
  </link>
  <!-- Link left_arm -->
  <link name="left_arm">
    <inertial>
      <origin xyz="-0.0267634 0.0046049 0.00174754" rpy="0 0 0"/>
      <mass value="0.00541129"/>
      <inertia ixx="1.47788e-07" ixy="1.70926e-07" ixz="1.92071e-07" iyy="1.39835e-06" iyz="-2.15256e-08" izz="1.40141e-06"/>
    </inertial>
    <!-- Part magnet -->
    <visual>
      <origin xyz="-0.038 6.245e-17 0.00384958" rpy="1.5708 1.10155e-16 3.14159"/>
      <geometry>
        <mesh filename="package://assets/magnet.stl"/>
      </geometry>
      <material name="magnet_material">
        <color rgba="0.713725 0.760784 0.8 1.0"/>
      </material>
    </visual>
    <collision>
      <origin xyz="-0.038 6.245e-17 0.00384958" rpy="1.5708 1.10155e-16 3.14159"/>
      <geometry>
        <mesh filename="package://assets/magnet.stl"/>
      </geometry>
    </collision>
    <!-- Part left_arm -->
    <visual>
      <origin xyz="0.0175 -0.0120291 0.0464647" rpy="1.84591 -3.55118e-18 -9.19674e-17"/>
      <geometry>
        <mesh filename="package://assets/left_arm.stl"/>
      </geometry>
      <material name="left_arm_material">
        <color rgba="1 1 1 1.0"/>
      </material>
    </visual>
    <collision>
      <origin xyz="0.0175 -0.0120291 0.0464647" rpy="1.84591 -3.55118e-18 -9.19674e-17"/>
      <geometry>
        <mesh filename="package://assets/left_arm.stl"/>
      </geometry>
    </collision>
  </link>
  <!-- Link passive_1_link_x -->
  <link name="passive_1_link_x">
    <inertial>
      <origin xyz="0 0 0" rpy="0 0 0"/>
      <mass value="1e-09"/>
      <inertia ixx="1e-09" ixy="0" ixz="0" iyy="1e-09" iyz="0" izz="1e-09"/>
    </inertial>
  </link>
  <!-- Link passive_1_link_y -->
  <link name="passive_1_link_y">
    <inertial>
      <origin xyz="0 0 0" rpy="0 0 0"/>
      <mass value="1e-09"/>
      <inertia ixx="1e-09" ixy="0" ixz="0" iyy="1e-09" iyz="0" izz="1e-09"/>
    </inertial>
  </link>
  <!-- Link rod -->
  <link name="rod">
    <inertial>
      <origin xyz="-0.00163493 0.00269119 0.049701" rpy="0 0 0"/>
      <mass value="0.0100726"/>
      <inertia ixx="2.05276e-05" ixy="3.62962e-08" ixz="6.70317e-07" iyy="2.04899e-05" iyz="-1.10338e-06" izz="1.72358e-07"/>
    </inertial>
    <!-- Part rod -->
    <visual>
      <origin xyz="0.0461199 -0.037426 0.0389005" rpy="0.338673 0.485261 -3.04345"/>
      <geometry>
        <mesh filename="package://assets/rod.stl"/>
      </geometry>
      <material name="rod_material">
        <color rgba="0.262745 0.282353 0.301961 1.0"/>
      </material>
    </visual>
    <collision>
      <origin xyz="0.0461199 -0.037426 0.0389005" rpy="0.338673 0.485261 -3.04345"/>
      <geometry>
        <mesh filename="package://assets/rod.stl"/>
      </geometry>
    </collision>
    <!-- Part 10mm_ball -->
    <visual>
      <origin xyz="-0.00326986 0.00538239 0.0994019" rpy="0.0562358 0.0290136 -3.07149"/>
      <geometry>
        <mesh filename="package://assets/10mm_ball.stl"/>
      </geometry>
      <material name="10mm_ball_material">
        <color rgba="0.713725 0.760784 0.8 1.0"/>
      </material>
    </visual>
    <collision>
      <origin xyz="-0.00326986 0.00538239 0.0994019" rpy="0.0562358 0.0290136 -3.07149"/>
      <geometry>
        <mesh filename="package://assets/10mm_ball.stl"/>
      </geometry>
    </collision>
    <!-- Part 10mm_ball_2 -->
    <visual>
      <origin xyz="0 1.31839e-16 -6.93889e-18" rpy="3.08536 -0.0290136 0.0701014"/>
      <geometry>
        <mesh filename="package://assets/10mm_ball.stl"/>
      </geometry>
      <material name="10mm_ball_2_material">
        <color rgba="0.713725 0.760784 0.8 1.0"/>
      </material>
    </visual>
    <collision>
      <origin xyz="0 1.31839e-16 -6.93889e-18" rpy="3.08536 -0.0290136 0.0701014"/>
      <geometry>
        <mesh filename="package://assets/10mm_ball.stl"/>
      </geometry>
    </collision>
  </link>
  <!-- Frame closing_2_1 (dummy link + fixed joint) -->
  <link name="closing_2_1">
    <origin xyz="0 0 0" rpy="0 -0 0"/>
    <inertial>
      <origin xyz="0 0 0" rpy="0 0 0"/>
      <mass value="1e-9"/>
      <inertia ixx="0" ixy="0" ixz="0" iyy="0" iyz="0" izz="0"/>
    </inertial>
  </link>
  <joint name="closing_2_1_frame" type="fixed">
    <origin xyz="-0.00326986 0.00538239 0.0994019" rpy="-3.08536 0.0290136 -3.07149"/>
    <parent link="rod"/>
    <child link="closing_2_1"/>
    <axis xyz="0 0 0"/>
  </joint>
  <!-- Joint from passive_1_link_y to rod -->
  <joint name="passive_1_z" type="revolute">
    <origin xyz="1.38778e-17 -6.93889e-18 -3.46945e-18" rpy="-1.91261e-17 3.04674e-17 5.37636e-17"/>
    <parent link="passive_1_link_y"/>
    <child link="rod"/>
    <axis xyz="0 0 1"/>
    <limit effort="10" velocity="10" lower="-3.141592653589793" upper="3.141592653589793"/>
  </joint>
  <!-- Joint from passive_1_link_x to passive_1_link_y -->
  <joint name="passive_1_y" type="revolute">
    <origin xyz="1.38778e-17 -6.93889e-18 -3.46945e-18" rpy="-1.91261e-17 3.04674e-17 5.37636e-17"/>
    <parent link="passive_1_link_x"/>
    <child link="passive_1_link_y"/>
    <axis xyz="0 1 0"/>
    <limit effort="10" velocity="10" lower="-3.141592653589793" upper="3.141592653589793"/>
  </joint>
  <!-- Joint from left_arm to passive_1_link_x -->
  <joint name="passive_1_x" type="revolute">
    <origin xyz="-0.038 6.245e-17 0.00384958" rpy="-1.5708 1.10155e-16 3.14159"/>
    <parent link="left_arm"/>
    <child link="passive_1_link_x"/>
    <axis xyz="1 0 0"/>
    <limit effort="10" velocity="10" lower="-3.141592653589793" upper="3.141592653589793"/>
  </joint>
  <!-- Joint from simplified_xl330 to left_arm -->
  <joint name="1" type="revolute">
    <origin xyz="-0.0386923 -0.0320171 0.0434238" rpy="-1.86732 0.377171 -0.635652"/>
    <parent link="simplified_xl330"/>
    <child link="left_arm"/>
    <axis xyz="0 0 1"/>
    <limit effort="10" velocity="10" lower="-3.141592653589793" upper="3.141592653589793"/>
  </joint>
  <!-- Link right_arm -->
  <link name="right_arm">
    <inertial>
      <origin xyz="0.0267634 0.0046049 0.00174754" rpy="0 0 0"/>
      <mass value="0.00541129"/>
      <inertia ixx="1.47788e-07" ixy="-1.70926e-07" ixz="-1.92071e-07" iyy="1.39835e-06" iyz="-2.15256e-08" izz="1.40141e-06"/>
    </inertial>
    <!-- Part magnet_2 -->
    <visual>
      <origin xyz="0.038 1.38778e-17 0.00384958" rpy="1.5708 8.51439e-17 -3.14159"/>
      <geometry>
        <mesh filename="package://assets/magnet.stl"/>
      </geometry>
      <material name="magnet_2_material">
        <color rgba="0.713725 0.760784 0.8 1.0"/>
      </material>
    </visual>
    <collision>
      <origin xyz="0.038 1.38778e-17 0.00384958" rpy="1.5708 8.51439e-17 -3.14159"/>
      <geometry>
        <mesh filename="package://assets/magnet.stl"/>
      </geometry>
    </collision>
    <!-- Part right_arm -->
    <visual>
      <origin xyz="-0.0175 -0.0120291 0.0464647" rpy="1.84591 9.59615e-18 4.52996e-17"/>
      <geometry>
        <mesh filename="package://assets/right_arm.stl"/>
      </geometry>
      <material name="right_arm_material">
        <color rgba="1 1 1 1.0"/>
      </material>
    </visual>
    <collision>
      <origin xyz="-0.0175 -0.0120291 0.0464647" rpy="1.84591 9.59615e-18 4.52996e-17"/>
      <geometry>
        <mesh filename="package://assets/right_arm.stl"/>
      </geometry>
    </collision>
  </link>
  <!-- Link passive_6_link_x -->
  <link name="passive_6_link_x">
    <inertial>
      <origin xyz="0 0 0" rpy="0 0 0"/>
      <mass value="1e-09"/>
      <inertia ixx="1e-09" ixy="0" ixz="0" iyy="1e-09" iyz="0" izz="1e-09"/>
    </inertial>
  </link>
  <!-- Link passive_6_link_y -->
  <link name="passive_6_link_y">
    <inertial>
      <origin xyz="0 0 0" rpy="0 0 0"/>
      <mass value="1e-09"/>
      <inertia ixx="1e-09" ixy="0" ixz="0" iyy="1e-09" iyz="0" izz="1e-09"/>
    </inertial>
  </link>
  <!-- Link 10mm_ball -->
  <link name="10mm_ball">
    <inertial>
      <origin xyz="5.25186e-16 5.58747e-18 0.0498006" rpy="0 0 0"/>
      <mass value="0.0100726"/>
      <inertia ixx="2.05497e-05" ixy="-3.58088e-21" ixz="-2.00486e-19" iyy="2.05497e-05" iyz="-2.62417e-21" izz="9.05619e-08"/>
    </inertial>
    <!-- Part rod_2 -->
    <visual>
      <origin xyz="0.0444954 -0.0426152 0.0352861" rpy="0.275115 0.457035 -3.14159"/>
      <geometry>
        <mesh filename="package://assets/rod.stl"/>
      </geometry>
      <material name="rod_2_material">
        <color rgba="0.262745 0.282353 0.301961 1.0"/>
      </material>
    </visual>
    <collision>
      <origin xyz="0.0444954 -0.0426152 0.0352861" rpy="0.275115 0.457035 -3.14159"/>
      <geometry>
        <mesh filename="package://assets/rod.stl"/>
      </geometry>
    </collision>
    <!-- Part 10mm_ball_3 -->
    <visual>
      <origin xyz="0 0 -3.46945e-18" rpy="-3.14159 -2.02993e-17 4.97353e-18"/>
      <geometry>
        <mesh filename="package://assets/10mm_ball.stl"/>
      </geometry>
      <material name="10mm_ball_3_material">
        <color rgba="0.713725 0.760784 0.8 1.0"/>
      </material>
    </visual>
    <collision>
      <origin xyz="0 0 -3.46945e-18" rpy="-3.14159 -2.02993e-17 4.97353e-18"/>
      <geometry>
        <mesh filename="package://assets/10mm_ball.stl"/>
      </geometry>
    </collision>
    <!-- Part 10mm_ball_4 -->
    <visual>
      <origin xyz="1.07553e-15 1.38778e-17 0.0996012" rpy="-4.68876e-15 -3.84954e-16 3.14159"/>
      <geometry>
        <mesh filename="package://assets/10mm_ball.stl"/>
      </geometry>
      <material name="10mm_ball_4_material">
        <color rgba="0.713725 0.760784 0.8 1.0"/>
      </material>
    </visual>
    <collision>
      <origin xyz="1.07553e-15 1.38778e-17 0.0996012" rpy="-4.68876e-15 -3.84954e-16 3.14159"/>
      <geometry>
        <mesh filename="package://assets/10mm_ball.stl"/>
      </geometry>
    </collision>
  </link>
  <!-- Frame closing_3_2 (dummy link + fixed joint) -->
  <link name="closing_3_2">
    <origin xyz="0 0 0" rpy="0 -0 0"/>
    <inertial>
      <origin xyz="0 0 0" rpy="0 0 0"/>
      <mass value="1e-9"/>
      <inertia ixx="0" ixy="0" ixz="0" iyy="0" iyz="0" izz="0"/>
    </inertial>
  </link>
  <joint name="closing_3_2_frame" type="fixed">
    <origin xyz="1.07553e-15 1.38778e-17 0.0996012" rpy="4.68876e-15 3.84954e-16 -1.1657e-16"/>
    <parent link="10mm_ball"/>
    <child link="closing_3_2"/>
    <axis xyz="0 0 0"/>
  </joint>
  <!-- Joint from passive_6_link_y to 10mm_ball -->
  <joint name="passive_6_z" type="revolute">
    <origin xyz="0 0 -3.46945e-18" rpy="2.96551e-17 -2.02993e-17 4.97353e-18"/>
    <parent link="passive_6_link_y"/>
    <child link="10mm_ball"/>
    <axis xyz="0 0 1"/>
    <limit effort="10" velocity="10" lower="-3.141592653589793" upper="3.141592653589793"/>
  </joint>
  <!-- Joint from passive_6_link_x to passive_6_link_y -->
  <joint name="passive_6_y" type="revolute">
    <origin xyz="0 0 -3.46945e-18" rpy="2.96551e-17 -2.02993e-17 4.97353e-18"/>
    <parent link="passive_6_link_x"/>
    <child link="passive_6_link_y"/>
    <axis xyz="0 1 0"/>
    <limit effort="10" velocity="10" lower="-3.141592653589793" upper="3.141592653589793"/>
  </joint>
  <!-- Joint from right_arm to passive_6_link_x -->
  <joint name="passive_6_x" type="revolute">
    <origin xyz="0.038 4.51028e-17 0.00384958" rpy="-1.63195 0.485977 3.08012"/>
    <parent link="right_arm"/>
    <child link="passive_6_link_x"/>
    <axis xyz="1 0 0"/>
    <limit effort="10" velocity="10" lower="-3.141592653589793" upper="3.141592653589793"/>
  </joint>
  <!-- Joint from simplified_xl330 to right_arm -->
  <joint name="2" type="revolute">
    <origin xyz="-0.00838143 -0.0495171 0.0434238" rpy="-1.86732 -0.377171 -0.411546"/>
    <parent link="simplified_xl330"/>
    <child link="right_arm"/>
    <axis xyz="0 0 1"/>
    <limit effort="10" velocity="10" lower="-3.141592653589793" upper="3.141592653589793"/>
  </joint>
  <!-- Link left_arm_2 -->
  <link name="left_arm_2">
    <inertial>
      <origin xyz="-0.0267634 0.0046049 0.00174754" rpy="0 0 0"/>
      <mass value="0.00541129"/>
      <inertia ixx="1.47788e-07" ixy="1.70926e-07" ixz="1.92071e-07" iyy="1.39835e-06" iyz="-2.15256e-08" izz="1.40141e-06"/>
    </inertial>
    <!-- Part magnet_3 -->
    <visual>
      <origin xyz="-0.038 -1.04083e-17 0.00384958" rpy="-1.5708 -1.5708 0"/>
      <geometry>
        <mesh filename="package://assets/magnet.stl"/>
      </geometry>
      <material name="magnet_3_material">
        <color rgba="0.713725 0.760784 0.8 1.0"/>
      </material>
    </visual>
    <collision>
      <origin xyz="-0.038 -1.04083e-17 0.00384958" rpy="-1.5708 -1.5708 0"/>
      <geometry>
        <mesh filename="package://assets/magnet.stl"/>
      </geometry>
    </collision>
    <!-- Part left_arm_2 -->
    <visual>
      <origin xyz="0.0175 -0.0120291 0.0464647" rpy="1.84591 1.49967e-17 -1.51216e-17"/>
      <geometry>
        <mesh filename="package://assets/left_arm.stl"/>
      </geometry>
      <material name="left_arm_2_material">
        <color rgba="1 1 1 1.0"/>
      </material>
    </visual>
    <collision>
      <origin xyz="0.0175 -0.0120291 0.0464647" rpy="1.84591 1.49967e-17 -1.51216e-17"/>
      <geometry>
        <mesh filename="package://assets/left_arm.stl"/>
      </geometry>
    </collision>
  </link>
  <!-- Link passive_5_link_x -->
  <link name="passive_5_link_x">
    <inertial>
      <origin xyz="0 0 0" rpy="0 0 0"/>
      <mass value="1e-09"/>
      <inertia ixx="1e-09" ixy="0" ixz="0" iyy="1e-09" iyz="0" izz="1e-09"/>
    </inertial>
  </link>
  <!-- Link passive_5_link_y -->
  <link name="passive_5_link_y">
    <inertial>
      <origin xyz="0 0 0" rpy="0 0 0"/>
      <mass value="1e-09"/>
      <inertia ixx="1e-09" ixy="0" ixz="0" iyy="1e-09" iyz="0" izz="1e-09"/>
    </inertial>
  </link>
  <!-- Link 10mm_ball_2 -->
  <link name="10mm_ball_2">
    <inertial>
      <origin xyz="-2.22203e-16 1.38918e-17 0.0498006" rpy="0 0 0"/>
      <mass value="0.0100726"/>
      <inertia ixx="2.05497e-05" ixy="2.30501e-21" ixz="7.71427e-20" iyy="2.05497e-05" iyz="1.09072e-20" izz="9.05619e-08"/>
    </inertial>
    <!-- Part rod_3 -->
    <visual>
      <origin xyz="0.0444954 -0.0426152 0.0352861" rpy="0.275115 0.457035 -3.14159"/>
      <geometry>
        <mesh filename="package://assets/rod.stl"/>
      </geometry>
      <material name="rod_3_material">
        <color rgba="0.262745 0.282353 0.301961 1.0"/>
      </material>
    </visual>
    <collision>
      <origin xyz="0.0444954 -0.0426152 0.0352861" rpy="0.275115 0.457035 -3.14159"/>
      <geometry>
        <mesh filename="package://assets/rod.stl"/>
      </geometry>
    </collision>
    <!-- Part 10mm_ball_5 -->
    <visual>
      <origin xyz="-6.93889e-18 6.93889e-18 0" rpy="-3.14159 -2.05212e-17 -1.09212e-17"/>
      <geometry>
        <mesh filename="package://assets/10mm_ball.stl"/>
      </geometry>
      <material name="10mm_ball_5_material">
        <color rgba="0.713725 0.760784 0.8 1.0"/>
      </material>
    </visual>
    <collision>
      <origin xyz="-6.93889e-18 6.93889e-18 0" rpy="-3.14159 -2.05212e-17 -1.09212e-17"/>
      <geometry>
        <mesh filename="package://assets/10mm_ball.stl"/>
      </geometry>
    </collision>
    <!-- Part 10mm_ball_6 -->
    <visual>
      <origin xyz="-4.3715e-16 2.08167e-17 0.0996012" rpy="1.14058e-14 -8.209e-16 -3.14159"/>
      <geometry>
        <mesh filename="package://assets/10mm_ball.stl"/>
      </geometry>
      <material name="10mm_ball_6_material">
        <color rgba="0.713725 0.760784 0.8 1.0"/>
      </material>
    </visual>
    <collision>
      <origin xyz="-4.3715e-16 2.08167e-17 0.0996012" rpy="1.14058e-14 -8.209e-16 -3.14159"/>
      <geometry>
        <mesh filename="package://assets/10mm_ball.stl"/>
      </geometry>
    </collision>
  </link>
  <!-- Frame closing_4_1 (dummy link + fixed joint) -->
  <link name="closing_4_1">
    <origin xyz="0 0 0" rpy="0 -0 0"/>
    <inertial>
      <origin xyz="0 0 0" rpy="0 0 0"/>
      <mass value="1e-9"/>
      <inertia ixx="0" ixy="0" ixz="0" iyy="0" iyz="0" izz="0"/>
    </inertial>
  </link>
  <joint name="closing_4_1_frame" type="fixed">
    <origin xyz="-4.3715e-16 2.08167e-17 0.0996012" rpy="-3.14159 -8.209e-16 -3.14159"/>
    <parent link="10mm_ball_2"/>
    <child link="closing_4_1"/>
    <axis xyz="0 0 0"/>
  </joint>
  <!-- Joint from passive_5_link_y to 10mm_ball_2 -->
  <joint name="passive_5_z" type="revolute">
    <origin xyz="-6.93889e-18 6.93889e-18 0" rpy="4.59049e-17 -2.05212e-17 -1.09212e-17"/>
    <parent link="passive_5_link_y"/>
    <child link="10mm_ball_2"/>
    <axis xyz="0 0 1"/>
    <limit effort="10" velocity="10" lower="-3.141592653589793" upper="3.141592653589793"/>
  </joint>
  <!-- Joint from passive_5_link_x to passive_5_link_y -->
  <joint name="passive_5_y" type="revolute">
    <origin xyz="-6.93889e-18 6.93889e-18 0" rpy="4.59049e-17 -2.05212e-17 -1.09212e-17"/>
    <parent link="passive_5_link_x"/>
    <child link="passive_5_link_y"/>
    <axis xyz="0 1 0"/>
    <limit effort="10" velocity="10" lower="-3.141592653589793" upper="3.141592653589793"/>
  </joint>
  <!-- Joint from left_arm_2 to passive_5_link_x -->
  <joint name="passive_5_x" type="revolute">
    <origin xyz="-0.038 -3.46945e-18 0.00384958" rpy="1.94647 -1.42258 -0.338994"/>
    <parent link="left_arm_2"/>
    <child link="passive_5_link_x"/>
    <axis xyz="1 0 0"/>
    <limit effort="10" velocity="10" lower="-3.141592653589793" upper="3.141592653589793"/>
  </joint>
  <!-- Joint from simplified_xl330 to left_arm_2 -->
  <joint name="3" type="revolute">
    <origin xyz="0.0470734 -0.017499 0.0434252" rpy="-1.86732 0.377203 1.45873"/>
    <parent link="simplified_xl330"/>
    <child link="left_arm_2"/>
    <axis xyz="0 0 1"/>
    <limit effort="10" velocity="10" lower="-3.141592653589793" upper="3.141592653589793"/>
  </joint>
  <!-- Link right_arm_2 -->
  <link name="right_arm_2">
    <inertial>
      <origin xyz="0.0267634 0.0046049 0.00174754" rpy="0 0 0"/>
      <mass value="0.00541129"/>
      <inertia ixx="1.47788e-07" ixy="-1.70926e-07" ixz="-1.92071e-07" iyy="1.39835e-06" iyz="-2.15256e-08" izz="1.40141e-06"/>
    </inertial>
    <!-- Part right_arm_2 -->
    <visual>
      <origin xyz="-0.0175 -0.0120291 0.0464647" rpy="1.84591 -1.24927e-17 2.64147e-17"/>
      <geometry>
        <mesh filename="package://assets/right_arm.stl"/>
      </geometry>
      <material name="right_arm_2_material">
        <color rgba="1 1 1 1.0"/>
      </material>
    </visual>
    <collision>
      <origin xyz="-0.0175 -0.0120291 0.0464647" rpy="1.84591 -1.24927e-17 2.64147e-17"/>
      <geometry>
        <mesh filename="package://assets/right_arm.stl"/>
      </geometry>
    </collision>
    <!-- Part magnet_4 -->
    <visual>
      <origin xyz="0.038 -1.17961e-16 0.00384958" rpy="-1.5708 7.39625e-18 3.77643e-15"/>
      <geometry>
        <mesh filename="package://assets/magnet.stl"/>
      </geometry>
      <material name="magnet_4_material">
        <color rgba="0.713725 0.760784 0.8 1.0"/>
      </material>
    </visual>
    <collision>
      <origin xyz="0.038 -1.17961e-16 0.00384958" rpy="-1.5708 7.39625e-18 3.77643e-15"/>
      <geometry>
        <mesh filename="package://assets/magnet.stl"/>
      </geometry>
    </collision>
  </link>
  <!-- Link passive_4_link_x -->
  <link name="passive_4_link_x">
    <inertial>
      <origin xyz="0 0 0" rpy="0 0 0"/>
      <mass value="1e-09"/>
      <inertia ixx="1e-09" ixy="0" ixz="0" iyy="1e-09" iyz="0" izz="1e-09"/>
    </inertial>
  </link>
  <!-- Link passive_4_link_y -->
  <link name="passive_4_link_y">
    <inertial>
      <origin xyz="0 0 0" rpy="0 0 0"/>
      <mass value="1e-09"/>
      <inertia ixx="1e-09" ixy="0" ixz="0" iyy="1e-09" iyz="0" izz="1e-09"/>
    </inertial>
  </link>
  <!-- Link 10mm_ball_3 -->
  <link name="10mm_ball_3">
    <inertial>
      <origin xyz="-4.82459e-16 1.12232e-17 0.0498006" rpy="0 0 0"/>
      <mass value="0.0100726"/>
      <inertia ixx="2.05497e-05" ixy="-1.64555e-20" ixz="1.78786e-19" iyy="2.05497e-05" iyz="-1.0978e-20" izz="9.05619e-08"/>
    </inertial>
    <!-- Part 10mm_ball_7 -->
    <visual>
      <origin xyz="0 -1.38778e-17 0" rpy="3.14159 -3.20322e-17 6.66802e-17"/>
      <geometry>
        <mesh filename="package://assets/10mm_ball.stl"/>
      </geometry>
      <material name="10mm_ball_7_material">
        <color rgba="0.713725 0.760784 0.8 1.0"/>
      </material>
    </visual>
    <collision>
      <origin xyz="0 -1.38778e-17 0" rpy="3.14159 -3.20322e-17 6.66802e-17"/>
      <geometry>
        <mesh filename="package://assets/10mm_ball.stl"/>
      </geometry>
    </collision>
    <!-- Part 10mm_ball_8 -->
    <visual>
      <origin xyz="-9.64506e-16 5.55112e-17 0.0996012" rpy="-2.6558e-14 9.92746e-16 -1.5708"/>
      <geometry>
        <mesh filename="package://assets/10mm_ball.stl"/>
      </geometry>
      <material name="10mm_ball_8_material">
        <color rgba="0.713725 0.760784 0.8 1.0"/>
      </material>
    </visual>
    <collision>
      <origin xyz="-9.64506e-16 5.55112e-17 0.0996012" rpy="-2.6558e-14 9.92746e-16 -1.5708"/>
      <geometry>
        <mesh filename="package://assets/10mm_ball.stl"/>
      </geometry>
    </collision>
    <!-- Part rod_4 -->
    <visual>
      <origin xyz="0.0444954 -0.0426152 0.0352861" rpy="0.275115 0.457035 3.14159"/>
      <geometry>
        <mesh filename="package://assets/rod.stl"/>
      </geometry>
      <material name="rod_4_material">
        <color rgba="0.262745 0.282353 0.301961 1.0"/>
      </material>
    </visual>
    <collision>
      <origin xyz="0.0444954 -0.0426152 0.0352861" rpy="0.275115 0.457035 3.14159"/>
      <geometry>
        <mesh filename="package://assets/rod.stl"/>
      </geometry>
    </collision>
  </link>
  <!-- Frame closing_5_2 (dummy link + fixed joint) -->
  <link name="closing_5_2">
    <origin xyz="0 0 0" rpy="0 -0 0"/>
    <inertial>
      <origin xyz="0 0 0" rpy="0 0 0"/>
      <mass value="1e-9"/>
      <inertia ixx="0" ixy="0" ixz="0" iyy="0" iyz="0" izz="0"/>
    </inertial>
  </link>
  <joint name="closing_5_2_frame" type="fixed">
    <origin xyz="-9.64506e-16 5.55112e-17 0.0996012" rpy="2.6558e-14 -9.92746e-16 1.5708"/>
    <parent link="10mm_ball_3"/>
    <child link="closing_5_2"/>
    <axis xyz="0 0 0"/>
  </joint>
  <!-- Joint from passive_4_link_y to 10mm_ball_3 -->
  <joint name="passive_4_z" type="revolute">
    <origin xyz="0 -1.38778e-17 0" rpy="-5.80953e-17 -3.20322e-17 6.66802e-17"/>
    <parent link="passive_4_link_y"/>
    <child link="10mm_ball_3"/>
    <axis xyz="0 0 1"/>
    <limit effort="10" velocity="10" lower="-3.141592653589793" upper="3.141592653589793"/>
  </joint>
  <!-- Joint from passive_4_link_x to passive_4_link_y -->
  <joint name="passive_4_y" type="revolute">
    <origin xyz="0 -1.38778e-17 0" rpy="-5.80953e-17 -3.20322e-17 6.66802e-17"/>
    <parent link="passive_4_link_x"/>
    <child link="passive_4_link_y"/>
    <axis xyz="0 1 0"/>
    <limit effort="10" velocity="10" lower="-3.141592653589793" upper="3.141592653589793"/>
  </joint>
  <!-- Joint from right_arm_2 to passive_4_link_x -->
  <joint name="passive_4_x" type="revolute">
    <origin xyz="0.038 -1.14492e-16 0.00384958" rpy="1.63153 -0.467373 -0.0602377"/>
    <parent link="right_arm_2"/>
    <child link="passive_4_link_x"/>
    <axis xyz="1 0 0"/>
    <limit effort="10" velocity="10" lower="-3.141592653589793" upper="3.141592653589793"/>
  </joint>
  <!-- Joint from simplified_xl330 to right_arm_2 -->
  <joint name="4" type="revolute">
    <origin xyz="0.0470737 0.017501 0.0434241" rpy="-1.86731 -0.37714 1.68284"/>
    <parent link="simplified_xl330"/>
    <child link="right_arm_2"/>
    <axis xyz="0 0 1"/>
    <limit effort="10" velocity="10" lower="-3.141592653589793" upper="3.141592653589793"/>
  </joint>
  <!-- Link left_arm_3 -->
  <link name="left_arm_3">
    <inertial>
      <origin xyz="-0.0267634 0.0046049 0.00174754" rpy="0 0 0"/>
      <mass value="0.00541129"/>
      <inertia ixx="1.47788e-07" ixy="1.70926e-07" ixz="1.92071e-07" iyy="1.39835e-06" iyz="-2.15256e-08" izz="1.40141e-06"/>
    </inertial>
    <!-- Part left_arm_3 -->
    <visual>
      <origin xyz="0.0175 -0.0120291 0.0464647" rpy="1.84591 4.24979e-17 -1.20977e-17"/>
      <geometry>
        <mesh filename="package://assets/left_arm.stl"/>
      </geometry>
      <material name="left_arm_3_material">
        <color rgba="1 1 1 1.0"/>
      </material>
    </visual>
    <collision>
      <origin xyz="0.0175 -0.0120291 0.0464647" rpy="1.84591 4.24979e-17 -1.20977e-17"/>
      <geometry>
        <mesh filename="package://assets/left_arm.stl"/>
      </geometry>
    </collision>
    <!-- Part magnet_5 -->
    <visual>
      <origin xyz="-0.038 -1.249e-16 0.00384958" rpy="-1.5708 1.5708 0"/>
      <geometry>
        <mesh filename="package://assets/magnet.stl"/>
      </geometry>
      <material name="magnet_5_material">
        <color rgba="0.713725 0.760784 0.8 1.0"/>
      </material>
    </visual>
    <collision>
      <origin xyz="-0.038 -1.249e-16 0.00384958" rpy="-1.5708 1.5708 0"/>
      <geometry>
        <mesh filename="package://assets/magnet.stl"/>
      </geometry>
    </collision>
  </link>
  <!-- Link passive_3_link_x -->
  <link name="passive_3_link_x">
    <inertial>
      <origin xyz="0 0 0" rpy="0 0 0"/>
      <mass value="1e-09"/>
      <inertia ixx="1e-09" ixy="0" ixz="0" iyy="1e-09" iyz="0" izz="1e-09"/>
    </inertial>
  </link>
  <!-- Link passive_3_link_y -->
  <link name="passive_3_link_y">
    <inertial>
      <origin xyz="0 0 0" rpy="0 0 0"/>
      <mass value="1e-09"/>
      <inertia ixx="1e-09" ixy="0" ixz="0" iyy="1e-09" iyz="0" izz="1e-09"/>
    </inertial>
  </link>
  <!-- Link 10mm_ball_4 -->
  <link name="10mm_ball_4">
    <inertial>
      <origin xyz="2.61999e-17 1.29673e-17 0.0498006" rpy="0 0 0"/>
      <mass value="0.0100726"/>
      <inertia ixx="2.05497e-05" ixy="-3.01926e-22" ixz="-1.572e-20" iyy="2.05497e-05" iyz="-5.02598e-21" izz="9.05619e-08"/>
    </inertial>
    <!-- Part rod_5 -->
    <visual>
      <origin xyz="0.0444954 -0.0426152 0.0352861" rpy="0.275115 0.457035 -3.14159"/>
      <geometry>
        <mesh filename="package://assets/rod.stl"/>
      </geometry>
      <material name="rod_5_material">
        <color rgba="0.262745 0.282353 0.301961 1.0"/>
      </material>
    </visual>
    <collision>
      <origin xyz="0.0444954 -0.0426152 0.0352861" rpy="0.275115 0.457035 -3.14159"/>
      <geometry>
        <mesh filename="package://assets/rod.stl"/>
      </geometry>
    </collision>
    <!-- Part 10mm_ball_9 -->
    <visual>
      <origin xyz="-6.93889e-18 0 0" rpy="-3.14159 -5.53998e-17 3.69236e-17"/>
      <geometry>
        <mesh filename="package://assets/10mm_ball.stl"/>
      </geometry>
      <material name="10mm_ball_9_material">
        <color rgba="0.713725 0.760784 0.8 1.0"/>
      </material>
    </visual>
    <collision>
      <origin xyz="-6.93889e-18 0 0" rpy="-3.14159 -5.53998e-17 3.69236e-17"/>
      <geometry>
        <mesh filename="package://assets/10mm_ball.stl"/>
      </geometry>
    </collision>
    <!-- Part 10mm_ball_10 -->
    <visual>
      <origin xyz="7.63278e-17 2.77556e-17 0.0996012" rpy="9.49833e-16 5.75899e-17 -3.14159"/>
      <geometry>
        <mesh filename="package://assets/10mm_ball.stl"/>
      </geometry>
      <material name="10mm_ball_10_material">
        <color rgba="0.713725 0.760784 0.8 1.0"/>
      </material>
    </visual>
    <collision>
      <origin xyz="7.63278e-17 2.77556e-17 0.0996012" rpy="9.49833e-16 5.75899e-17 -3.14159"/>
      <geometry>
        <mesh filename="package://assets/10mm_ball.stl"/>
      </geometry>
    </collision>
  </link>
  <!-- Link passive_7_link_x -->
  <link name="passive_7_link_x">
    <inertial>
      <origin xyz="0 0 0" rpy="0 0 0"/>
      <mass value="1e-09"/>
      <inertia ixx="1e-09" ixy="0" ixz="0" iyy="1e-09" iyz="0" izz="1e-09"/>
    </inertial>
  </link>
  <!-- Link passive_7_link_y -->
  <link name="passive_7_link_y">
    <inertial>
      <origin xyz="0 0 0" rpy="0 0 0"/>
      <mass value="1e-09"/>
      <inertia ixx="1e-09" ixy="0" ixz="0" iyy="1e-09" iyz="0" izz="1e-09"/>
    </inertial>
  </link>
  <!-- Link platform -->
  <link name="platform">
    <inertial>
      <origin xyz="-0.0210906 -0.0161908 0.0584805" rpy="0 0 0"/>
      <mass value="0.363548"/>
      <inertia ixx="0.00100069" ixy="2.3324e-05" ixz="3.70713e-05" iyy="0.00100073" iyz="-4.82971e-05" izz="0.00107943"/>
    </inertial>
    <!-- Part magnet_6 -->
    <visual>
      <origin xyz="3.46945e-18 -1.38778e-17 -1.38778e-17" rpy="-1.3621e-17 -3.08255e-17 -6.96528e-17"/>
      <geometry>
        <mesh filename="package://assets/magnet.stl"/>
      </geometry>
      <material name="magnet_6_material">
        <color rgba="0.713725 0.760784 0.8 1.0"/>
      </material>
    </visual>
    <collision>
      <origin xyz="3.46945e-18 -1.38778e-17 -1.38778e-17" rpy="-1.3621e-17 -3.08255e-17 -6.96528e-17"/>
      <geometry>
        <mesh filename="package://assets/magnet.stl"/>
      </geometry>
    </collision>
    <!-- Part mp00663_neck_a2 -->
    <visual>
      <origin xyz="-0.0614166 -0.0410136 0.0528248" rpy="0.292726 0.446444 -0.977716"/>
      <geometry>
        <mesh filename="package://assets/mp00663_neck_a2.stl"/>
      </geometry>
      <material name="mp00663_neck_a2_material">
        <color rgba="0.701961 0.701961 0.701961 1.0"/>
      </material>
    </visual>
    <collision>
      <origin xyz="-0.0614166 -0.0410136 0.0528248" rpy="0.292726 0.446444 -0.977716"/>
      <geometry>
        <mesh filename="package://assets/mp00663_neck_a2.stl"/>
      </geometry>
    </collision>
    <!-- Part magnet_7 -->
    <visual>
      <origin xyz="-0.0347355 0.0172732 0.00975103" rpy="0.868921 0.289653 0.336009"/>
      <geometry>
        <mesh filename="package://assets/magnet.stl"/>
      </geometry>
      <material name="magnet_7_material">
        <color rgba="0.713725 0.760784 0.8 1.0"/>
      </material>
    </visual>
    <collision>
      <origin xyz="-0.0347355 0.0172732 0.00975103" rpy="0.868921 0.289653 0.336009"/>
      <geometry>
        <mesh filename="package://assets/magnet.stl"/>
      </geometry>
    </collision>
    <!-- Part magnet_8 -->
    <visual>
      <origin xyz="0.0114504 0.0172732 0.0101912" rpy="0.875514 -0.307639 -0.337949"/>
      <geometry>
        <mesh filename="package://assets/magnet.stl"/>
      </geometry>
      <material name="magnet_8_material">
        <color rgba="0.713725 0.760784 0.8 1.0"/>
      </material>
    </visual>
    <collision>
      <origin xyz="0.0114504 0.0172732 0.0101912" rpy="0.875514 -0.307639 -0.337949"/>
      <geometry>
        <mesh filename="package://assets/magnet.stl"/>
      </geometry>
    </collision>
    <!-- Part pp00671_monocle_a2 -->
    <visual>
      <origin xyz="-0.0598003 -0.0402533 0.0533951" rpy="0.292726 0.446444 -0.977716"/>
      <geometry>
        <mesh filename="package://assets/pp00671_monocle_a2.stl"/>
      </geometry>
      <material name="pp00671_monocle_a2_material">
        <color rgba="0.262745 0.282353 0.301961 1.0"/>
      </material>
    </visual>
    <collision>
      <origin xyz="-0.0598003 -0.0402533 0.0533951" rpy="0.292726 0.446444 -0.977716"/>
      <geometry>
        <mesh filename="package://assets/pp00671_monocle_a2.stl"/>
      </geometry>
    </collision>
    <!-- Part platform -->
    <visual>
      <origin xyz="-0.0109346 0.0606327 -0.0643152" rpy="-0.528315 0.00952906 3.14159"/>
      <geometry>
        <mesh filename="package://assets/platform.stl"/>
      </geometry>
      <material name="platform_material">
        <color rgba="1 1 1 1.0"/>
      </material>
    </visual>
    <collision>
      <origin xyz="-0.0109346 0.0606327 -0.0643152" rpy="-0.528315 0.00952906 3.14159"/>
      <geometry>
        <mesh filename="package://assets/platform.stl"/>
      </geometry>
    </collision>
    <!-- Part pp00670_front_shell_a2 -->
    <visual>
      <origin xyz="-0.0611719 -0.0409392 0.0529817" rpy="0.292726 0.446444 -0.977716"/>
      <geometry>
        <mesh filename="package://assets/pp00670_front_shell_a2.stl"/>
      </geometry>
      <material name="pp00670_front_shell_a2_material">
        <color rgba="1 1 1 1.0"/>
      </material>
    </visual>
    <collision>
      <origin xyz="-0.0611719 -0.0409392 0.0529817" rpy="0.292726 0.446444 -0.977716"/>
      <geometry>
        <mesh filename="package://assets/pp00670_front_shell_a2.stl"/>
      </geometry>
    </collision>
    <!-- Part magnet_9 -->
    <visual>
      <origin xyz="-0.000192133 0.0345463 0.0201622" rpy="0.860681 -0.32035 -0.341222"/>
      <geometry>
        <mesh filename="package://assets/magnet.stl"/>
      </geometry>
      <material name="magnet_9_material">
        <color rgba="0.713725 0.760784 0.8 1.0"/>
      </material>
    </visual>
    <collision>
      <origin xyz="-0.000192133 0.0345463 0.0201622" rpy="0.860681 -0.32035 -0.341222"/>
      <geometry>
        <mesh filename="package://assets/magnet.stl"/>
      </geometry>
    </collision>
    <!-- Part mp00664_back_sheet_a3 -->
    <visual>
      <origin xyz="-0.0614166 -0.0410136 0.0528248" rpy="0.292726 0.446444 -0.977716"/>
      <geometry>
        <mesh filename="package://assets/mp00664_back_sheet_a3.stl"/>
      </geometry>
      <material name="mp00664_back_sheet_a3_material">
        <color rgba="0.701961 0.701961 0.701961 1.0"/>
      </material>
    </visual>
    <collision>
      <origin xyz="-0.0614166 -0.0410136 0.0528248" rpy="0.292726 0.446444 -0.977716"/>
      <geometry>
        <mesh filename="package://assets/mp00664_back_sheet_a3.stl"/>
      </geometry>
    </collision>
    <!-- Part std00609_ed_lens_m12 -->
    <visual>
      <origin xyz="-0.00226359 -0.0764851 0.0327955" rpy="0.292726 0.446444 -0.977716"/>
      <geometry>
        <mesh filename="package://assets/std00609_ed_lens_m12.stl"/>
      </geometry>
      <material name="std00609_ed_lens_m12_material">
        <color rgba="0.615686 0.811765 0.929412 1.0"/>
      </material>
    </visual>
    <collision>
      <origin xyz="-0.00226359 -0.0764851 0.0327955" rpy="0.292726 0.446444 -0.977716"/>
      <geometry>
        <mesh filename="package://assets/std00609_ed_lens_m12.stl"/>
      </geometry>
    </collision>
    <!-- Part magnet_10 -->
    <visual>
      <origin xyz="-0.0232851 0.0345463 0.0199422" rpy="0.854 0.302384 0.339176"/>
      <geometry>
        <mesh filename="package://assets/magnet.stl"/>
      </geometry>
      <material name="magnet_10_material">
        <color rgba="0.713725 0.760784 0.8 1.0"/>
      </material>
    </visual>
    <collision>
      <origin xyz="-0.0232851 0.0345463 0.0199422" rpy="0.854 0.302384 0.339176"/>
      <geometry>
        <mesh filename="package://assets/magnet.stl"/>
      </geometry>
    </collision>
    <!-- Part std00609_ed_lens_m12_2 -->
    <visual>
      <origin xyz="-0.0347391 -0.0277217 0.0609484" rpy="0.292726 0.446444 -0.977716"/>
      <geometry>
        <mesh filename="package://assets/std00609_ed_lens_m12.stl"/>
      </geometry>
      <material name="std00609_ed_lens_m12_2_material">
        <color rgba="0.615686 0.811765 0.929412 1.0"/>
      </material>
    </visual>
    <collision>
      <origin xyz="-0.0347391 -0.0277217 0.0609484" rpy="0.292726 0.446444 -0.977716"/>
      <geometry>
        <mesh filename="package://assets/std00609_ed_lens_m12.stl"/>
      </geometry>
    </collision>
    <!-- Part magnet_11 -->
    <visual>
      <origin xyz="-0.023093 2.77556e-17 -0.000220061" rpy="-3.5922e-15 -0.0190581 -1.36686e-16"/>
      <geometry>
        <mesh filename="package://assets/magnet.stl"/>
      </geometry>
      <material name="magnet_11_material">
        <color rgba="0.713725 0.760784 0.8 1.0"/>
      </material>
    </visual>
    <collision>
      <origin xyz="-0.023093 2.77556e-17 -0.000220061" rpy="-3.5922e-15 -0.0190581 -1.36686e-16"/>
      <geometry>
        <mesh filename="package://assets/magnet.stl"/>
      </geometry>
    </collision>
  </link>
  <!-- Frame closing_1_1 (dummy link + fixed joint) -->
  <link name="closing_1_1">
    <origin xyz="0 0 0" rpy="0 -0 0"/>
    <inertial>
      <origin xyz="0 0 0" rpy="0 0 0"/>
      <mass value="1e-9"/>
      <inertia ixx="0" ixy="0" ixz="0" iyy="0" iyz="0" izz="0"/>
    </inertial>
  </link>
  <joint name="closing_1_1_frame" type="fixed">
    <origin xyz="0.0114504 0.0172732 0.0101912" rpy="0.875514 -0.307639 -0.337949"/>
    <parent link="platform"/>
    <child link="closing_1_1"/>
    <axis xyz="0 0 0"/>
  </joint>
  <!-- Frame closing_2_2 (dummy link + fixed joint) -->
  <link name="closing_2_2">
    <origin xyz="0 0 0" rpy="0 -0 0"/>
    <inertial>
      <origin xyz="0 0 0" rpy="0 0 0"/>
      <mass value="1e-9"/>
      <inertia ixx="0" ixy="0" ixz="0" iyy="0" iyz="0" izz="0"/>
    </inertial>
  </link>
  <joint name="closing_2_2_frame" type="fixed">
    <origin xyz="-0.000192133 0.0345463 0.0201622" rpy="2.28091 0.32035 2.80037"/>
    <parent link="platform"/>
    <child link="closing_2_2"/>
    <axis xyz="0 0 0"/>
  </joint>
  <!-- Frame closing_3_1 (dummy link + fixed joint) -->
  <link name="closing_3_1">
    <origin xyz="0 0 0" rpy="0 -0 0"/>
    <inertial>
      <origin xyz="0 0 0" rpy="0 0 0"/>
      <mass value="1e-9"/>
      <inertia ixx="0" ixy="0" ixz="0" iyy="0" iyz="0" izz="0"/>
    </inertial>
  </link>
  <joint name="closing_3_1_frame" type="fixed">
    <origin xyz="-0.0232851 0.0345463 0.0199422" rpy="0.854 0.302384 0.339176"/>
    <parent link="platform"/>
    <child link="closing_3_1"/>
    <axis xyz="0 0 0"/>
  </joint>
  <!-- Frame closing_4_2 (dummy link + fixed joint) -->
  <link name="closing_4_2">
    <origin xyz="0 0 0" rpy="0 -0 0"/>
    <inertial>
      <origin xyz="0 0 0" rpy="0 0 0"/>
      <mass value="1e-9"/>
      <inertia ixx="0" ixy="0" ixz="0" iyy="0" iyz="0" izz="0"/>
    </inertial>
  </link>
  <joint name="closing_4_2_frame" type="fixed">
    <origin xyz="-0.0347355 0.0172732 0.00975103" rpy="2.27267 -0.289653 -2.80558"/>
    <parent link="platform"/>
    <child link="closing_4_2"/>
    <axis xyz="0 0 0"/>
  </joint>
  <!-- Frame closing_5_1 (dummy link + fixed joint) -->
  <link name="closing_5_1">
    <origin xyz="0 0 0" rpy="0 -0 0"/>
    <inertial>
      <origin xyz="0 0 0" rpy="0 0 0"/>
      <mass value="1e-9"/>
      <inertia ixx="0" ixy="0" ixz="0" iyy="0" iyz="0" izz="0"/>
    </inertial>
  </link>
  <joint name="closing_5_1_frame" type="fixed">
    <origin xyz="-0.023093 2.77556e-17 -0.000220061" rpy="-3.5922e-15 -0.0190581 -1.36686e-16"/>
    <parent link="platform"/>
    <child link="closing_5_1"/>
    <axis xyz="0 0 0"/>
  </joint>
  <!-- Frame head (dummy link + fixed joint) -->
  <link name="head">
    <origin xyz="0 0 0" rpy="0 -0 0"/>
    <inertial>
      <origin xyz="0 0 0" rpy="0 0 0"/>
      <mass value="1e-9"/>
      <inertia ixx="0" ixy="0" ixz="0" iyy="0" iyz="0" izz="0"/>
    </inertial>
  </link>
  <joint name="head_frame" type="fixed">
    <origin xyz="-0.0117248 0.0122324 0.0186073" rpy="-0.463603 0.263312 -2.67791"/>
    <parent link="platform"/>
    <child link="head"/>
    <axis xyz="0 0 0"/>
  </joint>
  <!-- Link pp00672_antenna_mic_a1 -->
  <link name="pp00672_antenna_mic_a1">
    <inertial>
      <origin xyz="-0.0118437 0.0164131 -0.0243813" rpy="0 0 0"/>
      <mass value="0.0202419"/>
      <inertia ixx="3.22006e-05" ixy="1.40013e-05" ixz="-1.0829e-05" iyy="2.29008e-05" iyz="1.50069e-05" izz="3.09616e-05"/>
    </inertial>
    <!-- Part pp00673_antenna_sphere_a1 -->
    <visual>
      <origin xyz="-0.0798952 0.110719 -0.0971912" rpy="3.14159 -1.01229 2.19587"/>
      <geometry>
        <mesh filename="package://assets/pp00673_antenna_sphere_a1.stl"/>
      </geometry>
      <material name="pp00673_antenna_sphere_a1_material">
        <color rgba="0.901961 0.901961 0.901961 1.0"/>
      </material>
    </visual>
    <collision>
      <origin xyz="-0.0798952 0.110719 -0.0971912" rpy="3.14159 -1.01229 2.19587"/>
      <geometry>
        <mesh filename="package://assets/pp00673_antenna_sphere_a1.stl"/>
      </geometry>
    </collision>
    <!-- Part pp00672_antenna_mic_a1 -->
    <visual>
      <origin xyz="-0.0780354 0.108142 -0.0952052" rpy="3.14159 -1.01229 2.19587"/>
      <geometry>
        <mesh filename="package://assets/pp00672_antenna_mic_a1.stl"/>
      </geometry>
      <material name="pp00672_antenna_mic_a1_material">
        <color rgba="0.262745 0.282353 0.301961 1.0"/>
      </material>
    </visual>
    <collision>
      <origin xyz="-0.0780354 0.108142 -0.0952052" rpy="3.14159 -1.01229 2.19587"/>
      <geometry>
        <mesh filename="package://assets/pp00672_antenna_mic_a1.stl"/>
      </geometry>
    </collision>
  </link>
  <!-- Joint from platform to pp00672_antenna_mic_a1 -->
  <joint name="left_antenna" type="revolute">
    <origin xyz="0.035159 -0.0622228 0.0749453" rpy="2.08187 1.01498 -1.71429"/>
    <parent link="platform"/>
    <child link="pp00672_antenna_mic_a1"/>
    <axis xyz="0 0 1"/>
    <limit effort="10" velocity="10" lower="-3.141592653589793" upper="3.141592653589793"/>
  </joint>
  <!-- Link pp00672_antenna_mic_a1_2 -->
  <link name="pp00672_antenna_mic_a1_2">
    <inertial>
      <origin xyz="0.0115338 0.0166324 -0.0243813" rpy="0 0 0"/>
      <mass value="0.0202419"/>
      <inertia ixx="3.27223e-05" ixy="-1.38171e-05" ixz="1.05456e-05" iyy="2.2379e-05" iyz="1.52073e-05" izz="3.09616e-05"/>
    </inertial>
    <!-- Part pp00672_antenna_mic_a1_2 -->
    <visual>
      <origin xyz="0.0759936 0.109586 -0.0952052" rpy="3.14159 -1.01229 0.964474"/>
      <geometry>
        <mesh filename="package://assets/pp00672_antenna_mic_a1.stl"/>
      </geometry>
      <material name="pp00672_antenna_mic_a1_2_material">
        <color rgba="0.262745 0.282353 0.301961 1.0"/>
      </material>
    </visual>
    <collision>
      <origin xyz="0.0759936 0.109586 -0.0952052" rpy="3.14159 -1.01229 0.964474"/>
      <geometry>
        <mesh filename="package://assets/pp00672_antenna_mic_a1.stl"/>
      </geometry>
    </collision>
    <!-- Part pp00673_antenna_sphere_a1_2 -->
    <visual>
      <origin xyz="0.0778047 0.112198 -0.0971912" rpy="3.14159 -1.01229 0.964474"/>
      <geometry>
        <mesh filename="package://assets/pp00673_antenna_sphere_a1.stl"/>
      </geometry>
      <material name="pp00673_antenna_sphere_a1_2_material">
        <color rgba="0.901961 0.901961 0.901961 1.0"/>
      </material>
    </visual>
    <collision>
      <origin xyz="0.0778047 0.112198 -0.0971912" rpy="3.14159 -1.01229 0.964474"/>
      <geometry>
        <mesh filename="package://assets/pp00673_antenna_sphere_a1.stl"/>
      </geometry>
    </collision>
  </link>
  <!-- Joint from platform to pp00672_antenna_mic_a1_2 -->
  <joint name="right_antenna" type="revolute">
    <origin xyz="-0.0202961 0.0200517 0.122439" rpy="2.64924 -0.230354 -0.605094"/>
    <parent link="platform"/>
    <child link="pp00672_antenna_mic_a1_2"/>
    <axis xyz="0 0 1"/>
    <limit effort="10" velocity="10" lower="-3.141592653589793" upper="3.141592653589793"/>
  </joint>
  <!-- Joint from passive_7_link_y to platform -->
  <joint name="passive_7_z" type="revolute">
    <origin xyz="3.46945e-18 -1.38778e-17 -1.38778e-17" rpy="-1.3621e-17 -3.08255e-17 -6.96528e-17"/>
    <parent link="passive_7_link_y"/>
    <child link="platform"/>
    <axis xyz="0 0 1"/>
    <limit effort="10" velocity="10" lower="-3.141592653589793" upper="3.141592653589793"/>
  </joint>
  <!-- Joint from passive_7_link_x to passive_7_link_y -->
  <joint name="passive_7_y" type="revolute">
    <origin xyz="3.46945e-18 -1.38778e-17 -1.38778e-17" rpy="-1.3621e-17 -3.08255e-17 -6.96528e-17"/>
    <parent link="passive_7_link_x"/>
    <child link="passive_7_link_y"/>
    <axis xyz="0 1 0"/>
    <limit effort="10" velocity="10" lower="-3.141592653589793" upper="3.141592653589793"/>
  </joint>
  <!-- Joint from 10mm_ball_4 to passive_7_link_x -->
  <joint name="passive_7_x" type="revolute">
    <origin xyz="7.63278e-17 4.16334e-17 0.0996012" rpy="-0.0563544 -0.0277816 0.113755"/>
    <parent link="10mm_ball_4"/>
    <child link="passive_7_link_x"/>
    <axis xyz="1 0 0"/>
    <limit effort="10" velocity="10" lower="-3.141592653589793" upper="3.141592653589793"/>
  </joint>
  <!-- Joint from passive_3_link_y to 10mm_ball_4 -->
  <joint name="passive_3_z" type="revolute">
    <origin xyz="-6.93889e-18 0 0" rpy="8.6686e-17 -5.53998e-17 3.69236e-17"/>
    <parent link="passive_3_link_y"/>
    <child link="10mm_ball_4"/>
    <axis xyz="0 0 1"/>
    <limit effort="10" velocity="10" lower="-3.141592653589793" upper="3.141592653589793"/>
  </joint>
  <!-- Joint from passive_3_link_x to passive_3_link_y -->
  <joint name="passive_3_y" type="revolute">
    <origin xyz="-6.93889e-18 0 0" rpy="8.6686e-17 -5.53998e-17 3.69236e-17"/>
    <parent link="passive_3_link_x"/>
    <child link="passive_3_link_y"/>
    <axis xyz="0 1 0"/>
    <limit effort="10" velocity="10" lower="-3.141592653589793" upper="3.141592653589793"/>
  </joint>
  <!-- Joint from left_arm_3 to passive_3_link_x -->
  <joint name="passive_3_x" type="revolute">
    <origin xyz="-0.038 -1.56125e-16 0.00384958" rpy="1.68969 1.09636 0.138717"/>
    <parent link="left_arm_3"/>
    <child link="passive_3_link_x"/>
    <axis xyz="1 0 0"/>
    <limit effort="10" velocity="10" lower="-3.141592653589793" upper="3.141592653589793"/>
  </joint>
  <!-- Joint from simplified_xl330 to left_arm_3 -->
  <joint name="5" type="revolute">
    <origin xyz="-0.00838053 0.0495175 0.0434241" rpy="-1.86731 0.37714 -2.73004"/>
    <parent link="simplified_xl330"/>
    <child link="left_arm_3"/>
    <axis xyz="0 0 1"/>
    <limit effort="10" velocity="10" lower="-3.141592653589793" upper="3.141592653589793"/>
  </joint>
  <!-- Link right_arm_3 -->
  <link name="right_arm_3">
    <inertial>
      <origin xyz="0.0267634 0.0046049 0.00174754" rpy="0 0 0"/>
      <mass value="0.00541129"/>
      <inertia ixx="1.47788e-07" ixy="-1.70926e-07" ixz="-1.92071e-07" iyy="1.39835e-06" iyz="-2.15256e-08" izz="1.40141e-06"/>
    </inertial>
    <!-- Part magnet_12 -->
    <visual>
      <origin xyz="0.038 -6.93889e-17 0.00384958" rpy="-1.5708 1.5708 0"/>
      <geometry>
        <mesh filename="package://assets/magnet.stl"/>
      </geometry>
      <material name="magnet_12_material">
        <color rgba="0.713725 0.760784 0.8 1.0"/>
      </material>
    </visual>
    <collision>
      <origin xyz="0.038 -6.93889e-17 0.00384958" rpy="-1.5708 1.5708 0"/>
      <geometry>
        <mesh filename="package://assets/magnet.stl"/>
      </geometry>
    </collision>
    <!-- Part right_arm_3 -->
    <visual>
      <origin xyz="-0.0175 -0.0120291 0.0464647" rpy="1.84591 -6.01005e-17 -4.86395e-17"/>
      <geometry>
        <mesh filename="package://assets/right_arm.stl"/>
      </geometry>
      <material name="right_arm_3_material">
        <color rgba="1 1 1 1.0"/>
      </material>
    </visual>
    <collision>
      <origin xyz="-0.0175 -0.0120291 0.0464647" rpy="1.84591 -6.01005e-17 -4.86395e-17"/>
      <geometry>
        <mesh filename="package://assets/right_arm.stl"/>
      </geometry>
    </collision>
  </link>
  <!-- Link passive_2_link_x -->
  <link name="passive_2_link_x">
    <inertial>
      <origin xyz="0 0 0" rpy="0 0 0"/>
      <mass value="1e-09"/>
      <inertia ixx="1e-09" ixy="0" ixz="0" iyy="1e-09" iyz="0" izz="1e-09"/>
    </inertial>
  </link>
  <!-- Link passive_2_link_y -->
  <link name="passive_2_link_y">
    <inertial>
      <origin xyz="0 0 0" rpy="0 0 0"/>
      <mass value="1e-09"/>
      <inertia ixx="1e-09" ixy="0" ixz="0" iyy="1e-09" iyz="0" izz="1e-09"/>
    </inertial>
  </link>
  <!-- Link 10mm_ball_5 -->
  <link name="10mm_ball_5">
    <inertial>
      <origin xyz="2.72071e-16 2.11526e-18 0.0498006" rpy="0 0 0"/>
      <mass value="0.0100726"/>
      <inertia ixx="2.05497e-05" ixy="-9.69819e-21" ixz="-9.57583e-20" iyy="2.05497e-05" iyz="-7.15797e-21" izz="9.05619e-08"/>
    </inertial>
    <!-- Part rod_6 -->
    <visual>
      <origin xyz="0.0444954 -0.0426152 0.0352861" rpy="0.275115 0.457035 -3.14159"/>
      <geometry>
        <mesh filename="package://assets/rod.stl"/>
      </geometry>
      <material name="rod_6_material">
        <color rgba="0.262745 0.282353 0.301961 1.0"/>
      </material>
    </visual>
    <collision>
      <origin xyz="0.0444954 -0.0426152 0.0352861" rpy="0.275115 0.457035 -3.14159"/>
      <geometry>
        <mesh filename="package://assets/rod.stl"/>
      </geometry>
    </collision>
    <!-- Part 10mm_ball_11 -->
    <visual>
      <origin xyz="5.27356e-16 3.46945e-18 0.0996012" rpy="-1.01567e-14 -8.6843e-16 -3.14159"/>
      <geometry>
        <mesh filename="package://assets/10mm_ball.stl"/>
      </geometry>
      <material name="10mm_ball_11_material">
        <color rgba="0.713725 0.760784 0.8 1.0"/>
      </material>
    </visual>
    <collision>
      <origin xyz="5.27356e-16 3.46945e-18 0.0996012" rpy="-1.01567e-14 -8.6843e-16 -3.14159"/>
      <geometry>
        <mesh filename="package://assets/10mm_ball.stl"/>
      </geometry>
    </collision>
    <!-- Part 10mm_ball_12 -->
    <visual>
      <origin xyz="1.38778e-17 3.46945e-18 0" rpy="-3.14159 -4.04313e-17 -1.04784e-17"/>
      <geometry>
        <mesh filename="package://assets/10mm_ball.stl"/>
      </geometry>
      <material name="10mm_ball_12_material">
        <color rgba="0.713725 0.760784 0.8 1.0"/>
      </material>
    </visual>
    <collision>
      <origin xyz="1.38778e-17 3.46945e-18 0" rpy="-3.14159 -4.04313e-17 -1.04784e-17"/>
      <geometry>
        <mesh filename="package://assets/10mm_ball.stl"/>
      </geometry>
    </collision>
  </link>
  <!-- Frame closing_1_2 (dummy link + fixed joint) -->
  <link name="closing_1_2">
    <origin xyz="0 0 0" rpy="0 -0 0"/>
    <inertial>
      <origin xyz="0 0 0" rpy="0 0 0"/>
      <mass value="1e-9"/>
      <inertia ixx="0" ixy="0" ixz="0" iyy="0" iyz="0" izz="0"/>
    </inertial>
  </link>
  <joint name="closing_1_2_frame" type="fixed">
    <origin xyz="5.27356e-16 3.46945e-18 0.0996012" rpy="1.01567e-14 8.6843e-16 5.16933e-16"/>
    <parent link="10mm_ball_5"/>
    <child link="closing_1_2"/>
    <axis xyz="0 0 0"/>
  </joint>
  <!-- Joint from passive_2_link_y to 10mm_ball_5 -->
  <joint name="passive_2_z" type="revolute">
    <origin xyz="1.38778e-17 3.46945e-18 0" rpy="2.2995e-17 -4.04313e-17 -1.04784e-17"/>
    <parent link="passive_2_link_y"/>
    <child link="10mm_ball_5"/>
    <axis xyz="0 0 1"/>
    <limit effort="10" velocity="10" lower="-3.141592653589793" upper="3.141592653589793"/>
  </joint>
  <!-- Joint from passive_2_link_x to passive_2_link_y -->
  <joint name="passive_2_y" type="revolute">
    <origin xyz="1.38778e-17 3.46945e-18 0" rpy="2.2995e-17 -4.04313e-17 -1.04784e-17"/>
    <parent link="passive_2_link_x"/>
    <child link="passive_2_link_y"/>
    <axis xyz="0 1 0"/>
    <limit effort="10" velocity="10" lower="-3.141592653589793" upper="3.141592653589793"/>
  </joint>
  <!-- Joint from right_arm_3 to passive_2_link_x -->
  <joint name="passive_2_x" type="revolute">
    <origin xyz="0.038 -3.19189e-16 0.00384958" rpy="1.67139 1.0009 0.0518494"/>
    <parent link="right_arm_3"/>
    <child link="passive_2_link_x"/>
    <axis xyz="1 0 0"/>
    <limit effort="10" velocity="10" lower="-3.141592653589793" upper="3.141592653589793"/>
  </joint>
  <!-- Joint from simplified_xl330 to right_arm_3 -->
  <joint name="6" type="revolute">
    <origin xyz="-0.0386913 0.0320172 0.0434252" rpy="-1.86732 -0.377203 -2.50593"/>
    <parent link="simplified_xl330"/>
    <child link="right_arm_3"/>
    <axis xyz="0 0 1"/>
    <limit effort="10" velocity="10" lower="-3.141592653589793" upper="3.141592653589793"/>
  </joint>
</robot>
