<?xml version="1.0" ?>
<!-- Generated using onshape-to-robot -->
<!-- Onshape https://cad.onshape.com/documents/e305b26a84339af20c593973/w/9fd8829121bfdcf40799413b/e/333e72319d1d07cd9b78e76b -->
<mujoco model="stewart">
  <compiler angle="radian" meshdir="assets" autolimits="true"/>
  <default>
    <default class="stewart">
      <joint frictionloss="0.1" armature="0.005"/>
      <position kp="50" dampratio="1"/>
      <default class="visual">
        <geom type="mesh" contype="0" conaffinity="0" group="2"/>
      </default>
      <default class="collision">
        <geom group="3"/>
      </default>
    </default>
  </default>
  <!-- Additional additional.xml -->
  <contact>
    <!-- <exclude name="exclude0" body1="torso" body2="sts32155"/> -->
  </contact>
  <default>
    <equality solref="0.002 1" solimp="0.99 0.999 0.0005 0.5 2"/>
  </default>
  <worldbody>
    <!-- Link simplified_xl330 -->
    <body name="simplified_xl330" pos="0 0 0" quat="1 0 0 0" childclass="stewart">
      <inertial pos="2.83208e-14 2.6921e-07 0.0267776" mass="0.180117" fullinertia="0.000167561 0.000167556 0.00025142 6.53996e-16 5.95475e-16 -6.80064e-10"/>
      <!-- Part base_side -->
      <geom type="mesh" class="visual" pos="0 0 0.0426353" quat="1 -1.66533e-16 -1.11022e-16 -0" mesh="base_side" material="base_side_material"/>
      <!-- Part base_side_2 -->
      <geom type="mesh" class="visual" pos="8.91654e-07 1.08255e-06 0.0426361" quat="0.500004 -1.36248e-05 -7.86628e-06 -0.866023" mesh="base_side" material="base_side_material"/>
      <!-- Part base_top -->
      <geom type="mesh" class="visual" pos="0 0 0.0426353" quat="1 -1.66533e-16 -1.11022e-16 -0" mesh="base_top" material="base_top_material"/>
      <!-- Part base_side_3 -->
      <geom type="mesh" class="visual" pos="-8.91654e-07 1.08255e-06 0.0426361" quat="0.500004 -1.36248e-05 7.86628e-06 0.866023" mesh="base_side" material="base_side_material"/>
      <!-- Part base_bot -->
      <geom type="mesh" class="visual" pos="0 0 0.0426353" quat="1 0 0 0" mesh="base_bot" material="base_bot_material"/>
      <geom type="mesh" class="collision" pos="0 0 0.0426353" quat="1 0 0 0" mesh="base_bot" material="base_bot_material"/>
      <!-- Part simplified_xl330 -->
      <geom type="mesh" class="visual" pos="0.0105418 0.0296086 0.0296924" quat="0.256325 0.397885 0.453716 0.755067" mesh="simplified_xl330" material="simplified_xl330_material"/>
      <!-- Part simplified_xl330_2 -->
      <geom type="mesh" class="visual" pos="-0.0105418 0.0296086 0.0296924" quat="0.256325 0.397885 -0.453716 -0.755067" mesh="simplified_xl330" material="simplified_xl330_material"/>
      <!-- Part simplified_xl330_3 -->
      <geom type="mesh" class="visual" pos="-0.0309116 -0.00567367 0.0296936" quat="0.525765 0.193968 -0.571443 -0.5995" mesh="simplified_xl330" material="simplified_xl330_material"/>
      <!-- Part simplified_xl330_4 -->
      <geom type="mesh" class="visual" pos="0.0203701 -0.0239338 0.0296922" quat="0.782067 0.591871 -0.11773 0.155563" mesh="simplified_xl330" material="simplified_xl330_material"/>
      <!-- Part simplified_xl330_5 -->
      <geom type="mesh" class="visual" pos="-0.0203701 -0.0239338 0.0296922" quat="0.782067 0.591871 0.11773 -0.155563" mesh="simplified_xl330" material="simplified_xl330_material"/>
      <!-- Part simplified_xl330_6 -->
      <geom type="mesh" class="visual" pos="0.0309116 -0.00567367 0.0296936" quat="0.525765 0.193968 0.571443 0.5995" mesh="simplified_xl330" material="simplified_xl330_material"/>
      <!-- Link right_arm -->
      <body name="right_arm" pos="0.0175 -0.0470737 0.0434238" quat="0.591871 -0.782067 -0.155563 -0.11773">
        <!-- Joint from simplified_xl330 to right_arm -->
        <joint axis="0 0 1" name="1" type="hinge"/>
        <inertial pos="0.0267634 0.0046049 0.00174754" mass="0.00541129" fullinertia="1.47788e-07 1.39835e-06 1.40141e-06 -1.70926e-07 -1.92071e-07 -2.15256e-08"/>
        <!-- Part magnet -->
        <geom type="mesh" class="visual" pos="0.038 -1.04083e-17 0.00384958" quat="1.11022e-15 1.63036e-15 -0.707107 -0.707107" mesh="magnet" material="magnet_material"/>
        <!-- Part right_arm -->
        <geom type="mesh" class="visual" pos="-0.0175 -0.0120291 0.0464647" quat="0.603466 0.797389 -0 3.52769e-17" mesh="right_arm" material="right_arm_material"/>
        <!-- Link 10mm_ball -->
        <body name="10mm_ball" pos="0.038 5.20417e-17 0.00384958" quat="0.0176239 -0.00526661 -0.725942 0.68751">
          <!-- Joint from right_arm to 10mm_ball -->
          <joint axis="0 0 1" name="passive_6" type="ball"/>
          <inertial pos="-1.28241e-15 2.73146e-18 0.0498006" mass="0.0100726" fullinertia="2.05497e-05 2.05497e-05 9.05619e-08 1.48358e-20 4.80669e-19 7.51213e-21"/>
          <!-- Part rod -->
          <geom type="mesh" class="visual" pos="0.0444954 -0.0426152 0.0352861" quat="0.0310632 -0.224394 0.133559 0.964803" mesh="rod" material="rod_material"/>
          <!-- Part 10mm_ball -->
          <geom type="mesh" class="visual" pos="0 0 0" quat="0 1 0 0" mesh="10mm_ball" material="10mm_ball_material"/>
          <!-- Part 10mm_ball_2 -->
          <geom type="mesh" class="visual" pos="-2.58127e-15 0 0.0996012" quat="1.8735e-15 -6.87745e-15 -1.33227e-15 1" mesh="10mm_ball" material="10mm_ball_material"/>
          <!-- Frame closing_3_2 -->
          <site group="3" name="closing_3_2" pos="-2.58127e-15 0 0.0996012" quat="1 9.59026e-16 -6.52256e-15 -1.90126e-15"/>
        </body>
      </body>
      <!-- Link left_arm -->
      <body name="left_arm" pos="-0.0175 -0.0470737 0.0434238" quat="0.591871 -0.782067 0.155563 0.11773">
        <!-- Joint from simplified_xl330 to left_arm -->
        <joint axis="0 0 1" name="2" type="hinge"/>
        <inertial pos="-0.0267634 0.0046049 0.00174754" mass="0.00541129" fullinertia="1.47788e-07 1.39835e-06 1.40141e-06 1.70926e-07 1.92071e-07 -2.15256e-08"/>
        <!-- Part magnet_2 -->
        <geom type="mesh" class="visual" pos="-0.038 6.93889e-18 0.00384958" quat="8.32667e-16 2.51143e-16 0.707107 0.707107" mesh="magnet" material="magnet_material"/>
        <!-- Part left_arm -->
        <geom type="mesh" class="visual" pos="0.0175 -0.0120291 0.0464647" quat="0.603466 0.797389 -0 3.59607e-18" mesh="left_arm" material="left_arm_material"/>
        <!-- Link rod -->
        <body name="rod" pos="-0.038 6.93889e-18 0.00384958" quat="2.35922e-16 -9.32245e-16 -0.707107 0.707107">
          <!-- Joint from left_arm to rod -->
          <joint axis="0 0 1" name="passive_1" type="ball"/>
          <inertial pos="-0.00163493 0.00269119 0.049701" mass="0.0100726" fullinertia="2.05276e-05 2.04899e-05 1.72358e-07 3.62962e-08 6.70317e-07 -1.10338e-06"/>
          <!-- Part rod_2 -->
          <geom type="mesh" class="visual" pos="0.0218058 -0.0551349 0.0390595" quat="0.230974 -0.212869 0.199178 0.928259" mesh="rod" material="rod_material"/>
          <!-- Part 10mm_ball_3 -->
          <geom type="mesh" class="visual" pos="-0.00326986 0.00538239 0.0994019" quat="0.210274 -0.0217426 0.0229732 0.977131" mesh="10mm_ball" material="10mm_ball_material"/>
          <!-- Part 10mm_ball_4 -->
          <geom type="mesh" class="visual" pos="0 1.17961e-16 9.36751e-17" quat="0.0229732 0.977131 -0.210274 0.0217426" mesh="10mm_ball" material="10mm_ball_material"/>
          <!-- Frame closing_2_1 -->
          <site group="3" name="closing_2_1" pos="-0.00326986 0.00538239 0.0994019" quat="0.0217426 0.210274 0.977131 -0.0229732"/>
        </body>
      </body>
      <!-- Link left_arm_2 -->
      <body name="left_arm_2" pos="-0.0320165 0.0386931 0.0434241" quat="0.397885 -0.256325 0.755067 -0.453716">
        <!-- Joint from simplified_xl330 to left_arm_2 -->
        <joint axis="0 0 1" name="3" type="hinge"/>
        <inertial pos="-0.0267634 0.0046049 0.00174754" mass="0.00541129" fullinertia="1.47788e-07 1.39835e-06 1.40141e-06 1.70926e-07 1.92071e-07 -2.15256e-08"/>
        <!-- Part left_arm_2 -->
        <geom type="mesh" class="visual" pos="0.0175 -0.0120291 0.0464647" quat="0.603466 0.797389 -0 -3.60205e-17" mesh="left_arm" material="left_arm_material"/>
        <!-- Part magnet_3 -->
        <geom type="mesh" class="visual" pos="-0.038 -4.85723e-17 0.00384958" quat="0.5 -0.5 0.5 0.5" mesh="magnet" material="magnet_material"/>
        <!-- Link 10mm_ball_2 -->
        <body name="10mm_ball_2" pos="-0.038 -4.3715e-16 0.00384958" quat="0.494717 0.50545 0.521167 -0.477661">
          <!-- Joint from left_arm_2 to 10mm_ball_2 -->
          <joint axis="0 0 1" name="passive_3" type="ball"/>
          <inertial pos="3.8399e-16 1.52472e-17 0.0498006" mass="0.0100726" fullinertia="2.05497e-05 2.05497e-05 9.05619e-08 1.05728e-20 -1.41991e-19 -8.02071e-21"/>
          <!-- Part rod_3 -->
          <geom type="mesh" class="visual" pos="0.0444954 -0.0426152 0.0352861" quat="0.0310632 -0.224394 0.133559 0.964803" mesh="rod" material="rod_material"/>
          <!-- Part 10mm_ball_5 -->
          <geom type="mesh" class="visual" pos="0 1.38778e-17 0" quat="6.06511e-18 -1 -5.21203e-17 -7.2232e-18" mesh="10mm_ball" material="10mm_ball_material"/>
          <!-- Part 10mm_ball_6 -->
          <geom type="mesh" class="visual" pos="7.63278e-16 1.38778e-17 0.0996012" quat="1.66533e-16 3.27077e-15 2.55351e-15 -1" mesh="10mm_ball" material="10mm_ball_material"/>
          <!-- Link platform -->
          <body name="platform" pos="8.95117e-16 -2.77556e-17 0.0996012" quat="0.957441 -0.0229911 -0.021396 0.286914">
            <!-- Joint from 10mm_ball_2 to platform -->
            <joint axis="0 0 1" name="passive_7" type="ball"/>
            <inertial pos="-0.0116867 0.0145692 0.0146036" mass="0.0270567" fullinertia="6.19961e-06 7.694e-06 1.05868e-05 2.44042e-08 -4.18107e-08 -2.56095e-06"/>
            <!-- Part magnet_4 -->
            <geom type="mesh" class="visual" pos="-1.73472e-18 1.38778e-17 1.38778e-17" quat="1 0 -1.11022e-16 -6.93889e-18" mesh="magnet" material="magnet_material"/>
            <!-- Part magnet_5 -->
            <geom type="mesh" class="visual" pos="-0.0347355 0.0172732 0.00975103" quat="0.895121 0.388759 0.198717 0.0902002" mesh="magnet" material="magnet_material"/>
            <!-- Part magnet_6 -->
            <geom type="mesh" class="visual" pos="0.0114504 0.0172732 0.0101912" quat="0.893187 0.389601 -0.207238 -0.0864916" mesh="magnet" material="magnet_material"/>
            <!-- Part platform -->
            <geom type="mesh" class="visual" pos="-0.0109346 0.0606327 -0.0643152" quat="0.001244 0.00459924 0.261093 -0.965302" mesh="platform" material="platform_material"/>
            <!-- Part magnet_7 -->
            <geom type="mesh" class="visual" pos="-0.000192133 0.0345463 0.0201622" quat="0.895461 0.38125 -0.212769 -0.0867587" mesh="magnet" material="magnet_material"/>
            <!-- Part magnet_8 -->
            <geom type="mesh" class="visual" pos="-0.0232851 0.0345463 0.0199422" quat="0.897448 0.380406 0.204226 0.0903877" mesh="magnet" material="magnet_material"/>
            <!-- Part magnet_9 -->
            <geom type="mesh" class="visual" pos="-0.023093 1.38778e-17 -0.000220061" quat="0.999955 5.85147e-17 -0.00952892 -2.70617e-16" mesh="magnet" material="magnet_material"/>
            <!-- Part injection_small_lens -->
            <geom type="mesh" class="visual" pos="-0.0347805 -0.0602959 0.0362659" quat="0.836598 0.228413 0.126564 -0.481574" mesh="injection_small_lens" material="injection_small_lens_material"/>
            <!-- Part small_lens_30mm -->
            <geom type="mesh" class="visual" pos="-0.0346078 -0.0602096 0.0363179" quat="0.430052 0.753076 -0.25103 -0.430018" mesh="small_lens_30mm" material="small_lens_30mm_material"/>
            <!-- Part large_lens_42mm -->
            <geom type="mesh" class="visual" pos="-0.0656467 -0.00572759 0.0678223" quat="0.430052 0.753076 -0.25103 -0.430018" mesh="large_lens_42mm" material="large_lens_42mm_material"/>
            <!-- Part injection_big_lens -->
            <geom type="mesh" class="visual" pos="-0.0680648 -0.00693671 0.0670935" quat="0.836598 0.228413 0.126564 -0.481574" mesh="injection_big_lens" material="injection_big_lens_material"/>
            <!-- Part reachy_mini_head -->
            <geom type="mesh" class="visual" pos="-0.0121528 -0.0139797 0.0635154" quat="0.836598 0.228413 0.126564 -0.481574" mesh="reachy_mini_head" material="reachy_mini_head_material"/>
            <!-- Frame closing_1_1 -->
            <site group="3" name="closing_1_1" pos="0.0114504 0.0172732 0.0101912" quat="0.893187 0.389601 -0.207238 -0.0864916"/>
            <!-- Frame closing_2_2 -->
            <site group="3" name="closing_2_2" pos="-0.000192133 0.0345463 0.0201622" quat="0.212769 0.0867587 0.895461 0.38125"/>
            <!-- Frame closing_3_1 -->
            <site group="3" name="closing_3_1" pos="-0.0232851 0.0345463 0.0199422" quat="0.897448 0.380406 0.204226 0.0903877"/>
            <!-- Frame closing_4_2 -->
            <site group="3" name="closing_4_2" pos="-0.0347355 0.0172732 0.00975103" quat="0.198717 0.0902002 -0.895121 -0.388759"/>
            <!-- Frame closing_5_1 -->
            <site group="3" name="closing_5_1" pos="-0.023093 1.38778e-17 -0.000220061" quat="0.999955 5.85147e-17 -0.00952892 -2.70617e-16"/>
          </body>
        </body>
      </body>
      <!-- Link right_arm_2 -->
      <body name="right_arm_2" pos="-0.0495162 0.00838209 0.0434252" quat="0.193968 -0.525765 0.5995 -0.571443">
        <!-- Joint from simplified_xl330 to right_arm_2 -->
        <joint axis="0 0 1" name="4" type="hinge"/>
        <inertial pos="0.0267634 0.0046049 0.00174754" mass="0.00541129" fullinertia="1.47788e-07 1.39835e-06 1.40141e-06 -1.70926e-07 -1.92071e-07 -2.15256e-08"/>
        <!-- Part magnet_10 -->
        <geom type="mesh" class="visual" pos="0.038 -1.04083e-17 0.00384958" quat="0.5 -0.5 0.5 0.5" mesh="magnet" material="magnet_material"/>
        <!-- Part right_arm_2 -->
        <geom type="mesh" class="visual" pos="-0.0175 -0.0120291 0.0464647" quat="0.603466 0.797389 0 2.51148e-17" mesh="right_arm" material="right_arm_material"/>
        <!-- Link 10mm_ball_3 -->
        <body name="10mm_ball_3" pos="0.038 -1.04083e-17 0.00384958" quat="0.499472 0.543452 0.481405 -0.472691">
          <!-- Joint from right_arm_2 to 10mm_ball_3 -->
          <joint axis="0 0 1" name="passive_2" type="ball"/>
          <inertial pos="-1.64558e-17 -3.92218e-18 0.0498006" mass="0.0100726" fullinertia="2.05497e-05 2.05497e-05 9.05619e-08 -3.19214e-22 6.557e-21 1.16646e-21"/>
          <!-- Part rod_4 -->
          <geom type="mesh" class="visual" pos="0.0444954 -0.0426152 0.0352861" quat="0.0310632 -0.224394 0.133559 0.964803" mesh="rod" material="rod_material"/>
          <!-- Part 10mm_ball_7 -->
          <geom type="mesh" class="visual" pos="-3.46945e-17 -6.93889e-18 0.0996012" quat="2.77556e-17 1.87924e-17 3.33067e-16 -1" mesh="10mm_ball" material="10mm_ball_material"/>
          <!-- Part 10mm_ball_8 -->
          <geom type="mesh" class="visual" pos="0 0 6.93889e-18" quat="0 1 0 0" mesh="10mm_ball" material="10mm_ball_material"/>
          <!-- Frame closing_1_2 -->
          <site group="3" name="closing_1_2" pos="-3.46945e-17 -6.93889e-18 0.0996012" quat="1 0 -2.63678e-16 1.45717e-16"/>
        </body>
      </body>
      <!-- Link left_arm_3 -->
      <body name="left_arm_3" pos="0.0495162 0.00838209 0.0434252" quat="0.193968 -0.525765 -0.5995 0.571443">
        <!-- Joint from simplified_xl330 to left_arm_3 -->
        <joint axis="0 0 1" name="5" type="hinge"/>
        <inertial pos="-0.0267634 0.0046049 0.00174754" mass="0.00541129" fullinertia="1.47788e-07 1.39835e-06 1.40141e-06 1.70926e-07 1.92071e-07 -2.15256e-08"/>
        <!-- Part magnet_11 -->
        <geom type="mesh" class="visual" pos="-0.038 -3.46945e-18 0.00384958" quat="0.5 -0.5 -0.5 -0.5" mesh="magnet" material="magnet_material"/>
        <!-- Part left_arm_3 -->
        <geom type="mesh" class="visual" pos="0.0175 -0.0120291 0.0464647" quat="0.603466 0.797389 -0 5.59666e-19" mesh="left_arm" material="left_arm_material"/>
        <!-- Link 10mm_ball_4 -->
        <body name="10mm_ball_4" pos="-0.038 -1.73472e-17 0.00384958" quat="0.606824 0.651541 -0.320288 0.323533">
          <!-- Joint from left_arm_3 to 10mm_ball_4 -->
          <joint axis="0 0 1" name="passive_5" type="ball"/>
          <inertial pos="-7.63898e-17 4.30648e-18 0.0498006" mass="0.0100726" fullinertia="2.05497e-05 2.05497e-05 9.05619e-08 1.56664e-22 3.85622e-20 -1.02356e-22"/>
          <!-- Part rod_5 -->
          <geom type="mesh" class="visual" pos="0.0444954 -0.0426152 0.0352861" quat="0.0310632 -0.224394 0.133559 0.964803" mesh="rod" material="rod_material"/>
          <!-- Part 10mm_ball_9 -->
          <geom type="mesh" class="visual" pos="2.77556e-17 -3.46945e-18 -3.46945e-18" quat="0 1 0 0" mesh="10mm_ball" material="10mm_ball_material"/>
          <!-- Part 10mm_ball_10 -->
          <geom type="mesh" class="visual" pos="-1.80411e-16 1.38778e-17 0.0996012" quat="5.55112e-17 -1.60663e-16 6.38378e-16 1" mesh="10mm_ball" material="10mm_ball_material"/>
          <!-- Frame closing_4_1 -->
          <site group="3" name="closing_4_1" pos="-1.80411e-16 1.38778e-17 0.0996012" quat="0 -1.21575e-16 -1 6.66134e-16"/>
        </body>
      </body>
      <!-- Link right_arm_3 -->
      <body name="right_arm_3" pos="0.0320165 0.0386931 0.0434241" quat="0.397885 -0.256325 -0.755067 0.453716">
        <!-- Joint from simplified_xl330 to right_arm_3 -->
        <joint axis="0 0 1" name="6" type="hinge"/>
        <inertial pos="0.0267634 0.0046049 0.00174754" mass="0.00541129" fullinertia="1.47788e-07 1.39835e-06 1.40141e-06 -1.70926e-07 -1.92071e-07 -2.15256e-08"/>
        <!-- Part right_arm_3 -->
        <geom type="mesh" class="visual" pos="-0.0175 -0.0120291 0.0464647" quat="0.603466 0.797389 -0 -9.34157e-18" mesh="right_arm" material="right_arm_material"/>
        <!-- Part magnet_12 -->
        <geom type="mesh" class="visual" pos="0.038 -2.77556e-17 0.00384958" quat="0.707107 -0.707107 2.22045e-16 -6.37696e-17" mesh="magnet" material="magnet_material"/>
        <!-- Link 10mm_ball_5 -->
        <body name="10mm_ball_5" pos="0.038 -1.11022e-16 0.00384958" quat="0.687546 0.725951 -0.00943964 -0.0136456">
          <!-- Joint from right_arm_3 to 10mm_ball_5 -->
          <joint axis="0 0 1" name="passive_4" type="ball"/>
          <inertial pos="2.39589e-16 -1.58895e-18 0.0498006" mass="0.0100726" fullinertia="2.05497e-05 2.05497e-05 9.05619e-08 -1.15287e-21 -9.013e-20 -7.46992e-21"/>
          <!-- Part 10mm_ball_11 -->
          <geom type="mesh" class="visual" pos="0 -1.38778e-17 0" quat="0 1 0 0" mesh="10mm_ball" material="10mm_ball_material"/>
          <!-- Part 10mm_ball_12 -->
          <geom type="mesh" class="visual" pos="4.85723e-16 6.93889e-18 0.0996012" quat="0.707107 -4.40487e-15 2.33147e-15 -0.707107" mesh="10mm_ball" material="10mm_ball_material"/>
          <!-- Part rod_6 -->
          <geom type="mesh" class="visual" pos="0.0444954 -0.0426152 0.0352861" quat="0.0310632 -0.224394 0.133559 0.964803" mesh="rod" material="rod_material"/>
          <!-- Frame closing_5_2 -->
          <site group="3" name="closing_5_2" pos="4.85723e-16 6.93889e-18 0.0996012" quat="0.707107 2.25975e-15 4.55191e-15 0.707107"/>
        </body>
      </body>
    </body>
  </worldbody>
  <asset>
    <mesh file="injection_small_lens.stl"/>
    <mesh file="rod.stl"/>
    <mesh file="base_top.stl"/>
    <mesh file="right_arm.stl"/>
    <mesh file="10mm_ball.stl"/>
    <mesh file="platform.stl"/>
    <mesh file="simplified_xl330.stl"/>
    <mesh file="reachy_mini_head.stl"/>
    <mesh file="left_arm.stl"/>
    <mesh file="large_lens_42mm.stl"/>
    <mesh file="injection_big_lens.stl"/>
    <mesh file="base_bot.stl"/>
    <mesh file="small_lens_30mm.stl"/>
    <mesh file="magnet.stl"/>
    <mesh file="base_side.stl"/>
    <material name="base_side_material" rgba="1 1 1 1"/>
    <material name="base_top_material" rgba="0.615686 0.811765 0.929412 1"/>
    <material name="base_bot_material" rgba="0.85098 0.756863 0.866667 1"/>
    <material name="simplified_xl330_material" rgba="0.301961 0.301961 0.301961 1"/>
    <material name="magnet_material" rgba="0.713725 0.760784 0.8 1"/>
    <material name="right_arm_material" rgba="1 1 1 1"/>
    <material name="rod_material" rgba="0.262745 0.282353 0.301961 1"/>
    <material name="10mm_ball_material" rgba="0.713725 0.760784 0.8 1"/>
    <material name="left_arm_material" rgba="1 1 1 1"/>
    <material name="platform_material" rgba="1 1 1 1"/>
    <material name="injection_small_lens_material" rgba="0.25098 0.25098 0.25098 1"/>
    <material name="small_lens_30mm_material" rgba="0.439216 0.47451 0.501961 1"/>
    <material name="large_lens_42mm_material" rgba="0.439216 0.47451 0.501961 1"/>
    <material name="injection_big_lens_material" rgba="0.25098 0.25098 0.25098 1"/>
    <material name="reachy_mini_head_material" rgba="1 1 1 1"/>
  </asset>
  <actuator>
    <position class="stewart" name="1" joint="1"/>
    <position class="stewart" name="2" joint="2"/>
    <position class="stewart" name="3" joint="3"/>
    <position class="stewart" name="4" joint="4"/>
    <position class="stewart" name="5" joint="5"/>
    <position class="stewart" name="6" joint="6"/>
  </actuator>
  <equality>
    <connect site1="closing_1_1" site2="closing_1_2"/>
    <connect site1="closing_2_1" site2="closing_2_2"/>
    <connect site1="closing_3_1" site2="closing_3_2"/>
    <connect site1="closing_4_1" site2="closing_4_2"/>
    <connect site1="closing_5_1" site2="closing_5_2"/>
  </equality>
</mujoco>
