<?xml version="1.0"?>
<!-- Generated using onshape-to-robot -->
<!-- Onshape
https://cad.onshape.com/documents/7836ed39be931c6ece17e007/w/39d557f31a0ba179c9e7bd5b/e/c82436d68c7d00e142abc581 -->
<robot name="robot">
  <!-- Link body_foot_3dprint -->
  <link name="body_foot_3dprint">
    <inertial>
      <origin xyz="0.00290221 0.000112574 0.0132607" rpy="0 0 0"/>
      <mass value="0.0617881"/>
      <inertia ixx="6.91521e-05" ixy="-1.98794e-07" ixz="-4.91678e-08" iyy="6.07324e-05" iyz="-3.02441e-08"
        izz="0.000110345"/>
    </inertial>
    <!-- Part body_foot_3dprint -->
    <visual>
      <origin xyz="-2.45997e-07 6.93889e-18 0.2298" rpy="6.12323e-17 -2.07076e-30 1.5708"/>
      <geometry>
        <mesh filename="package://assets/body_foot_3dprint.stl"/>
      </geometry>
      <material name="body_foot_3dprint_material">
        <color rgba="0.301961 0.301961 0.301961 1"/>
      </material>
    </visual>
        <!-- Part dc15_a01_horn_dummy -->
    <visual>
      <origin xyz="-2.45997e-07 0 0.0413" rpy="-1.5708 6.01506e-30 -1.5708"/>
      <geometry>
        <mesh filename="package://assets/dc15_a01_horn_dummy.stl"/>
      </geometry>
      <material name="dc15_a01_horn_dummy_material">
        <color rgba="0.262745 0.282353 0.301961 1"/>
      </material>
    </visual>
        <!-- Part body_turning_3dprint -->
    <visual>
      <origin xyz="-2.45997e-07 6.93889e-18 0.2298" rpy="6.12323e-17 -2.91879e-28 1.5708"/>
      <geometry>
        <mesh filename="package://assets/body_turning_3dprint.stl"/>
      </geometry>
      <material name="body_turning_3dprint_material">
        <color rgba="0.301961 0.301961 0.301961 1"/>
      </material>
    </visual>
      </link>
  <!-- Link body_down_3dprint -->
  <link name="body_down_3dprint">
    <inertial>
      <origin xyz="2.19196e-06 -0.000620543 -0.0201687" rpy="0 0 0"/>
      <mass value="0.78209"/>
      <inertia ixx="0.00233791" ixy="-1.10376e-07" ixz="1.41892e-07" iyy="0.00224458" iyz="-4.46122e-05"
        izz="0.00254424"/>
    </inertial>
    <!-- Part body_down_3dprint -->
    <visual>
      <origin xyz="3.79972e-17 2.16005e-16 -0.195" rpy="3.14159 3.08149e-33 3.14159"/>
      <geometry>
        <mesh filename="package://assets/body_down_3dprint.stl"/>
      </geometry>
      <material name="body_down_3dprint_material">
        <color rgba="1 1 1 1"/>
      </material>
    </visual>
        <!-- Part stewart_tricap_3dprint -->
    <visual>
      <origin xyz="4.19282e-17 2.50834e-17 -0.195" rpy="-3.14159 -5.88663e-28 -3.14159"/>
      <geometry>
        <mesh filename="package://assets/stewart_tricap_3dprint.stl"/>
      </geometry>
      <material name="stewart_tricap_3dprint_material">
        <color rgba="0.301961 0.301961 0.301961 1"/>
      </material>
    </visual>
        <!-- Part 5w_speaker -->
    <visual>
      <origin xyz="-2.25375e-17 0.005 -0.0535833" rpy="-1.5708 -5.88589e-28 -3.14159"/>
      <geometry>
        <mesh filename="package://assets/5w_speaker.stl"/>
      </geometry>
      <material name="5w_speaker_material">
        <color rgba="0.196078 0.196078 0.196078 1"/>
      </material>
    </visual>
        <!-- Part bearing_85x110x13 -->
    <visual>
      <origin xyz="3.79972e-17 -1.20958e-17 0.0115" rpy="-1.5708 1.1046e-15 -1.5708"/>
      <geometry>
        <mesh filename="package://assets/bearing_85x110x13.stl"/>
      </geometry>
      <material name="bearing_85x110x13_material">
        <color rgba="0.768627 0.886275 0.952941 1"/>
      </material>
    </visual>
        <!-- Part body_top_3dprint -->
    <visual>
      <origin xyz="3.26346e-18 2.40368e-16 -0.195" rpy="3.14159 -6.05031e-28 3.14159"/>
      <geometry>
        <mesh filename="package://assets/body_top_3dprint.stl"/>
      </geometry>
      <material name="body_top_3dprint_material">
        <color rgba="1 1 1 1"/>
      </material>
    </visual>
        <!-- Part stewart_main_plate_3dprint -->
    <visual>
      <origin xyz="-3.83816e-26 2.15398e-16 -0.195" rpy="3.14159 3.08149e-33 3.14159"/>
      <geometry>
        <mesh filename="package://assets/stewart_main_plate_3dprint.stl"/>
      </geometry>
      <material name="stewart_main_plate_3dprint_material">
        <color rgba="0.301961 0.301961 0.301961 1"/>
      </material>
    </visual>
        <!-- Part phs_1_7x20_5_dc10_2 -->
    <visual>
      <origin xyz="-0.01 0.0501606 -0.0418333" rpy="-1.60914e-16 1.63452e-15 -3.14159"/>
      <geometry>
        <mesh filename="package://assets/phs_1_7x20_5_dc10_2.stl"/>
      </geometry>
      <material name="phs_1_7x20_5_dc10_2_material">
        <color rgba="0.262745 0.282353 0.301961 1"/>
      </material>
    </visual>
        <!-- Part dc15_a01_case_b_dummy -->
    <visual>
      <origin xyz="-0.01 0.0501606 -0.0418333" rpy="-1.60914e-16 1.63452e-15 -3.14159"/>
      <geometry>
        <mesh filename="package://assets/dc15_a01_case_b_dummy.stl"/>
      </geometry>
      <material name="dc15_a01_case_b_dummy_material">
        <color rgba="0.262745 0.282353 0.301961 1"/>
      </material>
    </visual>
        <!-- Part dc15_a01_case_m_dummy -->
    <visual>
      <origin xyz="-0.01 0.0501606 -0.0418333" rpy="-1.60914e-16 1.63452e-15 -3.14159"/>
      <geometry>
        <mesh filename="package://assets/dc15_a01_case_m_dummy.stl"/>
      </geometry>
      <material name="dc15_a01_case_m_dummy_material">
        <color rgba="0.262745 0.282353 0.301961 1"/>
      </material>
    </visual>
        <!-- Part dc15_a01_led_cap2_dummy -->
    <visual>
      <origin xyz="-0.01 0.0501606 -0.0418333" rpy="-1.60914e-16 1.63452e-15 -3.14159"/>
      <geometry>
        <mesh filename="package://assets/dc15_a01_led_cap2_dummy.stl"/>
      </geometry>
      <material name="dc15_a01_led_cap2_dummy_material">
        <color rgba="0.87451 0.447059 0.317647 1"/>
      </material>
    </visual>
        <!-- Part bts2_m2_6x8 -->
    <visual>
      <origin xyz="-0.01 0.0501606 -0.0418333" rpy="-1.60914e-16 1.63452e-15 -3.14159"/>
      <geometry>
        <mesh filename="package://assets/bts2_m2_6x8.stl"/>
      </geometry>
      <material name="bts2_m2_6x8_material">
        <color rgba="0.262745 0.282353 0.301961 1"/>
      </material>
    </visual>
        <!-- Part dc15_a01_case_f_dummy -->
    <visual>
      <origin xyz="-0.01 0.0501606 -0.0418333" rpy="-1.60914e-16 1.63452e-15 -3.14159"/>
      <geometry>
        <mesh filename="package://assets/dc15_a01_case_f_dummy.stl"/>
      </geometry>
      <material name="dc15_a01_case_f_dummy_material">
        <color rgba="0.262745 0.282353 0.301961 1"/>
      </material>
    </visual>
        <!-- Part b3b_eh_1 -->
    <visual>
      <origin xyz="-0.01 0.0501606 -0.0418333" rpy="-1.60914e-16 1.63452e-15 -3.14159"/>
      <geometry>
        <mesh filename="package://assets/b3b_eh_1.stl"/>
      </geometry>
      <material name="b3b_eh_1_material">
        <color rgba="0.262745 0.282353 0.301961 1"/>
      </material>
    </visual>
        <!-- Part b3b_eh -->
    <visual>
      <origin xyz="-0.01 0.0501606 -0.0418333" rpy="-1.60914e-16 1.63452e-15 -3.14159"/>
      <geometry>
        <mesh filename="package://assets/b3b_eh.stl"/>
      </geometry>
      <material name="b3b_eh_material">
        <color rgba="0.262745 0.282353 0.301961 1"/>
      </material>
    </visual>
        <!-- Part phs_1_7x20_5_dc10_3 -->
    <visual>
      <origin xyz="-0.01 0.0501606 -0.0418333" rpy="-1.60914e-16 1.63452e-15 -3.14159"/>
      <geometry>
        <mesh filename="package://assets/phs_1_7x20_5_dc10_3.stl"/>
      </geometry>
      <material name="phs_1_7x20_5_dc10_3_material">
        <color rgba="0.262745 0.282353 0.301961 1"/>
      </material>
    </visual>
        <!-- Part phs_1_7x20_5_dc10_1 -->
    <visual>
      <origin xyz="-0.01 0.0501606 -0.0418333" rpy="-1.60914e-16 1.63452e-15 -3.14159"/>
      <geometry>
        <mesh filename="package://assets/phs_1_7x20_5_dc10_1.stl"/>
      </geometry>
      <material name="phs_1_7x20_5_dc10_1_material">
        <color rgba="0.262745 0.282353 0.301961 1"/>
      </material>
    </visual>
        <!-- Part phs_1_7x20_5_dc10 -->
    <visual>
      <origin xyz="-0.01 0.0501606 -0.0418333" rpy="-1.60914e-16 1.63452e-15 -3.14159"/>
      <geometry>
        <mesh filename="package://assets/phs_1_7x20_5_dc10.stl"/>
      </geometry>
      <material name="phs_1_7x20_5_dc10_material">
        <color rgba="0.262745 0.282353 0.301961 1"/>
      </material>
    </visual>
        <!-- Part phs_1_7x20_5_dc10_2_2 -->
    <visual>
      <origin xyz="-0.0384404 -0.0337406 -0.0418333" rpy="1.49599e-15 2.59113e-15 -1.0472"/>
      <geometry>
        <mesh filename="package://assets/phs_1_7x20_5_dc10_2.stl"/>
      </geometry>
      <material name="phs_1_7x20_5_dc10_2_2_material">
        <color rgba="0.262745 0.282353 0.301961 1"/>
      </material>
    </visual>
        <!-- Part dc15_a01_case_b_dummy_2 -->
    <visual>
      <origin xyz="-0.0384404 -0.0337406 -0.0418333" rpy="1.49599e-15 2.59113e-15 -1.0472"/>
      <geometry>
        <mesh filename="package://assets/dc15_a01_case_b_dummy.stl"/>
      </geometry>
      <material name="dc15_a01_case_b_dummy_2_material">
        <color rgba="0.262745 0.282353 0.301961 1"/>
      </material>
    </visual>
        <!-- Part dc15_a01_case_m_dummy_2 -->
    <visual>
      <origin xyz="-0.0384404 -0.0337406 -0.0418333" rpy="1.49599e-15 2.59113e-15 -1.0472"/>
      <geometry>
        <mesh filename="package://assets/dc15_a01_case_m_dummy.stl"/>
      </geometry>
      <material name="dc15_a01_case_m_dummy_2_material">
        <color rgba="0.262745 0.282353 0.301961 1"/>
      </material>
    </visual>
        <!-- Part dc15_a01_led_cap2_dummy_2 -->
    <visual>
      <origin xyz="-0.0384404 -0.0337406 -0.0418333" rpy="1.49599e-15 2.59113e-15 -1.0472"/>
      <geometry>
        <mesh filename="package://assets/dc15_a01_led_cap2_dummy.stl"/>
      </geometry>
      <material name="dc15_a01_led_cap2_dummy_2_material">
        <color rgba="0.87451 0.447059 0.317647 1"/>
      </material>
    </visual>
        <!-- Part bts2_m2_6x8_2 -->
    <visual>
      <origin xyz="-0.0384404 -0.0337406 -0.0418333" rpy="1.49599e-15 2.59113e-15 -1.0472"/>
      <geometry>
        <mesh filename="package://assets/bts2_m2_6x8.stl"/>
      </geometry>
      <material name="bts2_m2_6x8_2_material">
        <color rgba="0.262745 0.282353 0.301961 1"/>
      </material>
    </visual>
        <!-- Part dc15_a01_case_f_dummy_2 -->
    <visual>
      <origin xyz="-0.0384404 -0.0337406 -0.0418333" rpy="1.49599e-15 2.59113e-15 -1.0472"/>
      <geometry>
        <mesh filename="package://assets/dc15_a01_case_f_dummy.stl"/>
      </geometry>
      <material name="dc15_a01_case_f_dummy_2_material">
        <color rgba="0.262745 0.282353 0.301961 1"/>
      </material>
    </visual>
        <!-- Part b3b_eh_1_2 -->
    <visual>
      <origin xyz="-0.0384404 -0.0337406 -0.0418333" rpy="1.49599e-15 2.59113e-15 -1.0472"/>
      <geometry>
        <mesh filename="package://assets/b3b_eh_1.stl"/>
      </geometry>
      <material name="b3b_eh_1_2_material">
        <color rgba="0.262745 0.282353 0.301961 1"/>
      </material>
    </visual>
        <!-- Part b3b_eh_2 -->
    <visual>
      <origin xyz="-0.0384404 -0.0337406 -0.0418333" rpy="1.49599e-15 2.59113e-15 -1.0472"/>
      <geometry>
        <mesh filename="package://assets/b3b_eh.stl"/>
      </geometry>
      <material name="b3b_eh_2_material">
        <color rgba="0.262745 0.282353 0.301961 1"/>
      </material>
    </visual>
        <!-- Part phs_1_7x20_5_dc10_3_2 -->
    <visual>
      <origin xyz="-0.0384404 -0.0337406 -0.0418333" rpy="1.49599e-15 2.59113e-15 -1.0472"/>
      <geometry>
        <mesh filename="package://assets/phs_1_7x20_5_dc10_3.stl"/>
      </geometry>
      <material name="phs_1_7x20_5_dc10_3_2_material">
        <color rgba="0.262745 0.282353 0.301961 1"/>
      </material>
    </visual>
        <!-- Part phs_1_7x20_5_dc10_1_2 -->
    <visual>
      <origin xyz="-0.0384404 -0.0337406 -0.0418333" rpy="1.49599e-15 2.59113e-15 -1.0472"/>
      <geometry>
        <mesh filename="package://assets/phs_1_7x20_5_dc10_1.stl"/>
      </geometry>
      <material name="phs_1_7x20_5_dc10_1_2_material">
        <color rgba="0.262745 0.282353 0.301961 1"/>
      </material>
    </visual>
        <!-- Part phs_1_7x20_5_dc10_2 -->
    <visual>
      <origin xyz="-0.0384404 -0.0337406 -0.0418333" rpy="1.49599e-15 2.59113e-15 -1.0472"/>
      <geometry>
        <mesh filename="package://assets/phs_1_7x20_5_dc10.stl"/>
      </geometry>
      <material name="phs_1_7x20_5_dc10_2_material">
        <color rgba="0.262745 0.282353 0.301961 1"/>
      </material>
    </visual>
        <!-- Part phs_1_7x20_5_dc10_2_3 -->
    <visual>
      <origin xyz="0 0 -0.0065" rpy="1.5708 3.30619e-45 9.81999e-32"/>
      <geometry>
        <mesh filename="package://assets/phs_1_7x20_5_dc10_2.stl"/>
      </geometry>
      <material name="phs_1_7x20_5_dc10_2_3_material">
        <color rgba="0.262745 0.282353 0.301961 1"/>
      </material>
    </visual>
        <!-- Part dc15_a01_case_b_dummy_3 -->
    <visual>
      <origin xyz="0 0 -0.0065" rpy="1.5708 3.30619e-45 9.81999e-32"/>
      <geometry>
        <mesh filename="package://assets/dc15_a01_case_b_dummy.stl"/>
      </geometry>
      <material name="dc15_a01_case_b_dummy_3_material">
        <color rgba="0.262745 0.282353 0.301961 1"/>
      </material>
    </visual>
        <!-- Part dc15_a01_case_m_dummy_3 -->
    <visual>
      <origin xyz="0 0 -0.0065" rpy="1.5708 3.30619e-45 9.81999e-32"/>
      <geometry>
        <mesh filename="package://assets/dc15_a01_case_m_dummy.stl"/>
      </geometry>
      <material name="dc15_a01_case_m_dummy_3_material">
        <color rgba="0.262745 0.282353 0.301961 1"/>
      </material>
    </visual>
        <!-- Part dc15_a01_led_cap2_dummy_3 -->
    <visual>
      <origin xyz="0 0 -0.0065" rpy="1.5708 3.30619e-45 9.81999e-32"/>
      <geometry>
        <mesh filename="package://assets/dc15_a01_led_cap2_dummy.stl"/>
      </geometry>
      <material name="dc15_a01_led_cap2_dummy_3_material">
        <color rgba="0.87451 0.447059 0.317647 1"/>
      </material>
    </visual>
        <!-- Part bts2_m2_6x8_3 -->
    <visual>
      <origin xyz="0 0 -0.0065" rpy="1.5708 3.30619e-45 9.81999e-32"/>
      <geometry>
        <mesh filename="package://assets/bts2_m2_6x8.stl"/>
      </geometry>
      <material name="bts2_m2_6x8_3_material">
        <color rgba="0.262745 0.282353 0.301961 1"/>
      </material>
    </visual>
        <!-- Part dc15_a01_case_f_dummy_3 -->
    <visual>
      <origin xyz="0 0 -0.0065" rpy="1.5708 3.30619e-45 9.81999e-32"/>
      <geometry>
        <mesh filename="package://assets/dc15_a01_case_f_dummy.stl"/>
      </geometry>
      <material name="dc15_a01_case_f_dummy_3_material">
        <color rgba="0.262745 0.282353 0.301961 1"/>
      </material>
    </visual>
        <!-- Part b3b_eh_1_3 -->
    <visual>
      <origin xyz="0 0 -0.0065" rpy="1.5708 3.30619e-45 9.81999e-32"/>
      <geometry>
        <mesh filename="package://assets/b3b_eh_1.stl"/>
      </geometry>
      <material name="b3b_eh_1_3_material">
        <color rgba="0.262745 0.282353 0.301961 1"/>
      </material>
    </visual>
        <!-- Part b3b_eh_3 -->
    <visual>
      <origin xyz="0 0 -0.0065" rpy="1.5708 3.30619e-45 9.81999e-32"/>
      <geometry>
        <mesh filename="package://assets/b3b_eh.stl"/>
      </geometry>
      <material name="b3b_eh_3_material">
        <color rgba="0.262745 0.282353 0.301961 1"/>
      </material>
    </visual>
        <!-- Part phs_1_7x20_5_dc10_3_3 -->
    <visual>
      <origin xyz="0 0 -0.0065" rpy="1.5708 3.30619e-45 9.81999e-32"/>
      <geometry>
        <mesh filename="package://assets/phs_1_7x20_5_dc10_3.stl"/>
      </geometry>
      <material name="phs_1_7x20_5_dc10_3_3_material">
        <color rgba="0.262745 0.282353 0.301961 1"/>
      </material>
    </visual>
        <!-- Part phs_1_7x20_5_dc10_1_3 -->
    <visual>
      <origin xyz="0 0 -0.0065" rpy="1.5708 3.30619e-45 9.81999e-32"/>
      <geometry>
        <mesh filename="package://assets/phs_1_7x20_5_dc10_1.stl"/>
      </geometry>
      <material name="phs_1_7x20_5_dc10_1_3_material">
        <color rgba="0.262745 0.282353 0.301961 1"/>
      </material>
    </visual>
        <!-- Part phs_1_7x20_5_dc10_3 -->
    <visual>
      <origin xyz="0 0 -0.0065" rpy="1.5708 3.30619e-45 9.81999e-32"/>
      <geometry>
        <mesh filename="package://assets/phs_1_7x20_5_dc10.stl"/>
      </geometry>
      <material name="phs_1_7x20_5_dc10_3_material">
        <color rgba="0.262745 0.282353 0.301961 1"/>
      </material>
    </visual>
        <!-- Part phs_1_7x20_5_dc10_2_4 -->
    <visual>
      <origin xyz="0.0384404 -0.0337406 -0.0418333" rpy="1.49599e-15 -2.59113e-15 1.0472"/>
      <geometry>
        <mesh filename="package://assets/phs_1_7x20_5_dc10_2.stl"/>
      </geometry>
      <material name="phs_1_7x20_5_dc10_2_4_material">
        <color rgba="0.262745 0.282353 0.301961 1"/>
      </material>
    </visual>
        <!-- Part dc15_a01_case_b_dummy_4 -->
    <visual>
      <origin xyz="0.0384404 -0.0337406 -0.0418333" rpy="1.49599e-15 -2.59113e-15 1.0472"/>
      <geometry>
        <mesh filename="package://assets/dc15_a01_case_b_dummy.stl"/>
      </geometry>
      <material name="dc15_a01_case_b_dummy_4_material">
        <color rgba="0.262745 0.282353 0.301961 1"/>
      </material>
    </visual>
        <!-- Part dc15_a01_case_m_dummy_4 -->
    <visual>
      <origin xyz="0.0384404 -0.0337406 -0.0418333" rpy="1.49599e-15 -2.59113e-15 1.0472"/>
      <geometry>
        <mesh filename="package://assets/dc15_a01_case_m_dummy.stl"/>
      </geometry>
      <material name="dc15_a01_case_m_dummy_4_material">
        <color rgba="0.262745 0.282353 0.301961 1"/>
      </material>
    </visual>
        <!-- Part dc15_a01_led_cap2_dummy_4 -->
    <visual>
      <origin xyz="0.0384404 -0.0337406 -0.0418333" rpy="1.49599e-15 -2.59113e-15 1.0472"/>
      <geometry>
        <mesh filename="package://assets/dc15_a01_led_cap2_dummy.stl"/>
      </geometry>
      <material name="dc15_a01_led_cap2_dummy_4_material">
        <color rgba="0.87451 0.447059 0.317647 1"/>
      </material>
    </visual>
        <!-- Part bts2_m2_6x8_4 -->
    <visual>
      <origin xyz="0.0384404 -0.0337406 -0.0418333" rpy="1.49599e-15 -2.59113e-15 1.0472"/>
      <geometry>
        <mesh filename="package://assets/bts2_m2_6x8.stl"/>
      </geometry>
      <material name="bts2_m2_6x8_4_material">
        <color rgba="0.262745 0.282353 0.301961 1"/>
      </material>
    </visual>
        <!-- Part dc15_a01_case_f_dummy_4 -->
    <visual>
      <origin xyz="0.0384404 -0.0337406 -0.0418333" rpy="1.49599e-15 -2.59113e-15 1.0472"/>
      <geometry>
        <mesh filename="package://assets/dc15_a01_case_f_dummy.stl"/>
      </geometry>
      <material name="dc15_a01_case_f_dummy_4_material">
        <color rgba="0.262745 0.282353 0.301961 1"/>
      </material>
    </visual>
        <!-- Part b3b_eh_1_4 -->
    <visual>
      <origin xyz="0.0384404 -0.0337406 -0.0418333" rpy="1.49599e-15 -2.59113e-15 1.0472"/>
      <geometry>
        <mesh filename="package://assets/b3b_eh_1.stl"/>
      </geometry>
      <material name="b3b_eh_1_4_material">
        <color rgba="0.262745 0.282353 0.301961 1"/>
      </material>
    </visual>
        <!-- Part b3b_eh_4 -->
    <visual>
      <origin xyz="0.0384404 -0.0337406 -0.0418333" rpy="1.49599e-15 -2.59113e-15 1.0472"/>
      <geometry>
        <mesh filename="package://assets/b3b_eh.stl"/>
      </geometry>
      <material name="b3b_eh_4_material">
        <color rgba="0.262745 0.282353 0.301961 1"/>
      </material>
    </visual>
        <!-- Part phs_1_7x20_5_dc10_3_4 -->
    <visual>
      <origin xyz="0.0384404 -0.0337406 -0.0418333" rpy="1.49599e-15 -2.59113e-15 1.0472"/>
      <geometry>
        <mesh filename="package://assets/phs_1_7x20_5_dc10_3.stl"/>
      </geometry>
      <material name="phs_1_7x20_5_dc10_3_4_material">
        <color rgba="0.262745 0.282353 0.301961 1"/>
      </material>
    </visual>
        <!-- Part phs_1_7x20_5_dc10_1_4 -->
    <visual>
      <origin xyz="0.0384404 -0.0337406 -0.0418333" rpy="1.49599e-15 -2.59113e-15 1.0472"/>
      <geometry>
        <mesh filename="package://assets/phs_1_7x20_5_dc10_1.stl"/>
      </geometry>
      <material name="phs_1_7x20_5_dc10_1_4_material">
        <color rgba="0.262745 0.282353 0.301961 1"/>
      </material>
    </visual>
        <!-- Part phs_1_7x20_5_dc10_4 -->
    <visual>
      <origin xyz="0.0384404 -0.0337406 -0.0418333" rpy="1.49599e-15 -2.59113e-15 1.0472"/>
      <geometry>
        <mesh filename="package://assets/phs_1_7x20_5_dc10.stl"/>
      </geometry>
      <material name="phs_1_7x20_5_dc10_4_material">
        <color rgba="0.262745 0.282353 0.301961 1"/>
      </material>
    </visual>
        <!-- Part phs_1_7x20_5_dc10_2_5 -->
    <visual>
      <origin xyz="0.01 0.0501606 -0.0418333" rpy="-1.60914e-16 -1.63452e-15 3.14159"/>
      <geometry>
        <mesh filename="package://assets/phs_1_7x20_5_dc10_2.stl"/>
      </geometry>
      <material name="phs_1_7x20_5_dc10_2_5_material">
        <color rgba="0.262745 0.282353 0.301961 1"/>
      </material>
    </visual>
        <!-- Part dc15_a01_case_b_dummy_5 -->
    <visual>
      <origin xyz="0.01 0.0501606 -0.0418333" rpy="-1.60914e-16 -1.63452e-15 3.14159"/>
      <geometry>
        <mesh filename="package://assets/dc15_a01_case_b_dummy.stl"/>
      </geometry>
      <material name="dc15_a01_case_b_dummy_5_material">
        <color rgba="0.262745 0.282353 0.301961 1"/>
      </material>
    </visual>
        <!-- Part dc15_a01_case_m_dummy_5 -->
    <visual>
      <origin xyz="0.01 0.0501606 -0.0418333" rpy="-1.60914e-16 -1.63452e-15 3.14159"/>
      <geometry>
        <mesh filename="package://assets/dc15_a01_case_m_dummy.stl"/>
      </geometry>
      <material name="dc15_a01_case_m_dummy_5_material">
        <color rgba="0.262745 0.282353 0.301961 1"/>
      </material>
    </visual>
        <!-- Part dc15_a01_led_cap2_dummy_5 -->
    <visual>
      <origin xyz="0.01 0.0501606 -0.0418333" rpy="-1.60914e-16 -1.63452e-15 3.14159"/>
      <geometry>
        <mesh filename="package://assets/dc15_a01_led_cap2_dummy.stl"/>
      </geometry>
      <material name="dc15_a01_led_cap2_dummy_5_material">
        <color rgba="0.87451 0.447059 0.317647 1"/>
      </material>
    </visual>
        <!-- Part bts2_m2_6x8_5 -->
    <visual>
      <origin xyz="0.01 0.0501606 -0.0418333" rpy="-1.60914e-16 -1.63452e-15 3.14159"/>
      <geometry>
        <mesh filename="package://assets/bts2_m2_6x8.stl"/>
      </geometry>
      <material name="bts2_m2_6x8_5_material">
        <color rgba="0.262745 0.282353 0.301961 1"/>
      </material>
    </visual>
        <!-- Part dc15_a01_case_f_dummy_5 -->
    <visual>
      <origin xyz="0.01 0.0501606 -0.0418333" rpy="-1.60914e-16 -1.63452e-15 3.14159"/>
      <geometry>
        <mesh filename="package://assets/dc15_a01_case_f_dummy.stl"/>
      </geometry>
      <material name="dc15_a01_case_f_dummy_5_material">
        <color rgba="0.262745 0.282353 0.301961 1"/>
      </material>
    </visual>
        <!-- Part b3b_eh_1_5 -->
    <visual>
      <origin xyz="0.01 0.0501606 -0.0418333" rpy="-1.60914e-16 -1.63452e-15 3.14159"/>
      <geometry>
        <mesh filename="package://assets/b3b_eh_1.stl"/>
      </geometry>
      <material name="b3b_eh_1_5_material">
        <color rgba="0.262745 0.282353 0.301961 1"/>
      </material>
    </visual>
        <!-- Part b3b_eh_5 -->
    <visual>
      <origin xyz="0.01 0.0501606 -0.0418333" rpy="-1.60914e-16 -1.63452e-15 3.14159"/>
      <geometry>
        <mesh filename="package://assets/b3b_eh.stl"/>
      </geometry>
      <material name="b3b_eh_5_material">
        <color rgba="0.262745 0.282353 0.301961 1"/>
      </material>
    </visual>
        <!-- Part phs_1_7x20_5_dc10_3_5 -->
    <visual>
      <origin xyz="0.01 0.0501606 -0.0418333" rpy="-1.60914e-16 -1.63452e-15 3.14159"/>
      <geometry>
        <mesh filename="package://assets/phs_1_7x20_5_dc10_3.stl"/>
      </geometry>
      <material name="phs_1_7x20_5_dc10_3_5_material">
        <color rgba="0.262745 0.282353 0.301961 1"/>
      </material>
    </visual>
        <!-- Part phs_1_7x20_5_dc10_1_5 -->
    <visual>
      <origin xyz="0.01 0.0501606 -0.0418333" rpy="-1.60914e-16 -1.63452e-15 3.14159"/>
      <geometry>
        <mesh filename="package://assets/phs_1_7x20_5_dc10_1.stl"/>
      </geometry>
      <material name="phs_1_7x20_5_dc10_1_5_material">
        <color rgba="0.262745 0.282353 0.301961 1"/>
      </material>
    </visual>
        <!-- Part phs_1_7x20_5_dc10_5 -->
    <visual>
      <origin xyz="0.01 0.0501606 -0.0418333" rpy="-1.60914e-16 -1.63452e-15 3.14159"/>
      <geometry>
        <mesh filename="package://assets/phs_1_7x20_5_dc10.stl"/>
      </geometry>
      <material name="phs_1_7x20_5_dc10_5_material">
        <color rgba="0.262745 0.282353 0.301961 1"/>
      </material>
    </visual>
        <!-- Part phs_1_7x20_5_dc10_2_6 -->
    <visual>
      <origin xyz="-0.0484404 -0.01642 -0.0418333" rpy="1.49599e-15 -6.77904e-16 -1.0472"/>
      <geometry>
        <mesh filename="package://assets/phs_1_7x20_5_dc10_2.stl"/>
      </geometry>
      <material name="phs_1_7x20_5_dc10_2_6_material">
        <color rgba="0.262745 0.282353 0.301961 1"/>
      </material>
    </visual>
        <!-- Part dc15_a01_case_b_dummy_6 -->
    <visual>
      <origin xyz="-0.0484404 -0.01642 -0.0418333" rpy="1.49599e-15 -6.77904e-16 -1.0472"/>
      <geometry>
        <mesh filename="package://assets/dc15_a01_case_b_dummy.stl"/>
      </geometry>
      <material name="dc15_a01_case_b_dummy_6_material">
        <color rgba="0.262745 0.282353 0.301961 1"/>
      </material>
    </visual>
        <!-- Part dc15_a01_case_m_dummy_6 -->
    <visual>
      <origin xyz="-0.0484404 -0.01642 -0.0418333" rpy="1.49599e-15 -6.77904e-16 -1.0472"/>
      <geometry>
        <mesh filename="package://assets/dc15_a01_case_m_dummy.stl"/>
      </geometry>
      <material name="dc15_a01_case_m_dummy_6_material">
        <color rgba="0.262745 0.282353 0.301961 1"/>
      </material>
    </visual>
        <!-- Part dc15_a01_led_cap2_dummy_6 -->
    <visual>
      <origin xyz="-0.0484404 -0.01642 -0.0418333" rpy="1.49599e-15 -6.77904e-16 -1.0472"/>
      <geometry>
        <mesh filename="package://assets/dc15_a01_led_cap2_dummy.stl"/>
      </geometry>
      <material name="dc15_a01_led_cap2_dummy_6_material">
        <color rgba="0.87451 0.447059 0.317647 1"/>
      </material>
    </visual>
        <!-- Part bts2_m2_6x8_6 -->
    <visual>
      <origin xyz="-0.0484404 -0.01642 -0.0418333" rpy="1.49599e-15 -6.77904e-16 -1.0472"/>
      <geometry>
        <mesh filename="package://assets/bts2_m2_6x8.stl"/>
      </geometry>
      <material name="bts2_m2_6x8_6_material">
        <color rgba="0.262745 0.282353 0.301961 1"/>
      </material>
    </visual>
        <!-- Part dc15_a01_case_f_dummy_6 -->
    <visual>
      <origin xyz="-0.0484404 -0.01642 -0.0418333" rpy="1.49599e-15 -6.77904e-16 -1.0472"/>
      <geometry>
        <mesh filename="package://assets/dc15_a01_case_f_dummy.stl"/>
      </geometry>
      <material name="dc15_a01_case_f_dummy_6_material">
        <color rgba="0.262745 0.282353 0.301961 1"/>
      </material>
    </visual>
        <!-- Part b3b_eh_1_6 -->
    <visual>
      <origin xyz="-0.0484404 -0.01642 -0.0418333" rpy="1.49599e-15 -6.77904e-16 -1.0472"/>
      <geometry>
        <mesh filename="package://assets/b3b_eh_1.stl"/>
      </geometry>
      <material name="b3b_eh_1_6_material">
        <color rgba="0.262745 0.282353 0.301961 1"/>
      </material>
    </visual>
        <!-- Part b3b_eh_6 -->
    <visual>
      <origin xyz="-0.0484404 -0.01642 -0.0418333" rpy="1.49599e-15 -6.77904e-16 -1.0472"/>
      <geometry>
        <mesh filename="package://assets/b3b_eh.stl"/>
      </geometry>
      <material name="b3b_eh_6_material">
        <color rgba="0.262745 0.282353 0.301961 1"/>
      </material>
    </visual>
        <!-- Part phs_1_7x20_5_dc10_3_6 -->
    <visual>
      <origin xyz="-0.0484404 -0.01642 -0.0418333" rpy="1.49599e-15 -6.77904e-16 -1.0472"/>
      <geometry>
        <mesh filename="package://assets/phs_1_7x20_5_dc10_3.stl"/>
      </geometry>
      <material name="phs_1_7x20_5_dc10_3_6_material">
        <color rgba="0.262745 0.282353 0.301961 1"/>
      </material>
    </visual>
        <!-- Part phs_1_7x20_5_dc10_1_6 -->
    <visual>
      <origin xyz="-0.0484404 -0.01642 -0.0418333" rpy="1.49599e-15 -6.77904e-16 -1.0472"/>
      <geometry>
        <mesh filename="package://assets/phs_1_7x20_5_dc10_1.stl"/>
      </geometry>
      <material name="phs_1_7x20_5_dc10_1_6_material">
        <color rgba="0.262745 0.282353 0.301961 1"/>
      </material>
    </visual>
        <!-- Part phs_1_7x20_5_dc10_6 -->
    <visual>
      <origin xyz="-0.0484404 -0.01642 -0.0418333" rpy="1.49599e-15 -6.77904e-16 -1.0472"/>
      <geometry>
        <mesh filename="package://assets/phs_1_7x20_5_dc10.stl"/>
      </geometry>
      <material name="phs_1_7x20_5_dc10_6_material">
        <color rgba="0.262745 0.282353 0.301961 1"/>
      </material>
    </visual>
        <!-- Part phs_1_7x20_5_dc10_2_7 -->
    <visual>
      <origin xyz="0.0484404 -0.01642 -0.0418333" rpy="1.49599e-15 6.77904e-16 1.0472"/>
      <geometry>
        <mesh filename="package://assets/phs_1_7x20_5_dc10_2.stl"/>
      </geometry>
      <material name="phs_1_7x20_5_dc10_2_7_material">
        <color rgba="0.262745 0.282353 0.301961 1"/>
      </material>
    </visual>
        <!-- Part dc15_a01_case_b_dummy_7 -->
    <visual>
      <origin xyz="0.0484404 -0.01642 -0.0418333" rpy="1.49599e-15 6.77904e-16 1.0472"/>
      <geometry>
        <mesh filename="package://assets/dc15_a01_case_b_dummy.stl"/>
      </geometry>
      <material name="dc15_a01_case_b_dummy_7_material">
        <color rgba="0.262745 0.282353 0.301961 1"/>
      </material>
    </visual>
        <!-- Part dc15_a01_case_m_dummy_7 -->
    <visual>
      <origin xyz="0.0484404 -0.01642 -0.0418333" rpy="1.49599e-15 6.77904e-16 1.0472"/>
      <geometry>
        <mesh filename="package://assets/dc15_a01_case_m_dummy.stl"/>
      </geometry>
      <material name="dc15_a01_case_m_dummy_7_material">
        <color rgba="0.262745 0.282353 0.301961 1"/>
      </material>
    </visual>
        <!-- Part dc15_a01_led_cap2_dummy_7 -->
    <visual>
      <origin xyz="0.0484404 -0.01642 -0.0418333" rpy="1.49599e-15 6.77904e-16 1.0472"/>
      <geometry>
        <mesh filename="package://assets/dc15_a01_led_cap2_dummy.stl"/>
      </geometry>
      <material name="dc15_a01_led_cap2_dummy_7_material">
        <color rgba="0.87451 0.447059 0.317647 1"/>
      </material>
    </visual>
        <!-- Part bts2_m2_6x8_7 -->
    <visual>
      <origin xyz="0.0484404 -0.01642 -0.0418333" rpy="1.49599e-15 6.77904e-16 1.0472"/>
      <geometry>
        <mesh filename="package://assets/bts2_m2_6x8.stl"/>
      </geometry>
      <material name="bts2_m2_6x8_7_material">
        <color rgba="0.262745 0.282353 0.301961 1"/>
      </material>
    </visual>
        <!-- Part dc15_a01_case_f_dummy_7 -->
    <visual>
      <origin xyz="0.0484404 -0.01642 -0.0418333" rpy="1.49599e-15 6.77904e-16 1.0472"/>
      <geometry>
        <mesh filename="package://assets/dc15_a01_case_f_dummy.stl"/>
      </geometry>
      <material name="dc15_a01_case_f_dummy_7_material">
        <color rgba="0.262745 0.282353 0.301961 1"/>
      </material>
    </visual>
        <!-- Part b3b_eh_1_7 -->
    <visual>
      <origin xyz="0.0484404 -0.01642 -0.0418333" rpy="1.49599e-15 6.77904e-16 1.0472"/>
      <geometry>
        <mesh filename="package://assets/b3b_eh_1.stl"/>
      </geometry>
      <material name="b3b_eh_1_7_material">
        <color rgba="0.262745 0.282353 0.301961 1"/>
      </material>
    </visual>
        <!-- Part b3b_eh_7 -->
    <visual>
      <origin xyz="0.0484404 -0.01642 -0.0418333" rpy="1.49599e-15 6.77904e-16 1.0472"/>
      <geometry>
        <mesh filename="package://assets/b3b_eh.stl"/>
      </geometry>
      <material name="b3b_eh_7_material">
        <color rgba="0.262745 0.282353 0.301961 1"/>
      </material>
    </visual>
        <!-- Part phs_1_7x20_5_dc10_3_7 -->
    <visual>
      <origin xyz="0.0484404 -0.01642 -0.0418333" rpy="1.49599e-15 6.77904e-16 1.0472"/>
      <geometry>
        <mesh filename="package://assets/phs_1_7x20_5_dc10_3.stl"/>
      </geometry>
      <material name="phs_1_7x20_5_dc10_3_7_material">
        <color rgba="0.262745 0.282353 0.301961 1"/>
      </material>
    </visual>
        <!-- Part phs_1_7x20_5_dc10_1_7 -->
    <visual>
      <origin xyz="0.0484404 -0.01642 -0.0418333" rpy="1.49599e-15 6.77904e-16 1.0472"/>
      <geometry>
        <mesh filename="package://assets/phs_1_7x20_5_dc10_1.stl"/>
      </geometry>
      <material name="phs_1_7x20_5_dc10_1_7_material">
        <color rgba="0.262745 0.282353 0.301961 1"/>
      </material>
    </visual>
        <!-- Part phs_1_7x20_5_dc10_7 -->
    <visual>
      <origin xyz="0.0484404 -0.01642 -0.0418333" rpy="1.49599e-15 6.77904e-16 1.0472"/>
      <geometry>
        <mesh filename="package://assets/phs_1_7x20_5_dc10.stl"/>
      </geometry>
      <material name="phs_1_7x20_5_dc10_7_material">
        <color rgba="0.262745 0.282353 0.301961 1"/>
      </material>
    </visual>
      </link>
  <!-- Link dc15_a01_horn_dummy -->
  <link name="dc15_a01_horn_dummy">
    <inertial>
      <origin xyz="0.0194599 0.0136161 0.00335838" rpy="0 0 0"/>
      <mass value="0.00366675"/>
      <inertia ixx="4.78297e-07" ixy="-5.61085e-07" ixz="-1.58236e-07" iyy="8.87601e-07" iyz="-1.10718e-07"
        izz="1.26546e-06"/>
    </inertial>
    <!-- Part dc15_a01_horn_dummy_2 -->
    <visual>
      <origin xyz="1.73472e-18 1.38778e-17 -0.0065" rpy="1.5708 4.50125e-17 -0.960272"/>
      <geometry>
        <mesh filename="package://assets/dc15_a01_horn_dummy.stl"/>
      </geometry>
      <material name="dc15_a01_horn_dummy_2_material">
        <color rgba="0.262745 0.282353 0.301961 1"/>
      </material>
    </visual>
        <!-- Part mp01062_stewart_arm_3 -->
    <visual>
      <origin xyz="0.0796165 -0.13123 0.0436606" rpy="1.5708 -1.0472 0.610524"/>
      <geometry>
        <mesh filename="package://assets/mp01062_stewart_arm_3.stl"/>
      </geometry>
      <material name="mp01062_stewart_arm_3_material">
        <color rgba="0.301961 0.301961 0.301961 1"/>
      </material>
    </visual>
        <!-- Part stewart_link_ball -->
    <visual>
      <origin xyz="0.0675962 0.047297 0.007" rpy="5.7738e-15 1.16489e-16 0.610524"/>
      <geometry>
        <mesh filename="package://assets/stewart_link_ball.stl"/>
      </geometry>
      <material name="stewart_link_ball_material">
        <color rgba="0.439216 0.47451 0.501961 1"/>
      </material>
    </visual>
      </link>
  <!-- Link passive_1_link_x -->
  <link name="passive_1_link_x">
    <inertial>
      <origin xyz="0 0 0" rpy="0 0 0"/>
      <mass value="1e-09"/>
      <inertia ixx="1e-09" ixy="0" ixz="0" iyy="1e-09" iyz="0" izz="1e-09"/>
    </inertial>
  </link>
  <!-- Link passive_1_link_y -->
  <link name="passive_1_link_y">
    <inertial>
      <origin xyz="0 0 0" rpy="0 0 0"/>
      <mass value="1e-09"/>
      <inertia ixx="1e-09" ixy="0" ixz="0" iyy="1e-09" iyz="0" izz="1e-09"/>
    </inertial>
  </link>
  <!-- Link stewart_link_rod -->
  <link name="stewart_link_rod">
    <inertial>
      <origin xyz="0.0425001 8.43768e-11 -1.88428e-09" rpy="0 0 0"/>
      <mass value="0.00503424"/>
      <inertia ixx="2.63976e-08" ixy="-3.69517e-13" ixz="7.12534e-14" iyy="3.65211e-06" iyz="5.21041e-14"
        izz="3.66473e-06"/>
    </inertial>
    <!-- Part stewart_link_rod -->
    <visual>
      <origin xyz="0.0425 0 -6.93889e-18" rpy="-1.89585e-17 -5.12506e-17 5.13924e-17"/>
      <geometry>
        <mesh filename="package://assets/stewart_link_rod.stl"/>
      </geometry>
      <material name="stewart_link_rod_material">
        <color rgba="0.811765 0.858824 0.898039 1"/>
      </material>
    </visual>
      </link>
  <!-- Frame closing_1_1 (dummy link + fixed joint) -->
  <link name="closing_1_1">
    <origin xyz="0 0 0" rpy="0 -0 0"/>
    <inertial>
      <origin xyz="0 0 0" rpy="0 0 0"/>
      <mass value="1e-9"/>
      <inertia ixx="0" ixy="0" ixz="0" iyy="0" iyz="0" izz="0"/>
    </inertial>
  </link>
  <joint name="closing_1_1_frame" type="fixed">
    <origin xyz="0.085 -1.38778e-17 -6.93889e-18" rpy="-1.89585e-17 -5.12506e-17 5.13924e-17"/>
    <parent link="stewart_link_rod"/>
    <child link="closing_1_1"/>
    <axis xyz="0 0 0"/>
  </joint>
  <!-- Joint from passive_1_link_y to stewart_link_rod -->
  <joint name="passive_1_z" type="revolute">
    <origin xyz="0 0 -6.93889e-18" rpy="-1.89585e-17 -5.12506e-17 5.13924e-17"/>
    <parent link="passive_1_link_y"/>
    <child link="stewart_link_rod"/>
    <axis xyz="0 0 1"/>
    <limit effort="10" velocity="1e+08" lower="-3.141592653589793" upper="3.141592653589793"/>
  </joint>
  <!-- Joint from passive_1_link_x to passive_1_link_y -->
  <joint name="passive_1_y" type="revolute">
    <origin xyz="0 0 -6.93889e-18" rpy="-1.89585e-17 -5.12506e-17 5.13924e-17"/>
    <parent link="passive_1_link_x"/>
    <child link="passive_1_link_y"/>
    <axis xyz="0 1 0"/>
    <limit effort="10" velocity="1e+08" lower="-3.141592653589793" upper="3.141592653589793"/>
  </joint>
  <!-- Joint from dc15_a01_horn_dummy to passive_1_link_x -->
  <joint name="passive_1_x" type="revolute">
    <origin xyz="0.0327739 0.0229319 0.007" rpy="-0.129033 -0.0882156 2.00701"/>
    <parent link="dc15_a01_horn_dummy"/>
    <child link="passive_1_link_x"/>
    <axis xyz="1 0 0"/>
    <limit effort="10" velocity="1e+08" lower="-3.141592653589793" upper="3.141592653589793"/>
  </joint>
  <!-- Joint from body_down_3dprint to dc15_a01_horn_dummy -->
  <joint name="stewart_1" type="revolute">
    <origin xyz="-0.0328112 -0.0304906 -0.0418333" rpy="-1.5708 3.05628e-14 -1.0472"/>
    <parent link="body_down_3dprint"/>
    <child link="dc15_a01_horn_dummy"/>
    <axis xyz="0 0 1"/>
    <limit effort="10" velocity="8" lower="-3.141592653589793" upper="3.141592653589793"/>
  </joint>
  <!-- Link dc15_a01_horn_dummy_2 -->
  <link name="dc15_a01_horn_dummy_2">
    <inertial>
      <origin xyz="-0.0194599 0.0136161 0.00335838" rpy="0 0 0"/>
      <mass value="0.00366675"/>
      <inertia ixx="4.78298e-07" ixy="5.61085e-07" ixz="1.58236e-07" iyy="8.87601e-07" iyz="-1.10718e-07"
        izz="1.26546e-06"/>
    </inertial>
    <!-- Part stewart_link_ball_2 -->
    <visual>
      <origin xyz="0.00204837 -0.00143324 0.007" rpy="4.41275e-15 2.27308e-16 -0.610524"/>
      <geometry>
        <mesh filename="package://assets/stewart_link_ball.stl"/>
      </geometry>
      <material name="stewart_link_ball_2_material">
        <color rgba="0.439216 0.47451 0.501961 1"/>
      </material>
    </visual>
        <!-- Part dc15_a01_horn_dummy_3 -->
    <visual>
      <origin xyz="1.73472e-18 0 -0.0065" rpy="1.5708 -9.65447e-19 0.960272"/>
      <geometry>
        <mesh filename="package://assets/dc15_a01_horn_dummy.stl"/>
      </geometry>
      <material name="dc15_a01_horn_dummy_3_material">
        <color rgba="0.262745 0.282353 0.301961 1"/>
      </material>
    </visual>
        <!-- Part mp01062_stewart_arm_3_2 -->
    <visual>
      <origin xyz="0.0960035 0.119764 0.0436606" rpy="1.5708 -1.0472 2.53107"/>
      <geometry>
        <mesh filename="package://assets/mp01062_stewart_arm_3.stl"/>
      </geometry>
      <material name="mp01062_stewart_arm_3_2_material">
        <color rgba="0.301961 0.301961 0.301961 1"/>
      </material>
    </visual>
      </link>
  <!-- Link passive_2_link_x -->
  <link name="passive_2_link_x">
    <inertial>
      <origin xyz="0 0 0" rpy="0 0 0"/>
      <mass value="1e-09"/>
      <inertia ixx="1e-09" ixy="0" ixz="0" iyy="1e-09" iyz="0" izz="1e-09"/>
    </inertial>
  </link>
  <!-- Link passive_2_link_y -->
  <link name="passive_2_link_y">
    <inertial>
      <origin xyz="0 0 0" rpy="0 0 0"/>
      <mass value="1e-09"/>
      <inertia ixx="1e-09" ixy="0" ixz="0" iyy="1e-09" iyz="0" izz="1e-09"/>
    </inertial>
  </link>
  <!-- Link stewart_link_rod_2 -->
  <link name="stewart_link_rod_2">
    <inertial>
      <origin xyz="-0.00734199 -0.0416931 -0.00374429" rpy="0 0 0"/>
      <mass value="0.00503424"/>
      <inertia ixx="3.54399e-06" ixy="-6.14388e-07" ixz="-5.61994e-08" iyy="1.62816e-07" iyz="-3.14306e-07"
        izz="3.63643e-06"/>
    </inertial>
    <!-- Part stewart_link_rod_2 -->
    <visual>
      <origin xyz="-0.00734201 -0.0416932 -0.0037443" rpy="3.07468 -0.0882156 1.39649"/>
      <geometry>
        <mesh filename="package://assets/stewart_link_rod.stl"/>
      </geometry>
      <material name="stewart_link_rod_2_material">
        <color rgba="0.811765 0.858824 0.898039 1"/>
      </material>
    </visual>
      </link>
  <!-- Frame closing_2_1 (dummy link + fixed joint) -->
  <link name="closing_2_1">
    <origin xyz="0 0 0" rpy="0 -0 0"/>
    <inertial>
      <origin xyz="0 0 0" rpy="0 0 0"/>
      <mass value="1e-9"/>
      <inertia ixx="0" ixy="0" ixz="0" iyy="0" iyz="0" izz="0"/>
    </inertial>
  </link>
  <joint name="closing_2_1_frame" type="fixed">
    <origin xyz="-0.014684 -0.0833865 -0.00748861" rpy="3.07468 -0.0882156 1.39649"/>
    <parent link="stewart_link_rod_2"/>
    <child link="closing_2_1"/>
    <axis xyz="0 0 0"/>
  </joint>
  <!-- Joint from passive_2_link_y to stewart_link_rod_2 -->
  <joint name="passive_2_z" type="revolute">
    <origin xyz="0 6.93889e-18 6.93889e-18" rpy="3.32777e-18 -2.35601e-17 -9.45252e-18"/>
    <parent link="passive_2_link_y"/>
    <child link="stewart_link_rod_2"/>
    <axis xyz="0 0 1"/>
    <limit effort="10" velocity="1e+08" lower="-3.141592653589793" upper="3.141592653589793"/>
  </joint>
  <!-- Joint from passive_2_link_x to passive_2_link_y -->
  <joint name="passive_2_y" type="revolute">
    <origin xyz="0 6.93889e-18 6.93889e-18" rpy="3.32777e-18 -2.35601e-17 -9.45252e-18"/>
    <parent link="passive_2_link_x"/>
    <child link="passive_2_link_y"/>
    <axis xyz="0 1 0"/>
    <limit effort="10" velocity="1e+08" lower="-3.141592653589793" upper="3.141592653589793"/>
  </joint>
  <!-- Joint from dc15_a01_horn_dummy_2 to passive_2_link_x -->
  <joint name="passive_2_x" type="revolute">
    <origin xyz="-0.0327739 0.0229319 0.007" rpy="-3.14159 2.27308e-16 -0.610524"/>
    <parent link="dc15_a01_horn_dummy_2"/>
    <child link="passive_2_link_x"/>
    <axis xyz="1 0 0"/>
    <limit effort="10" velocity="1e+08" lower="-3.141592653589793" upper="3.141592653589793"/>
  </joint>
  <!-- Joint from body_down_3dprint to dc15_a01_horn_dummy_2 -->
  <joint name="stewart_2" type="revolute">
    <origin xyz="-0.0428112 -0.01317 -0.0418333" rpy="-1.5708 6.75017e-15 -1.0472"/>
    <parent link="body_down_3dprint"/>
    <child link="dc15_a01_horn_dummy_2"/>
    <axis xyz="0 0 1"/>
    <limit effort="10" velocity="8" lower="-3.141592653589793" upper="3.141592653589793"/>
  </joint>
  <!-- Link dc15_a01_horn_dummy_3 -->
  <link name="dc15_a01_horn_dummy_3">
    <inertial>
      <origin xyz="0.013616 -0.0194607 0.00335838" rpy="0 0 0"/>
      <mass value="0.00366675"/>
      <inertia ixx="8.87498e-07" ixy="5.61092e-07" ixz="-1.10721e-07" iyy="4.78298e-07" iyz="1.58218e-07"
        izz="1.26536e-06"/>
    </inertial>
    <!-- Part dc15_a01_horn_dummy_4 -->
    <visual>
      <origin xyz="0 0 -0.0065" rpy="1.5708 3.47689e-30 -0.960272"/>
      <geometry>
        <mesh filename="package://assets/dc15_a01_horn_dummy.stl"/>
      </geometry>
      <material name="dc15_a01_horn_dummy_4_material">
        <color rgba="0.262745 0.282353 0.301961 1"/>
      </material>
    </visual>
        <!-- Part stewart_link_ball_3 -->
    <visual>
      <origin xyz="-0.0118904 -0.057139 0.007" rpy="-9.87966e-15 -1.14443e-15 -2.53107"/>
      <geometry>
        <mesh filename="package://assets/stewart_link_ball.stl"/>
      </geometry>
      <material name="stewart_link_ball_3_material">
        <color rgba="0.439216 0.47451 0.501961 1"/>
      </material>
    </visual>
        <!-- Part mp01062_stewart_arm_3_3 -->
    <visual>
      <origin xyz="-0.13123 -0.0796165 0.0436606" rpy="1.5708 -1.0472 -0.960272"/>
      <geometry>
        <mesh filename="package://assets/mp01062_stewart_arm_3.stl"/>
      </geometry>
      <material name="mp01062_stewart_arm_3_3_material">
        <color rgba="0.301961 0.301961 0.301961 1"/>
      </material>
    </visual>
      </link>
  <!-- Link passive_3_link_x -->
  <link name="passive_3_link_x">
    <inertial>
      <origin xyz="0 0 0" rpy="0 0 0"/>
      <mass value="1e-09"/>
      <inertia ixx="1e-09" ixy="0" ixz="0" iyy="1e-09" iyz="0" izz="1e-09"/>
    </inertial>
  </link>
  <!-- Link passive_3_link_y -->
  <link name="passive_3_link_y">
    <inertial>
      <origin xyz="0 0 0" rpy="0 0 0"/>
      <mass value="1e-09"/>
      <inertia ixx="1e-09" ixy="0" ixz="0" iyy="1e-09" iyz="0" izz="1e-09"/>
    </inertial>
  </link>
  <!-- Link stewart_link_rod_3 -->
  <link name="stewart_link_rod_3">
    <inertial>
      <origin xyz="-0.0424999 8.43768e-11 -1.88428e-09" rpy="0 0 0"/>
      <mass value="0.00503424"/>
      <inertia ixx="2.63976e-08" ixy="-3.69517e-13" ixz="7.12534e-14" iyy="3.65211e-06" iyz="5.21041e-14"
        izz="3.66473e-06"/>
    </inertial>
    <!-- Part stewart_link_rod_3 -->
    <visual>
      <origin xyz="-0.0425 -6.93889e-18 0" rpy="-2.43112e-17 2.25632e-17 2.00133e-17"/>
      <geometry>
        <mesh filename="package://assets/stewart_link_rod.stl"/>
      </geometry>
      <material name="stewart_link_rod_3_material">
        <color rgba="0.811765 0.858824 0.898039 1"/>
      </material>
    </visual>
      </link>
  <!-- Frame closing_3_1 (dummy link + fixed joint) -->
  <link name="closing_3_1">
    <origin xyz="0 0 0" rpy="0 -0 0"/>
    <inertial>
      <origin xyz="0 0 0" rpy="0 0 0"/>
      <mass value="1e-9"/>
      <inertia ixx="0" ixy="0" ixz="0" iyy="0" iyz="0" izz="0"/>
    </inertial>
  </link>
  <joint name="closing_3_1_frame" type="fixed">
    <origin xyz="-0.085 -6.93889e-18 0" rpy="-2.43112e-17 2.25632e-17 2.00133e-17"/>
    <parent link="stewart_link_rod_3"/>
    <child link="closing_3_1"/>
    <axis xyz="0 0 0"/>
  </joint>
  <!-- Joint from passive_3_link_y to stewart_link_rod_3 -->
  <joint name="passive_3_z" type="revolute">
    <origin xyz="0 0 0" rpy="-2.43112e-17 2.25632e-17 2.00133e-17"/>
    <parent link="passive_3_link_y"/>
    <child link="stewart_link_rod_3"/>
    <axis xyz="0 0 1"/>
    <limit effort="10" velocity="1e+08" lower="-3.141592653589793" upper="3.141592653589793"/>
  </joint>
  <!-- Joint from passive_3_link_x to passive_3_link_y -->
  <joint name="passive_3_y" type="revolute">
    <origin xyz="0 0 0" rpy="-2.43112e-17 2.25632e-17 2.00133e-17"/>
    <parent link="passive_3_link_x"/>
    <child link="passive_3_link_y"/>
    <axis xyz="0 1 0"/>
    <limit effort="10" velocity="1e+08" lower="-3.141592653589793" upper="3.141592653589793"/>
  </joint>
  <!-- Joint from dc15_a01_horn_dummy_3 to passive_3_link_x -->
  <joint name="passive_3_x" type="revolute">
    <origin xyz="0.0229319 -0.0327739 0.007" rpy="0.365063 0.0882156 -2.70538"/>
    <parent link="dc15_a01_horn_dummy_3"/>
    <child link="passive_3_link_x"/>
    <axis xyz="1 0 0"/>
    <limit effort="10" velocity="1e+08" lower="-3.141592653589793" upper="3.141592653589793"/>
  </joint>
  <!-- Joint from body_down_3dprint to dc15_a01_horn_dummy_3 -->
  <joint name="stewart_3" type="revolute">
    <origin xyz="-0.01 0.0436606 -0.0418333" rpy="1.5708 1.5708 0"/>
    <parent link="body_down_3dprint"/>
    <child link="dc15_a01_horn_dummy_3"/>
    <axis xyz="0 0 1"/>
    <limit effort="10" velocity="8" lower="-3.141592653589793" upper="3.141592653589793"/>
  </joint>
  <!-- Link dc15_a01_horn_dummy_4 -->
  <link name="dc15_a01_horn_dummy_4">
    <inertial>
      <origin xyz="0.0136169 0.0194601 0.00335838" rpy="0 0 0"/>
      <mass value="0.00366675"/>
      <inertia ixx="8.87594e-07" ixy="-5.61057e-07" ixz="-1.107e-07" iyy="4.78202e-07" iyz="-1.58233e-07"
        izz="1.26536e-06"/>
    </inertial>
    <!-- Part stewart_link_ball_4 -->
    <visual>
      <origin xyz="-0.0118904 0.057139 0.007" rpy="2.30725e-15 -2.13242e-15 2.53107"/>
      <geometry>
        <mesh filename="package://assets/stewart_link_ball.stl"/>
      </geometry>
      <material name="stewart_link_ball_4_material">
        <color rgba="0.439216 0.47451 0.501961 1"/>
      </material>
    </visual>
        <!-- Part mp01062_stewart_arm_3_4 -->
    <visual>
      <origin xyz="0.119764 -0.0960035 0.0436606" rpy="1.5708 -1.0472 0.960272"/>
      <geometry>
        <mesh filename="package://assets/mp01062_stewart_arm_3.stl"/>
      </geometry>
      <material name="mp01062_stewart_arm_3_4_material">
        <color rgba="0.301961 0.301961 0.301961 1"/>
      </material>
    </visual>
        <!-- Part dc15_a01_horn_dummy_5 -->
    <visual>
      <origin xyz="-1.38778e-17 0 -0.0065" rpy="1.5708 -2.37698e-30 0.960272"/>
      <geometry>
        <mesh filename="package://assets/dc15_a01_horn_dummy.stl"/>
      </geometry>
      <material name="dc15_a01_horn_dummy_5_material">
        <color rgba="0.262745 0.282353 0.301961 1"/>
      </material>
    </visual>
      </link>
  <!-- Link passive_4_link_x -->
  <link name="passive_4_link_x">
    <inertial>
      <origin xyz="0 0 0" rpy="0 0 0"/>
      <mass value="1e-09"/>
      <inertia ixx="1e-09" ixy="0" ixz="0" iyy="1e-09" iyz="0" izz="1e-09"/>
    </inertial>
  </link>
  <!-- Link passive_4_link_y -->
  <link name="passive_4_link_y">
    <inertial>
      <origin xyz="0 0 0" rpy="0 0 0"/>
      <mass value="1e-09"/>
      <inertia ixx="1e-09" ixy="0" ixz="0" iyy="1e-09" iyz="0" izz="1e-09"/>
    </inertial>
  </link>
  <!-- Link stewart_link_rod_4 -->
  <link name="stewart_link_rod_4">
    <inertial>
      <origin xyz="-0.0424999 8.43768e-11 -1.88428e-09" rpy="0 0 0"/>
      <mass value="0.00503424"/>
      <inertia ixx="2.63976e-08" ixy="-3.69517e-13" ixz="7.12534e-14" iyy="3.65211e-06" iyz="5.21041e-14"
        izz="3.66473e-06"/>
    </inertial>
    <!-- Part stewart_link_rod_4 -->
    <visual>
      <origin xyz="-0.0425 0 -6.93889e-18" rpy="3.17368e-18 -3.23103e-18 -2.7013e-17"/>
      <geometry>
        <mesh filename="package://assets/stewart_link_rod.stl"/>
      </geometry>
      <material name="stewart_link_rod_4_material">
        <color rgba="0.811765 0.858824 0.898039 1"/>
      </material>
    </visual>
      </link>
  <!-- Frame closing_4_1 (dummy link + fixed joint) -->
  <link name="closing_4_1">
    <origin xyz="0 0 0" rpy="0 -0 0"/>
    <inertial>
      <origin xyz="0 0 0" rpy="0 0 0"/>
      <mass value="1e-9"/>
      <inertia ixx="0" ixy="0" ixz="0" iyy="0" iyz="0" izz="0"/>
    </inertial>
  </link>
  <joint name="closing_4_1_frame" type="fixed">
    <origin xyz="-0.085 0 0" rpy="3.17368e-18 -3.23103e-18 -2.7013e-17"/>
    <parent link="stewart_link_rod_4"/>
    <child link="closing_4_1"/>
    <axis xyz="0 0 0"/>
  </joint>
  <!-- Joint from passive_4_link_y to stewart_link_rod_4 -->
  <joint name="passive_4_z" type="revolute">
    <origin xyz="1.38778e-17 0 0" rpy="3.17368e-18 -3.23103e-18 -2.7013e-17"/>
    <parent link="passive_4_link_y"/>
    <child link="stewart_link_rod_4"/>
    <axis xyz="0 0 1"/>
    <limit effort="10" velocity="1e+08" lower="-3.141592653589793" upper="3.141592653589793"/>
  </joint>
  <!-- Joint from passive_4_link_x to passive_4_link_y -->
  <joint name="passive_4_y" type="revolute">
    <origin xyz="1.38778e-17 0 0" rpy="3.17368e-18 -3.23103e-18 -2.7013e-17"/>
    <parent link="passive_4_link_x"/>
    <child link="passive_4_link_y"/>
    <axis xyz="0 1 0"/>
    <limit effort="10" velocity="1e+08" lower="-3.141592653589793" upper="3.141592653589793"/>
  </joint>
  <!-- Joint from dc15_a01_horn_dummy_4 to passive_4_link_x -->
  <joint name="passive_4_x" type="revolute">
    <origin xyz="0.0229319 0.0327739 0.007" rpy="-0.077578 0.0882156 2.70538"/>
    <parent link="dc15_a01_horn_dummy_4"/>
    <child link="passive_4_link_x"/>
    <axis xyz="1 0 0"/>
    <limit effort="10" velocity="1e+08" lower="-3.141592653589793" upper="3.141592653589793"/>
  </joint>
  <!-- Joint from body_down_3dprint to dc15_a01_horn_dummy_4 -->
  <joint name="stewart_4" type="revolute">
    <origin xyz="0.01 0.0436606 -0.0418333" rpy="1.5708 1.5708 0"/>
    <parent link="body_down_3dprint"/>
    <child link="dc15_a01_horn_dummy_4"/>
    <axis xyz="0 0 1"/>
    <limit effort="10" velocity="8" lower="-3.141592653589793" upper="3.141592653589793"/>
  </joint>
  <!-- Link dc15_a01_horn_dummy_5 -->
  <link name="dc15_a01_horn_dummy_5">
    <inertial>
      <origin xyz="0.013616 -0.0194607 0.00335838" rpy="0 0 0"/>
      <mass value="0.00366675"/>
      <inertia ixx="8.87498e-07" ixy="5.61092e-07" ixz="-1.10721e-07" iyy="4.78298e-07" iyz="1.58218e-07"
        izz="1.26536e-06"/>
    </inertial>
    <!-- Part mp01062_stewart_arm_3_5 -->
    <visual>
      <origin xyz="-0.13123 -0.0796165 0.0436606" rpy="1.5708 -1.0472 -0.960272"/>
      <geometry>
        <mesh filename="package://assets/mp01062_stewart_arm_3.stl"/>
      </geometry>
      <material name="mp01062_stewart_arm_3_5_material">
        <color rgba="0.301961 0.301961 0.301961 1"/>
      </material>
    </visual>
        <!-- Part stewart_link_ball_5 -->
    <visual>
      <origin xyz="-0.00143324 0.00204837 0.007" rpy="-7.51419e-15 4.93751e-15 2.18132"/>
      <geometry>
        <mesh filename="package://assets/stewart_link_ball.stl"/>
      </geometry>
      <material name="stewart_link_ball_5_material">
        <color rgba="0.439216 0.47451 0.501961 1"/>
      </material>
    </visual>
        <!-- Part dc15_a01_horn_dummy_6 -->
    <visual>
      <origin xyz="2.77556e-17 3.46945e-18 -0.0065" rpy="1.5708 -5.7586e-17 -0.960272"/>
      <geometry>
        <mesh filename="package://assets/dc15_a01_horn_dummy.stl"/>
      </geometry>
      <material name="dc15_a01_horn_dummy_6_material">
        <color rgba="0.262745 0.282353 0.301961 1"/>
      </material>
    </visual>
      </link>
  <!-- Link passive_5_link_x -->
  <link name="passive_5_link_x">
    <inertial>
      <origin xyz="0 0 0" rpy="0 0 0"/>
      <mass value="1e-09"/>
      <inertia ixx="1e-09" ixy="0" ixz="0" iyy="1e-09" iyz="0" izz="1e-09"/>
    </inertial>
  </link>
  <!-- Link passive_5_link_y -->
  <link name="passive_5_link_y">
    <inertial>
      <origin xyz="0 0 0" rpy="0 0 0"/>
      <mass value="1e-09"/>
      <inertia ixx="1e-09" ixy="0" ixz="0" iyy="1e-09" iyz="0" izz="1e-09"/>
    </inertial>
  </link>
  <!-- Link stewart_link_rod_5 -->
  <link name="stewart_link_rod_5">
    <inertial>
      <origin xyz="-0.0424999 8.43768e-11 -1.88428e-09" rpy="0 0 0"/>
      <mass value="0.00503424"/>
      <inertia ixx="2.63976e-08" ixy="-3.69517e-13" ixz="7.12534e-14" iyy="3.65211e-06" iyz="5.21041e-14"
        izz="3.66473e-06"/>
    </inertial>
    <!-- Part stewart_link_rod_5 -->
    <visual>
      <origin xyz="-0.0425 0 0" rpy="-3.0015e-19 1.3471e-17 1.28245e-17"/>
      <geometry>
        <mesh filename="package://assets/stewart_link_rod.stl"/>
      </geometry>
      <material name="stewart_link_rod_5_material">
        <color rgba="0.811765 0.858824 0.898039 1"/>
      </material>
    </visual>
      </link>
  <!-- Frame closing_5_1 (dummy link + fixed joint) -->
  <link name="closing_5_1">
    <origin xyz="0 0 0" rpy="0 -0 0"/>
    <inertial>
      <origin xyz="0 0 0" rpy="0 0 0"/>
      <mass value="1e-9"/>
      <inertia ixx="0" ixy="0" ixz="0" iyy="0" iyz="0" izz="0"/>
    </inertial>
  </link>
  <joint name="closing_5_1_frame" type="fixed">
    <origin xyz="-0.085 0 0" rpy="-3.0015e-19 1.3471e-17 1.28245e-17"/>
    <parent link="stewart_link_rod_5"/>
    <child link="closing_5_1"/>
    <axis xyz="0 0 0"/>
  </joint>
  <!-- Joint from passive_5_link_y to stewart_link_rod_5 -->
  <joint name="passive_5_z" type="revolute">
    <origin xyz="0 0 0" rpy="-3.0015e-19 1.3471e-17 1.28245e-17"/>
    <parent link="passive_5_link_y"/>
    <child link="stewart_link_rod_5"/>
    <axis xyz="0 0 1"/>
    <limit effort="10" velocity="1e+08" lower="-3.141592653589793" upper="3.141592653589793"/>
  </joint>
  <!-- Joint from passive_5_link_x to passive_5_link_y -->
  <joint name="passive_5_y" type="revolute">
    <origin xyz="0 0 0" rpy="-3.0015e-19 1.3471e-17 1.28245e-17"/>
    <parent link="passive_5_link_x"/>
    <child link="passive_5_link_y"/>
    <axis xyz="0 1 0"/>
    <limit effort="10" velocity="1e+08" lower="-3.141592653589793" upper="3.141592653589793"/>
  </joint>
  <!-- Joint from dc15_a01_horn_dummy_5 to passive_5_link_x -->
  <joint name="passive_5_x" type="revolute">
    <origin xyz="0.0229319 -0.0327739 0.007" rpy="0.11547 0.0882156 -2.70538"/>
    <parent link="dc15_a01_horn_dummy_5"/>
    <child link="passive_5_link_x"/>
    <axis xyz="1 0 0"/>
    <limit effort="10" velocity="1e+08" lower="-3.141592653589793" upper="3.141592653589793"/>
  </joint>
  <!-- Joint from body_down_3dprint to dc15_a01_horn_dummy_5 -->
  <joint name="stewart_5" type="revolute">
    <origin xyz="0.0428112 -0.01317 -0.0418333" rpy="-2.61799 1.5708 0"/>
    <parent link="body_down_3dprint"/>
    <child link="dc15_a01_horn_dummy_5"/>
    <axis xyz="0 0 1"/>
    <limit effort="10" velocity="8" lower="-3.141592653589793" upper="3.141592653589793"/>
  </joint>
  <!-- Link dc15_a01_horn_dummy_6 -->
  <link name="dc15_a01_horn_dummy_6">
    <inertial>
      <origin xyz="-0.0194599 0.0136161 0.00335838" rpy="0 0 0"/>
      <mass value="0.00366675"/>
      <inertia ixx="4.78298e-07" ixy="5.61085e-07" ixz="1.58236e-07" iyy="8.87601e-07" iyz="-1.10718e-07"
        izz="1.26546e-06"/>
    </inertial>
    <!-- Part dc15_a01_horn_dummy_7 -->
    <visual>
      <origin xyz="-1.73472e-18 0 -0.0065" rpy="1.5708 -5.74126e-17 0.960272"/>
      <geometry>
        <mesh filename="package://assets/dc15_a01_horn_dummy.stl"/>
      </geometry>
      <material name="dc15_a01_horn_dummy_7_material">
        <color rgba="0.262745 0.282353 0.301961 1"/>
      </material>
    </visual>
        <!-- Part stewart_link_ball_6 -->
    <visual>
      <origin xyz="-0.0675962 0.047297 0.007" rpy="-1.48102e-14 9.12477e-17 2.53107"/>
      <geometry>
        <mesh filename="package://assets/stewart_link_ball.stl"/>
      </geometry>
      <material name="stewart_link_ball_6_material">
        <color rgba="0.439216 0.47451 0.501961 1"/>
      </material>
    </visual>
        <!-- Part mp01062_stewart_arm_3_6 -->
    <visual>
      <origin xyz="0.0960035 0.119764 0.0436606" rpy="1.5708 -1.0472 2.53107"/>
      <geometry>
        <mesh filename="package://assets/mp01062_stewart_arm_3.stl"/>
      </geometry>
      <material name="mp01062_stewart_arm_3_6_material">
        <color rgba="0.301961 0.301961 0.301961 1"/>
      </material>
    </visual>
      </link>
  <!-- Link passive_6_link_x -->
  <link name="passive_6_link_x">
    <inertial>
      <origin xyz="0 0 0" rpy="0 0 0"/>
      <mass value="1e-09"/>
      <inertia ixx="1e-09" ixy="0" ixz="0" iyy="1e-09" iyz="0" izz="1e-09"/>
    </inertial>
  </link>
  <!-- Link passive_6_link_y -->
  <link name="passive_6_link_y">
    <inertial>
      <origin xyz="0 0 0" rpy="0 0 0"/>
      <mass value="1e-09"/>
      <inertia ixx="1e-09" ixy="0" ixz="0" iyy="1e-09" iyz="0" izz="1e-09"/>
    </inertial>
  </link>
  <!-- Link stewart_link_rod_6 -->
  <link name="stewart_link_rod_6">
    <inertial>
      <origin xyz="-0.0424999 8.43768e-11 -1.88428e-09" rpy="0 0 0"/>
      <mass value="0.00503424"/>
      <inertia ixx="2.63976e-08" ixy="-3.69517e-13" ixz="7.12534e-14" iyy="3.65211e-06" iyz="5.21041e-14"
        izz="3.66473e-06"/>
    </inertial>
    <!-- Part stewart_link_rod_6 -->
    <visual>
      <origin xyz="-0.0425 0 0" rpy="-2.80507e-17 2.33044e-18 5.49106e-18"/>
      <geometry>
        <mesh filename="package://assets/stewart_link_rod.stl"/>
      </geometry>
      <material name="stewart_link_rod_6_material">
        <color rgba="0.811765 0.858824 0.898039 1"/>
      </material>
    </visual>
      </link>
  <!-- Link passive_7_link_x -->
  <link name="passive_7_link_x">
    <inertial>
      <origin xyz="0 0 0" rpy="0 0 0"/>
      <mass value="1e-09"/>
      <inertia ixx="1e-09" ixy="0" ixz="0" iyy="1e-09" iyz="0" izz="1e-09"/>
    </inertial>
  </link>
  <!-- Link passive_7_link_y -->
  <link name="passive_7_link_y">
    <inertial>
      <origin xyz="0 0 0" rpy="0 0 0"/>
      <mass value="1e-09"/>
      <inertia ixx="1e-09" ixy="0" ixz="0" iyy="1e-09" iyz="0" izz="1e-09"/>
    </inertial>
  </link>
  <!-- Link xl_330 -->
  <link name="xl_330">
    <inertial>
      <origin xyz="-0.0506035 -0.019003 0.0210208" rpy="0 0 0"/>
      <mass value="0.259259"/>
      <inertia ixx="0.000640991" ixy="3.21297e-05" ixz="-1.41214e-05" iyy="0.000581183" iyz="9.44174e-05"
        izz="0.000460545"/>
    </inertial>
    <!-- Part m12_fisheye_lens_1_8mm -->
    <visual>
      <origin xyz="-0.0418682 -0.0290809 -0.0237487" rpy="1.44163 -0.547922 2.06985"/>
      <geometry>
        <mesh filename="package://assets/m12_fisheye_lens_1_8mm.stl"/>
      </geometry>
      <material name="m12_fisheye_lens_1_8mm_material">
        <color rgba="0.498039 0.498039 0.498039 1"/>
      </material>
    </visual>
        <!-- Part stewart_link_ball_7 -->
    <visual>
      <origin xyz="0.0218754 0.0401877 0.0549733" rpy="-2.12245 0.110171 -2.71009"/>
      <geometry>
        <mesh filename="package://assets/stewart_link_ball__2.stl"/>
      </geometry>
      <material name="stewart_link_ball_7_material">
        <color rgba="0.439216 0.47451 0.501961 1"/>
      </material>
    </visual>
        <!-- Part big_lens_d40 -->
    <visual>
      <origin xyz="-0.0313424 -0.0483916 -0.0371699" rpy="1.44163 -0.547922 2.06985"/>
      <geometry>
        <mesh filename="package://assets/big_lens_d40.stl"/>
      </geometry>
      <material name="big_lens_d40_material">
        <color rgba="0.439216 0.47451 0.501961 0.301961"/>
      </material>
    </visual>
        <!-- Part neck_reference_3dprint -->
    <visual>
      <origin xyz="-0.0549574 -0.0138138 0.0260112" rpy="1.77881 -1.00937 -1.3161"/>
      <geometry>
        <mesh filename="package://assets/neck_reference_3dprint.stl"/>
      </geometry>
      <material name="neck_reference_3dprint_material">
        <color rgba="0.901961 0.901961 0.901961 1"/>
      </material>
    </visual>
        <!-- Part head_back_3dprint -->
    <visual>
      <origin xyz="-0.0549574 -0.0138138 0.0260112" rpy="1.77881 -1.00937 -1.3161"/>
      <geometry>
        <mesh filename="package://assets/head_back_3dprint.stl"/>
      </geometry>
      <material name="head_back_3dprint_material">
        <color rgba="1 1 1 1"/>
      </material>
    </visual>
        <!-- Part arducam -->
    <visual>
      <origin xyz="-0.050012 -0.0402635 -0.00327501" rpy="-1.77881 1.00937 1.82549"/>
      <geometry>
        <mesh filename="package://assets/arducam.stl"/>
      </geometry>
      <material name="arducam_material">
        <color rgba="0.498039 0.498039 0.498039 1"/>
      </material>
    </visual>
        <!-- Part pp01102_arducam_carter -->
    <visual>
      <origin xyz="-0.0359607 -0.0486655 0.00178862" rpy="1.77881 -1.00937 -1.3161"/>
      <geometry>
        <mesh filename="package://assets/pp01102_arducam_carter.stl"/>
      </geometry>
      <material name="pp01102_arducam_carter_material">
        <color rgba="0.301961 0.301961 0.301961 1"/>
      </material>
    </visual>
        <!-- Part antenna_holder_l_3dprint -->
    <visual>
      <origin xyz="-0.0550392 -0.0136639 0.0261153" rpy="1.77881 -1.00937 -1.3161"/>
      <geometry>
        <mesh filename="package://assets/antenna_holder_l_3dprint.stl"/>
      </geometry>
      <material name="antenna_holder_l_3dprint_material">
        <color rgba="0.498039 0.498039 0.498039 1"/>
      </material>
    </visual>
        <!-- Part stewart_link_ball_8 -->
    <visual>
      <origin xyz="-0.00634751 -0.0057883 0.0740068" rpy="-2.91303 1.06415 -0.938629"/>
      <geometry>
        <mesh filename="package://assets/stewart_link_ball__2.stl"/>
      </geometry>
      <material name="stewart_link_ball_8_material">
        <color rgba="0.439216 0.47451 0.501961 1"/>
      </material>
    </visual>
        <!-- Part lens_cap_d30_3dprint -->
    <visual>
      <origin xyz="-0.055029 -0.0136825 0.0261024" rpy="1.77881 -1.00937 -1.3161"/>
      <geometry>
        <mesh filename="package://assets/lens_cap_d30_3dprint.stl"/>
      </geometry>
      <material name="lens_cap_d30_3dprint_material">
        <color rgba="0.0980392 0.0980392 0.0980392 1"/>
      </material>
    </visual>
        <!-- Part lens_cap_d40_3dprint -->
    <visual>
      <origin xyz="-0.0550145 -0.0137091 0.026084" rpy="1.77881 -1.00937 -1.3161"/>
      <geometry>
        <mesh filename="package://assets/lens_cap_d40_3dprint.stl"/>
      </geometry>
      <material name="lens_cap_d40_3dprint_material">
        <color rgba="0.0980392 0.0980392 0.0980392 1"/>
      </material>
    </visual>
        <!-- Part antenna_holder_r_3dprint -->
    <visual>
      <origin xyz="-0.0550392 -0.0136639 0.0261153" rpy="1.77881 -1.00937 -1.3161"/>
      <geometry>
        <mesh filename="package://assets/antenna_holder_r_3dprint.stl"/>
      </geometry>
      <material name="antenna_holder_r_3dprint_material">
        <color rgba="0.498039 0.498039 0.498039 1"/>
      </material>
    </visual>
        <!-- Part stewart_link_ball_9 -->
    <visual>
      <origin xyz="0.0199975 0.0474008 0.0431223" rpy="-2.12245 0.110171 -2.71009"/>
      <geometry>
        <mesh filename="package://assets/stewart_link_ball__2.stl"/>
      </geometry>
      <material name="stewart_link_ball_9_material">
        <color rgba="0.439216 0.47451 0.501961 1"/>
      </material>
    </visual>
        <!-- Part small_lens_d30 -->
    <visual>
      <origin xyz="-0.0307496 -0.0669726 0.0282138" rpy="1.44163 -0.547922 2.06985"/>
      <geometry>
        <mesh filename="package://assets/small_lens_d30.stl"/>
      </geometry>
      <material name="small_lens_d30_material">
        <color rgba="0.439216 0.47451 0.501961 0.301961"/>
      </material>
    </visual>
        <!-- Part stewart_link_ball_10 -->
    <visual>
      <origin xyz="-0.0103618 -0.000307632 0.086248" rpy="-2.91303 1.06415 -0.938629"/>
      <geometry>
        <mesh filename="package://assets/stewart_link_ball__2.stl"/>
      </geometry>
      <material name="stewart_link_ball_10_material">
        <color rgba="0.439216 0.47451 0.501961 1"/>
      </material>
    </visual>
        <!-- Part stewart_link_ball_11 -->
    <visual>
      <origin xyz="-0.017887 0.0385344 0.00118475" rpy="0.110214 0.02788 -1.13621"/>
      <geometry>
        <mesh filename="package://assets/stewart_link_ball__2.stl"/>
      </geometry>
      <material name="stewart_link_ball_11_material">
        <color rgba="0.439216 0.47451 0.501961 1"/>
      </material>
    </visual>
        <!-- Part glasses_dolder_3dprint -->
    <visual>
      <origin xyz="-0.0549574 -0.0138138 0.0260112" rpy="1.77881 -1.00937 -1.3161"/>
      <geometry>
        <mesh filename="package://assets/glasses_dolder_3dprint.stl"/>
      </geometry>
      <material name="glasses_dolder_3dprint_material">
        <color rgba="0.196078 0.196078 0.196078 1"/>
      </material>
    </visual>
        <!-- Part head_front_3dprint -->
    <visual>
      <origin xyz="-0.0549574 -0.0138138 0.0260112" rpy="1.77881 -1.00937 -1.3161"/>
      <geometry>
        <mesh filename="package://assets/head_front_3dprint.stl"/>
      </geometry>
      <material name="head_front_3dprint_material">
        <color rgba="1 1 1 1"/>
      </material>
    </visual>
        <!-- Part head_mic_3dprint -->
    <visual>
      <origin xyz="-0.0549574 -0.0138138 0.0260112" rpy="1.77881 -1.00937 -1.3161"/>
      <geometry>
        <mesh filename="package://assets/head_mic_3dprint.stl"/>
      </geometry>
      <material name="head_mic_3dprint_material">
        <color rgba="1 1 1 1"/>
      </material>
    </visual>
        <!-- Part m12_fisheye_lens_1_8mm_2 -->
    <visual>
      <origin xyz="-0.033123 -0.0626184 0.0312401" rpy="1.44163 -0.547922 2.06985"/>
      <geometry>
        <mesh filename="package://assets/m12_fisheye_lens_1_8mm.stl"/>
      </geometry>
      <material name="m12_fisheye_lens_1_8mm_2_material">
        <color rgba="0.498039 0.498039 0.498039 1"/>
      </material>
    </visual>
        <!-- Part stewart_link_ball_12 -->
    <visual>
      <origin xyz="-0.0237791 0.0512281 0.00157502" rpy="0.110214 0.02788 -1.13621"/>
      <geometry>
        <mesh filename="package://assets/stewart_link_ball__2.stl"/>
      </geometry>
      <material name="stewart_link_ball_12_material">
        <color rgba="0.439216 0.47451 0.501961 1"/>
      </material>
    </visual>
        <!-- Part phs_1_7x20_5_dc10_2_8 -->
    <visual>
      <origin xyz="-0.076086 -0.027265 0.0790109" rpy="1.37308 0.505067 2.01001"/>
      <geometry>
        <mesh filename="package://assets/phs_1_7x20_5_dc10_2.stl"/>
      </geometry>
      <material name="phs_1_7x20_5_dc10_2_8_material">
        <color rgba="0.262745 0.282353 0.301961 1"/>
      </material>
    </visual>
        <!-- Part dc15_a01_case_b_dummy_8 -->
    <visual>
      <origin xyz="-0.076086 -0.027265 0.0790109" rpy="1.37308 0.505067 2.01001"/>
      <geometry>
        <mesh filename="package://assets/dc15_a01_case_b_dummy.stl"/>
      </geometry>
      <material name="dc15_a01_case_b_dummy_8_material">
        <color rgba="0.262745 0.282353 0.301961 1"/>
      </material>
    </visual>
        <!-- Part dc15_a01_case_m_dummy_8 -->
    <visual>
      <origin xyz="-0.076086 -0.027265 0.0790109" rpy="1.37308 0.505067 2.01001"/>
      <geometry>
        <mesh filename="package://assets/dc15_a01_case_m_dummy.stl"/>
      </geometry>
      <material name="dc15_a01_case_m_dummy_8_material">
        <color rgba="0.262745 0.282353 0.301961 1"/>
      </material>
    </visual>
        <!-- Part dc15_a01_led_cap2_dummy_8 -->
    <visual>
      <origin xyz="-0.076086 -0.027265 0.0790109" rpy="1.37308 0.505067 2.01001"/>
      <geometry>
        <mesh filename="package://assets/dc15_a01_led_cap2_dummy.stl"/>
      </geometry>
      <material name="dc15_a01_led_cap2_dummy_8_material">
        <color rgba="0.87451 0.447059 0.317647 1"/>
      </material>
    </visual>
        <!-- Part bts2_m2_6x8_8 -->
    <visual>
      <origin xyz="-0.076086 -0.027265 0.0790109" rpy="1.37308 0.505067 2.01001"/>
      <geometry>
        <mesh filename="package://assets/bts2_m2_6x8.stl"/>
      </geometry>
      <material name="bts2_m2_6x8_8_material">
        <color rgba="0.262745 0.282353 0.301961 1"/>
      </material>
    </visual>
        <!-- Part dc15_a01_case_f_dummy_8 -->
    <visual>
      <origin xyz="-0.076086 -0.027265 0.0790109" rpy="1.37308 0.505067 2.01001"/>
      <geometry>
        <mesh filename="package://assets/dc15_a01_case_f_dummy.stl"/>
      </geometry>
      <material name="dc15_a01_case_f_dummy_8_material">
        <color rgba="0.262745 0.282353 0.301961 1"/>
      </material>
    </visual>
        <!-- Part b3b_eh_1_8 -->
    <visual>
      <origin xyz="-0.076086 -0.027265 0.0790109" rpy="1.37308 0.505067 2.01001"/>
      <geometry>
        <mesh filename="package://assets/b3b_eh_1.stl"/>
      </geometry>
      <material name="b3b_eh_1_8_material">
        <color rgba="0.262745 0.282353 0.301961 1"/>
      </material>
    </visual>
        <!-- Part b3b_eh_8 -->
    <visual>
      <origin xyz="-0.076086 -0.027265 0.0790109" rpy="1.37308 0.505067 2.01001"/>
      <geometry>
        <mesh filename="package://assets/b3b_eh.stl"/>
      </geometry>
      <material name="b3b_eh_8_material">
        <color rgba="0.262745 0.282353 0.301961 1"/>
      </material>
    </visual>
        <!-- Part phs_1_7x20_5_dc10_3_8 -->
    <visual>
      <origin xyz="-0.076086 -0.027265 0.0790109" rpy="1.37308 0.505067 2.01001"/>
      <geometry>
        <mesh filename="package://assets/phs_1_7x20_5_dc10_3.stl"/>
      </geometry>
      <material name="phs_1_7x20_5_dc10_3_8_material">
        <color rgba="0.262745 0.282353 0.301961 1"/>
      </material>
    </visual>
        <!-- Part phs_1_7x20_5_dc10_1_8 -->
    <visual>
      <origin xyz="-0.076086 -0.027265 0.0790109" rpy="1.37308 0.505067 2.01001"/>
      <geometry>
        <mesh filename="package://assets/phs_1_7x20_5_dc10_1.stl"/>
      </geometry>
      <material name="phs_1_7x20_5_dc10_1_8_material">
        <color rgba="0.262745 0.282353 0.301961 1"/>
      </material>
    </visual>
        <!-- Part phs_1_7x20_5_dc10_8 -->
    <visual>
      <origin xyz="-0.076086 -0.027265 0.0790109" rpy="1.37308 0.505067 2.01001"/>
      <geometry>
        <mesh filename="package://assets/phs_1_7x20_5_dc10.stl"/>
      </geometry>
      <material name="phs_1_7x20_5_dc10_8_material">
        <color rgba="0.262745 0.282353 0.301961 1"/>
      </material>
    </visual>
        <!-- Part phs_1_7x20_5_dc10_2_9 -->
    <visual>
      <origin xyz="-0.0892208 0.0231853 -0.00387875" rpy="0.0941379 1.39725 0.631412"/>
      <geometry>
        <mesh filename="package://assets/phs_1_7x20_5_dc10_2.stl"/>
      </geometry>
      <material name="phs_1_7x20_5_dc10_2_9_material">
        <color rgba="0.262745 0.282353 0.301961 1"/>
      </material>
    </visual>
        <!-- Part dc15_a01_case_b_dummy_9 -->
    <visual>
      <origin xyz="-0.0892208 0.0231853 -0.00387875" rpy="0.0941379 1.39725 0.631412"/>
      <geometry>
        <mesh filename="package://assets/dc15_a01_case_b_dummy.stl"/>
      </geometry>
      <material name="dc15_a01_case_b_dummy_9_material">
        <color rgba="0.262745 0.282353 0.301961 1"/>
      </material>
    </visual>
        <!-- Part dc15_a01_case_m_dummy_9 -->
    <visual>
      <origin xyz="-0.0892208 0.0231853 -0.00387875" rpy="0.0941379 1.39725 0.631412"/>
      <geometry>
        <mesh filename="package://assets/dc15_a01_case_m_dummy.stl"/>
      </geometry>
      <material name="dc15_a01_case_m_dummy_9_material">
        <color rgba="0.262745 0.282353 0.301961 1"/>
      </material>
    </visual>
        <!-- Part dc15_a01_led_cap2_dummy_9 -->
    <visual>
      <origin xyz="-0.0892208 0.0231853 -0.00387875" rpy="0.0941379 1.39725 0.631412"/>
      <geometry>
        <mesh filename="package://assets/dc15_a01_led_cap2_dummy.stl"/>
      </geometry>
      <material name="dc15_a01_led_cap2_dummy_9_material">
        <color rgba="0.87451 0.447059 0.317647 1"/>
      </material>
    </visual>
        <!-- Part bts2_m2_6x8_9 -->
    <visual>
      <origin xyz="-0.0892208 0.0231853 -0.00387875" rpy="0.0941379 1.39725 0.631412"/>
      <geometry>
        <mesh filename="package://assets/bts2_m2_6x8.stl"/>
      </geometry>
      <material name="bts2_m2_6x8_9_material">
        <color rgba="0.262745 0.282353 0.301961 1"/>
      </material>
    </visual>
        <!-- Part dc15_a01_case_f_dummy_9 -->
    <visual>
      <origin xyz="-0.0892208 0.0231853 -0.00387875" rpy="0.0941379 1.39725 0.631412"/>
      <geometry>
        <mesh filename="package://assets/dc15_a01_case_f_dummy.stl"/>
      </geometry>
      <material name="dc15_a01_case_f_dummy_9_material">
        <color rgba="0.262745 0.282353 0.301961 1"/>
      </material>
    </visual>
        <!-- Part b3b_eh_1_9 -->
    <visual>
      <origin xyz="-0.0892208 0.0231853 -0.00387875" rpy="0.0941379 1.39725 0.631412"/>
      <geometry>
        <mesh filename="package://assets/b3b_eh_1.stl"/>
      </geometry>
      <material name="b3b_eh_1_9_material">
        <color rgba="0.262745 0.282353 0.301961 1"/>
      </material>
    </visual>
        <!-- Part b3b_eh_9 -->
    <visual>
      <origin xyz="-0.0892208 0.0231853 -0.00387875" rpy="0.0941379 1.39725 0.631412"/>
      <geometry>
        <mesh filename="package://assets/b3b_eh.stl"/>
      </geometry>
      <material name="b3b_eh_9_material">
        <color rgba="0.262745 0.282353 0.301961 1"/>
      </material>
    </visual>
        <!-- Part phs_1_7x20_5_dc10_3_9 -->
    <visual>
      <origin xyz="-0.0892208 0.0231853 -0.00387875" rpy="0.0941379 1.39725 0.631412"/>
      <geometry>
        <mesh filename="package://assets/phs_1_7x20_5_dc10_3.stl"/>
      </geometry>
      <material name="phs_1_7x20_5_dc10_3_9_material">
        <color rgba="0.262745 0.282353 0.301961 1"/>
      </material>
    </visual>
        <!-- Part phs_1_7x20_5_dc10_1_9 -->
    <visual>
      <origin xyz="-0.0892208 0.0231853 -0.00387875" rpy="0.0941379 1.39725 0.631412"/>
      <geometry>
        <mesh filename="package://assets/phs_1_7x20_5_dc10_1.stl"/>
      </geometry>
      <material name="phs_1_7x20_5_dc10_1_9_material">
        <color rgba="0.262745 0.282353 0.301961 1"/>
      </material>
    </visual>
        <!-- Part phs_1_7x20_5_dc10_9 -->
    <visual>
      <origin xyz="-0.0892208 0.0231853 -0.00387875" rpy="0.0941379 1.39725 0.631412"/>
      <geometry>
        <mesh filename="package://assets/phs_1_7x20_5_dc10.stl"/>
      </geometry>
      <material name="phs_1_7x20_5_dc10_9_material">
        <color rgba="0.262745 0.282353 0.301961 1"/>
      </material>
    </visual>
      </link>
  <!-- Frame closing_1_2 (dummy link + fixed joint) -->
  <link name="closing_1_2">
    <origin xyz="0 0 0" rpy="0 -0 0"/>
    <inertial>
      <origin xyz="0 0 0" rpy="0 0 0"/>
      <mass value="1e-9"/>
      <inertia ixx="0" ixy="0" ixz="0" iyy="0" iyz="0" izz="0"/>
    </inertial>
  </link>
  <joint name="closing_1_2_frame" type="fixed">
    <origin xyz="0.00583863 -0.022426 0.0368459" rpy="-2.91303 1.06415 -0.938629"/>
    <parent link="xl_330"/>
    <child link="closing_1_2"/>
    <axis xyz="0 0 0"/>
  </joint>
  <!-- Frame closing_2_2 (dummy link + fixed joint) -->
  <link name="closing_2_2">
    <origin xyz="0 0 0" rpy="0 -0 0"/>
    <inertial>
      <origin xyz="0 0 0" rpy="0 0 0"/>
      <mass value="1e-9"/>
      <inertia ixx="0" ixy="0" ixz="0" iyy="0" iyz="0" izz="0"/>
    </inertial>
  </link>
  <joint name="closing_2_2_frame" type="fixed">
    <origin xyz="0.00182437 -0.0169454 0.0490871" rpy="-2.91303 1.06415 -0.938629"/>
    <parent link="xl_330"/>
    <child link="closing_2_2"/>
    <axis xyz="0 0 0"/>
  </joint>
  <!-- Frame closing_3_2 (dummy link + fixed joint) -->
  <link name="closing_3_2">
    <origin xyz="0 0 0" rpy="0 -0 0"/>
    <inertial>
      <origin xyz="0 0 0" rpy="0 0 0"/>
      <mass value="1e-9"/>
      <inertia ixx="0" ixy="0" ixz="0" iyy="0" iyz="0" izz="0"/>
    </inertial>
  </link>
  <joint name="closing_3_2_frame" type="fixed">
    <origin xyz="-0.016495 0.0225206 0.0503005" rpy="-2.93358 -1.00937 -1.3161"/>
    <parent link="xl_330"/>
    <child link="closing_3_2"/>
    <axis xyz="0 0 0"/>
  </joint>
  <!-- Frame closing_4_2 (dummy link + fixed joint) -->
  <link name="closing_4_2">
    <origin xyz="0 0 0" rpy="0 -0 0"/>
    <inertial>
      <origin xyz="0 0 0" rpy="0 0 0"/>
      <mass value="1e-9"/>
      <inertia ixx="0" ixy="0" ixz="0" iyy="0" iyz="0" izz="0"/>
    </inertial>
  </link>
  <joint name="closing_4_2_frame" type="fixed">
    <origin xyz="-0.0183729 0.0297336 0.0384495" rpy="-2.93358 -1.00937 -1.3161"/>
    <parent link="xl_330"/>
    <child link="closing_4_2"/>
    <axis xyz="0 0 0"/>
  </joint>
  <!-- Frame closing_5_2 (dummy link + fixed joint) -->
  <link name="closing_5_2">
    <origin xyz="0 0 0" rpy="0 -0 0"/>
    <inertial>
      <origin xyz="0 0 0" rpy="0 0 0"/>
      <mass value="1e-9"/>
      <inertia ixx="0" ixy="0" ixz="0" iyy="0" iyz="0" izz="0"/>
    </inertial>
  </link>
  <joint name="closing_5_2_frame" type="fixed">
    <origin xyz="-0.00589217 0.0126937 0.00039027" rpy="-3.11354 -0.110171 0.431499"/>
    <parent link="xl_330"/>
    <child link="closing_5_2"/>
    <axis xyz="0 0 0"/>
  </joint>
  <!-- Frame camera_optical (dummy link + fixed joint) -->
  <link name="camera_optical">
    <origin xyz="0 0 0" rpy="0 -0 0"/>
    <inertial>
      <origin xyz="0 0 0" rpy="0 0 0"/>
      <mass value="1e-9"/>
      <inertia ixx="0" ixy="0" ixz="0" iyy="0" iyz="0" izz="0"/>
    </inertial>
  </link>
  <joint name="camera_optical_frame" type="fixed">
    <origin xyz="-0.0367778 -0.0471665 0.00283045" rpy="2.93358 1.00937 1.82549"/>
    <parent link="xl_330"/>
    <child link="camera_optical"/>
    <axis xyz="0 0 0"/>
  </joint>
  <!-- Frame camera (dummy link + fixed joint) -->
  <link name="camera">
    <origin xyz="0 0 0" rpy="0 -0 0"/>
    <inertial>
      <origin xyz="0 0 0" rpy="0 0 0"/>
      <mass value="1e-9"/>
      <inertia ixx="0" ixy="0" ixz="0" iyy="0" iyz="0" izz="0"/>
    </inertial>
  </link>
  <joint name="camera_frame" type="fixed">
    <origin xyz="-0.0367778 -0.0471665 0.00283045" rpy="1.69996 0.547922 -1.07174"/>
    <parent link="xl_330"/>
    <child link="camera"/>
    <axis xyz="0 0 0"/>
  </joint>
  <!-- Frame head (dummy link + fixed joint) -->
  <link name="head">
    <origin xyz="0 0 0" rpy="0 -0 0"/>
    <inertial>
      <origin xyz="0 0 0" rpy="0 0 0"/>
      <mass value="1e-9"/>
      <inertia ixx="0" ixy="0" ixz="0" iyy="0" iyz="0" izz="0"/>
    </inertial>
  </link>
  <joint name="head_frame" type="fixed">
    <origin xyz="-0.00551617 0.00426275 0.0291789" rpy="1.69996 0.547922 -1.07174"/>
    <parent link="xl_330"/>
    <child link="head"/>
    <axis xyz="0 0 0"/>
  </joint>
  <!-- Link dc15_a01_horn_dummy_7 -->
  <link name="dc15_a01_horn_dummy_7">
    <inertial>
      <origin xyz="2.09613e-05 -0.0378463 -0.00866471" rpy="0 0 0"/>
      <mass value="0.0105926"/>
      <inertia ixx="2.69314e-05" ixy="2.22219e-09" ixz="3.62599e-10" iyy="2.98203e-07" iyz="-6.63107e-07"
        izz="2.68876e-05"/>
    </inertial>
    <!-- Part antenna -->
    <visual>
      <origin xyz="2.42861e-16 -0.0588 -0.0103" rpy="-8.19331e-16 -9.07109e-15 4.92976e-15"/>
      <geometry>
        <mesh filename="package://assets/antenna.stl"/>
      </geometry>
      <material name="antenna_material">
        <color rgba="0 0 0 1"/>
      </material>
    </visual>
        <!-- Part dc15_a01_horn_dummy_8 -->
    <visual>
      <origin xyz="-1.38778e-17 -2.77556e-17 0.0065" rpy="-1.5708 1.32592e-14 4.91048e-15"/>
      <geometry>
        <mesh filename="package://assets/dc15_a01_horn_dummy.stl"/>
      </geometry>
      <material name="dc15_a01_horn_dummy_8_material">
        <color rgba="0.262745 0.282353 0.301961 1"/>
      </material>
    </visual>
        <!-- Part antenna_interface_3dprint -->
    <visual>
      <origin xyz="-1.04083e-17 0 0" rpy="-1.5708 1.0255e-15 -3.14159"/>
      <geometry>
        <mesh filename="package://assets/antenna_interface_3dprint.stl"/>
      </geometry>
      <material name="antenna_interface_3dprint_material">
        <color rgba="0.713725 0.760784 0.8 1"/>
      </material>
    </visual>
        <!-- Part antenna_body_3dprint -->
    <visual>
      <origin xyz="4.51028e-17 2.77556e-17 -0.0028" rpy="-1.5708 9.19021e-15 -3.14159"/>
      <geometry>
        <mesh filename="package://assets/antenna_body_3dprint.stl"/>
      </geometry>
      <material name="antenna_body_3dprint_material">
        <color rgba="1 1 1 1"/>
      </material>
    </visual>
      </link>
  <!-- Joint from xl_330 to dc15_a01_horn_dummy_7 -->
  <joint name="right_antenna" type="revolute">
    <origin xyz="-0.0925548 0.0287641 -0.00377325" rpy="1.66493 1.39725 0.631412"/>
    <parent link="xl_330"/>
    <child link="dc15_a01_horn_dummy_7"/>
    <axis xyz="0 0 1"/>
    <limit effort="10" velocity="8" lower="-3.141592653589793" upper="3.141592653589793"/>
  </joint>
  <!-- Link dc15_a01_horn_dummy_8 -->
  <link name="dc15_a01_horn_dummy_8">
    <inertial>
      <origin xyz="2.09613e-05 -0.0378463 -0.00866471" rpy="0 0 0"/>
      <mass value="0.0105926"/>
      <inertia ixx="2.69314e-05" ixy="2.22219e-09" ixz="3.62599e-10" iyy="2.98203e-07" iyz="-6.63107e-07"
        izz="2.68876e-05"/>
    </inertial>
    <!-- Part dc15_a01_horn_dummy_9 -->
    <visual>
      <origin xyz="-5.11743e-16 3.60822e-16 0.0065" rpy="-1.5708 -1.97942e-14 -1.21374e-15"/>
      <geometry>
        <mesh filename="package://assets/dc15_a01_horn_dummy.stl"/>
      </geometry>
      <material name="dc15_a01_horn_dummy_9_material">
        <color rgba="0.262745 0.282353 0.301961 1"/>
      </material>
    </visual>
        <!-- Part antenna_body_3dprint_2 -->
    <visual>
      <origin xyz="-4.78784e-16 3.88578e-16 -0.0028" rpy="-1.5708 5.74322e-15 3.14159"/>
      <geometry>
        <mesh filename="package://assets/antenna_body_3dprint.stl"/>
      </geometry>
      <material name="antenna_body_3dprint_2_material">
        <color rgba="1 1 1 1"/>
      </material>
    </visual>
        <!-- Part antenna_interface_3dprint_2 -->
    <visual>
      <origin xyz="-5.23886e-16 3.33067e-16 1.38778e-17" rpy="-1.5708 5.04388e-15 3.14159"/>
      <geometry>
        <mesh filename="package://assets/antenna_interface_3dprint.stl"/>
      </geometry>
      <material name="antenna_interface_3dprint_2_material">
        <color rgba="0.713725 0.760784 0.8 1"/>
      </material>
    </visual>
        <!-- Part antenna_2 -->
    <visual>
      <origin xyz="-4.52763e-16 -0.0588 -0.0103" rpy="-1.64427e-16 -5.79311e-15 3.95395e-15"/>
      <geometry>
        <mesh filename="package://assets/antenna.stl"/>
      </geometry>
      <material name="antenna_2_material">
        <color rgba="0 0 0 1"/>
      </material>
    </visual>
      </link>
  <!-- Joint from xl_330 to dc15_a01_horn_dummy_8 -->
  <joint name="left_antenna" type="revolute">
    <origin xyz="-0.078553 -0.0250168 0.0845885" rpy="2.94387 0.505067 2.01001"/>
    <parent link="xl_330"/>
    <child link="dc15_a01_horn_dummy_8"/>
    <axis xyz="0 0 1"/>
    <limit effort="10" velocity="8" lower="-3.141592653589793" upper="3.141592653589793"/>
  </joint>
  <!-- Joint from passive_7_link_y to xl_330 -->
  <joint name="passive_7_z" type="revolute">
    <origin xyz="-2.77556e-17 0 -6.93889e-18" rpy="-2.80507e-17 -2.33044e-18 -5.49106e-18"/>
    <parent link="passive_7_link_y"/>
    <child link="xl_330"/>
    <axis xyz="0 0 1"/>
    <limit effort="10" velocity="1e+08" lower="-3.141592653589793" upper="3.141592653589793"/>
  </joint>
  <!-- Joint from passive_7_link_x to passive_7_link_y -->
  <joint name="passive_7_y" type="revolute">
    <origin xyz="-2.77556e-17 0 -6.93889e-18" rpy="-2.80507e-17 -2.33044e-18 -5.49106e-18"/>
    <parent link="passive_7_link_x"/>
    <child link="passive_7_link_y"/>
    <axis xyz="0 1 0"/>
    <limit effort="10" velocity="1e+08" lower="-3.141592653589793" upper="3.141592653589793"/>
  </joint>
  <!-- Joint from stewart_link_rod_6 to passive_7_link_x -->
  <joint name="passive_7_x" type="revolute">
    <origin xyz="-0.085 -1.38778e-17 6.93889e-18" rpy="3.14159 2.33044e-18 5.49106e-18"/>
    <parent link="stewart_link_rod_6"/>
    <child link="passive_7_link_x"/>
    <axis xyz="1 0 0"/>
    <limit effort="10" velocity="1e+08" lower="-3.141592653589793" upper="3.141592653589793"/>
  </joint>
  <!-- Joint from passive_6_link_y to stewart_link_rod_6 -->
  <joint name="passive_6_z" type="revolute">
    <origin xyz="-2.77556e-17 -1.38778e-17 0" rpy="-2.80507e-17 2.33044e-18 5.49106e-18"/>
    <parent link="passive_6_link_y"/>
    <child link="stewart_link_rod_6"/>
    <axis xyz="0 0 1"/>
    <limit effort="10" velocity="1e+08" lower="-3.141592653589793" upper="3.141592653589793"/>
  </joint>
  <!-- Joint from passive_6_link_x to passive_6_link_y -->
  <joint name="passive_6_y" type="revolute">
    <origin xyz="-2.77556e-17 -1.38778e-17 0" rpy="-2.80507e-17 2.33044e-18 5.49106e-18"/>
    <parent link="passive_6_link_x"/>
    <child link="passive_6_link_y"/>
    <axis xyz="0 1 0"/>
    <limit effort="10" velocity="1e+08" lower="-3.141592653589793" upper="3.141592653589793"/>
  </joint>
  <!-- Joint from dc15_a01_horn_dummy_6 to passive_6_link_x -->
  <joint name="passive_6_x" type="revolute">
    <origin xyz="-0.0327739 0.0229319 0.007" rpy="3.06981 0.0882156 -2.00701"/>
    <parent link="dc15_a01_horn_dummy_6"/>
    <child link="passive_6_link_x"/>
    <axis xyz="1 0 0"/>
    <limit effort="10" velocity="1e+08" lower="-3.141592653589793" upper="3.141592653589793"/>
  </joint>
  <!-- Joint from body_down_3dprint to dc15_a01_horn_dummy_6 -->
  <joint name="stewart_6" type="revolute">
    <origin xyz="0.0328112 -0.0304906 -0.0418333" rpy="-1.5708 1.11952e-14 1.0472"/>
    <parent link="body_down_3dprint"/>
    <child link="dc15_a01_horn_dummy_6"/>
    <axis xyz="0 0 1"/>
    <limit effort="10" velocity="8" lower="-3.141592653589793" upper="3.141592653589793"/>
  </joint>
  <!-- Joint from body_foot_3dprint to body_down_3dprint -->
  <joint name="yaw_body" type="revolute">
    <origin xyz="-2.45997e-07 6.93889e-18 0.0348" rpy="-3.14159 6.78125e-28 -1.5708"/>
    <parent link="body_foot_3dprint"/>
    <child link="body_down_3dprint"/>
    <axis xyz="0 0 1"/>
    <limit effort="10" velocity="8" lower="-3.141592653589793" upper="3.141592653589793"/>
  </joint>
  <!-- Dummy Link head_oriented_yaw used for constraint setting in placo-kinematics -->
  <link name="dummy_torso_yaw">
    <visual>
      <geometry>
        <box size="0 0 0"/>
      </geometry>
      <material name="blue"/>
    </visual>
  </link>
  <!-- Joint from pp01071_turning_bowl to dc15_a01_case_b_dummy -->
  <joint name="dummy_yaw" type="fixed">
    <origin xyz="0 0 0" rpy="3.14 0 -1.57"/>
    <!-- <origin xyz="4.85723e-17 -5.60663e-19 0.0339" rpy="3.14159 -2.22045e-16 1.5708"/> -->
    <parent link="body_down_3dprint"/>
    <!-- <parent link="dc15_a01_case_b_dummy"/>   -->
    <child link="dummy_torso_yaw"/>
    <axis xyz="0 0 1"/>
  </joint>
</robot>